Workbook

Sheet Total
C1: LTS
A2: Sector | D2: 2023 | E2: 2024 | F2: 2025 | G2: 2026 | H2: 2027 | I2: 2028 | J2: 2029 | K2: 2030 | L2: 2031 | M2: 2032 | N2: 2033 | O2: 2034 | P2: 2035 | Q2: 2036 | R2: 2037 | S2: 2038 | T2: 2039 | U2: 2040 | V2: 2041 | W2: 2042 | X2: 2043 | Y2: 2044 | Z2: 2045 | AA2: 2046 | AB2: 2047 | AC2: 2048 | AD2: 2049 | AE2: 2050
A3: EN - Power Industry | D3: 0 | E3: 0 | F3: 1.6405576 | G3: 0.34625024 | H3: 1.9174732 | I3: 2.5989561 | J3: 7.4215444 | K3: 12.361299 | L3: 10.532018 | M3: 2.5227963 | N3: 0 | O3: 0 | P3: 0 | Q3: 0.17038217 | R3: 1.7411691 | S3: 1.6253737 | T3: 1.3839284 | U3: 0.36629935 | V3: 1.2547853 | W3: 1.1758144 | X3: 1.1289111 | Y3: 0 | Z3: 1.9889886 | AA3: 1.1108272 | AB3: 1.9490205 | AC3: 1.7886575 | AD3: 3.3536365 | AE3: 7.1215774
A4: EN - Building | D4: 0 | E4: 0 | F4: 0 | G4: 0.012392549 | H4: 0.023961415 | I4: 0.034716882 | J4: 0.04467692 | K4: 0.064827291 | L4: 0.087174788 | M4: 0.11568716 | N4: 0.15926129 | O4: 0.23577258 | P4: 0.37229479 | Q4: 0.5841981 | R4: 0.83360216 | S4: 1.0449121 | T4: 1.1831236 | U4: 1.2640512 | V4: 1.3137549 | W4: 1.3490937 | X4: 1.3785 | Y4: 1.4057886 | Z4: 1.42454 | AA4: 1.4421371 | AB4: 1.4605851 | AC4: 1.4799217 | AD4: 1.5001853 | AE4: 1.5214156
A5: EN - Transportation | D5: 0 | E5: 0 | F5: 0.00071354781 | G5: 0.0034838861 | H5: 0.0064159389 | I5: 0.0095152481 | J5: 0.012795081 | K5: 0.016253265 | L5: 0.019892768 | M5: 0.023716181 | N5: 0.10602808 | O5: 0.17937431 | P5: 0.24473071 | Q5: 0.3029889 | R5: 0.35496134 | S5: 0.40138644 | T5: 0.44293309 | U5: 0.48020527 | V5: 0.51399811 | W5: 0.54484237 | X5: 0.57320804 | Y5: 0.59950962 | Z5: 0.6241114 | AA5: 0.64733216 | AB5: 0.66945045 | AC5: 0.69070656 | AD5: 0.71130656 | AE5: 0.73142549
A6: EN - Industrial combustion | D6: 0 | E6: 0 | F6: 0.014978408 | G6: 0.038599098 | H6: 0.061850965 | I6: 0.087728895 | J6: 0.11327748 | K6: 0.13857169 | L6: 0.16369791 | M6: 0.18873901 | N6: 0.21377563 | O6: 0.23887801 | P6: 0.26408324 | Q6: 0.28937229 | R6: 0.31468311 | S6: 0.33995973 | T6: 0.36518397 | U6: 0.39036782 | V6: 0.41560148 | W6: 0.4409168 | X6: 0.46633933 | Y6: 0.4918873 | Z6: 0.51757356 | AA6: 0.54340571 | AB6: 0.56938683 | AC6: 0.59551643 | AD6: 0.62157441 | AE6: 0.6477426
A7: IN - Industrial processes | D7: 0 | E7: 0 | F7: 0 | G7: 0.81392292 | H7: 0.9083042 | I7: 1.0048392 | J7: 1.1037592 | K7: 1.2048031 | L7: 1.3079567 | M7: 1.4132038 | N7: 1.5205262 | O7: 1.6299038 | P7: 1.7413146 | Q7: 1.8547346 | R7: 1.9701378 | S7: 2.0874964 | T7: 2.2067804 | U7: 2.3279581 | V7: 2.451401 | W7: 2.5771386 | X7: 2.7052009 | Y7: 2.8356177 | Z7: 2.9684192 | AA7: 3.103636 | AB7: 3.2412985 | AC7: 3.3814378 | AD7: 3.5240848 | AE7: 3.6692709
A8: Waste - Solid waste | D8: 0 | E8: 0 | F8: 0.087052446 | G8: 0.11358144 | H8: 0.1399269 | I8: 0.16354773 | J8: 0.1829564 | K8: 0.19795117 | L8: 0.20917977 | M8: 0.2175722 | N8: 0.2239904 | O8: 0.22909745 | P8: 0.2333409 | Q8: 0.23815074 | R8: 0.24258702 | S8: 0.24672606 | T8: 0.25063224 | U8: 0.25436408 | V8: 0.25796955 | W8: 0.26148254 | X8: 0.25997613 | Y8: 0.2584831 | Z8: 0.25701392 | AA8: 0.25557792 | AB8: 0.25418242 | AC8: 0.25283533 | AD8: 0.2513073 | AE8: 0.24983327
A9: Waste - Wastewater treatment (trww) | D9: 0 | E9: 0 | F9: 0 | G9: 0.11709818 | H9: 0.24928301 | I9: 0.39763456 | J9: 0.56345437 | K9: 0.74777457 | L9: 0.95177063 | M9: 1.1766567 | N9: 1.4236858 | O9: 1.6941498 | P9: 1.9893781 | Q9: 2.0439521 | R9: 2.0993942 | S9: 2.1556968 | T9: 2.2128525 | U9: 2.270853 | V9: 2.3303178 | W9: 2.3912911 | X9: 2.4538189 | Y9: 2.5179499 | Z9: 2.5837353 | AA9: 2.651228 | AB9: 2.7204793 | AC9: 2.7915445 | AD9: 2.8644803 | AE9: 2.9393447
A10: Waste - Wastewater (liquid waste) | D10: 0 | E10: 0 | F10: 0 | G10: 0 | H10: 0 | I10: 0 | J10: 0 | K10: 0 | L10: 0 | M10: 0 | N10: 0 | O10: 0 | P10: 0 | Q10: 0 | R10: 0 | S10: 0 | T10: 0 | U10: 0 | V10: 0 | W10: 0 | X10: 0 | Y10: 0 | Z10: 0 | AA10: 0 | AB10: 0 | AC10: 0 | AD10: 0 | AE10: 0
A11: AG - Livestock (manure) | D11: 0 | E11: 0 | F11: 0 | G11: 0 | H11: 0 | I11: 0 | J11: 0 | K11: 0 | L11: 0 | M11: 0 | N11: 0 | O11: 0 | P11: 0 | Q11: 0 | R11: 0 | S11: 0 | T11: 0 | U11: 0 | V11: 0 | W11: 0 | X11: 0 | Y11: 0 | Z11: 0 | AA11: 0 | AB11: 0 | AC11: 0 | AD11: 0 | AE11: 0
A12: LULUCF - Forest land | D12: 0 | E12: 0 | F12: 0.98551391 | G12: 1.217631 | H12: 1.4249767 | I12: 1.6039905 | J12: 1.7589536 | K12: 1.8900428 | L12: 2.0088138 | M12: 2.1188086 | N12: 2.2220535 | O12: 2.3206628 | P12: 2.416521 | Q12: 2.5108192 | R12: 2.6038114 | S12: 2.6944069 | T12: 2.7814845 | U12: 2.8635156 | V12: 2.9386065 | W12: 3.0067889 | X12: 3.0641981 | Y12: 3.1042697 | Z12: 3.1347957 | AA12: 3.1556165 | AB12: 3.1657721 | AC12: 3.1641768 | AD12: 3.131214 | AE12: 3.2774395
A14: units: billion 2019 USD
B15: GDP (constant 2019 PPP Billion US$) | D15: 316.71546 | E15: 326.67617 | F15: 337.46301 | G15: 348.87601 | H15: 360.72035 | I15: 372.90909 | J15: 385.62156 | K15: 398.62402 | L15: 411.91668 | M15: 425.49945 | N15: 439.37189 | O15: 453.53325 | P15: 467.9824 | Q15: 482.71789 | R15: 497.73788 | S15: 513.04015 | T15: 528.62212 | U15: 544.48078 | V15: 560.8152 | W15: 577.63966 | X15: 594.96885 | Y15: 612.81791 | Z15: 631.20245 | AA15: 650.13852 | AB15: 669.64268 | AC15: 689.73196 | AD15: 710.42392 | AE15: 731.73664
B16: Gross capital formation (% of GDP) | D16: 28.99836 | E16: 30.074355 | F16: 31.871247 | G16: 31.871247 | H16: 31.871247 | I16: 31.871247 | J16: 31.871247 | K16: 31.871247 | L16: 31.871247 | M16: 31.871247 | N16: 31.871247 | O16: 31.871247 | P16: 31.871247 | Q16: 31.871247 | R16: 31.871247 | S16: 31.871247 | T16: 31.871247 | U16: 31.871247 | V16: 31.871247 | W16: 31.871247 | X16: 31.871247 | Y16: 31.871247 | Z16: 31.871247 | AA16: 31.871247 | AB16: 31.871247 | AC16: 31.871247 | AD16: 31.871247 | AE16: 31.871247
B17: Gross capital formation (constant 2019 PPP Billion US$) | D17: =+D15*(D16)/100 -> 91.84229 | E17: =+E15*(E16)/100 -> 98.24575 | F17: =+F15*(F16)/100 -> 107.55367 | G17: =+G15*(G16)/100 -> 111.19114 | H17: =+H15*(H16)/100 -> 114.96608 | I17: =+I15*(I16)/100 -> 118.85078 | J17: =+J15*(J16)/100 -> 122.9024 | K17: =+K15*(K16)/100 -> 127.04645 | ... AE17: =+AE15*(AE16)/100 -> 233.21359
D19: LTS -Percent Change as Shock
A20: EN - Power Industry | D20: =+D3/D$17 -> 0 | E20: =+E3/E$17 -> 0 | F20: =+F3/F$17 -> 0.015253385 | G20: =+G3/G$17 -> 0.0031140094 | H20: =+H3/H$17 -> 0.0166786 | I20: =+I3/I$17 -> 0.021867388 | J20: =+J3/J$17 -> 0.060385674 | K20: =+K3/K$17 -> 0.097297482 | ... AE20: =+AE3/AE$17 -> 0.030536717
A21: EN - Building | D21: =+D4/D$17 -> 0 | E21: =+E4/E$17 -> 0 | F21: =+F4/F$17 -> 0 | G21: =+G4/G$17 -> 0.00011145267 | H21: =+H4/H$17 -> 0.00020842161 | I21: =+I4/I$17 -> 0.00029210479 | J21: =+J4/J$17 -> 0.00036351544 | K21: =+K4/K$17 -> 0.00051026449 | ... AE21: =+AE4/AE$17 -> 0.0065237005
A22: EN - Transportation | D22: =+D5/D$17 -> 0 | E22: =+E5/E$17 -> 0 | F22: =+F5/F$17 -> 6.6343418e-06 | G22: =+G5/G$17 -> 3.1332409e-05 | H22: =+H5/H$17 -> 5.5807236e-05 | I22: =+I5/I$17 -> 8.0060461e-05 | J22: =+J5/J$17 -> 0.00010410765 | K22: =+K5/K$17 -> 0.00012793168 | ... AE22: =+AE5/AE$17 -> 0.0031362901
A23: EN - Industrial combustion | D23: =+D6/D$17 -> 0 | E23: =+E6/E$17 -> 0 | F23: =+F6/F$17 -> 0.0001392645 | G23: =+G6/G$17 -> 0.00034714186 | H23: =+H6/H$17 -> 0.00053799318 | I23: =+I6/I$17 -> 0.0007381432 | J23: =+J6/J$17 -> 0.00092168645 | K23: =+K6/K$17 -> 0.0010907168 | ... AE23: =+AE6/AE$17 -> 0.0027774651
A24: IN - Industrial processes | D24: =+D7/D$17 -> 0 | E24: =+E7/E$17 -> 0 | F24: =+F7/F$17 -> 0 | G24: =+G7/G$17 -> 0.0073200342 | H24: =+H7/H$17 -> 0.0079006281 | I24: =+I7/I$17 -> 0.0084546283 | J24: =+J7/J$17 -> 0.0089807783 | K24: =+K7/K$17 -> 0.0094831707 | ... AE24: =+AE7/AE$17 -> 0.015733521
A25: Waste - Solid waste | D25: =+D8/D$17 -> 0 | E25: =+E8/E$17 -> 0 | F25: =+F8/F$17 -> 0.0008093861 | G25: =+G8/G$17 -> 0.0010214972 | H25: =+H8/H$17 -> 0.0012171147 | I25: =+I8/I$17 -> 0.0013760762 | J25: =+J8/J$17 -> 0.0014886316 | K25: =+K8/K$17 -> 0.0015581008 | ... AE25: =+AE8/AE$17 -> 0.0010712637
A26: Waste - Wastewater treatment (trww) | D26: =+D9/D$17 -> 0 | E26: =+E9/E$17 -> 0 | F26: =+F9/F$17 -> 0 | G26: =+G9/G$17 -> 0.0010531251 | H26: =+H9/H$17 -> 0.002168318 | I26: =+I9/I$17 -> 0.0033456622 | J26: =+J9/J$17 -> 0.0045845676 | K26: =+K9/K$17 -> 0.0058858361 | ... AE26: =+AE9/AE$17 -> 0.012603659
A27: Waste - Wastewater (liquid waste) | D27: =+D10/D$17 -> 0 | E27: =+E10/E$17 -> 0 | F27: =+F10/F$17 -> 0 | G27: =+G10/G$17 -> 0 | H27: =+H10/H$17 -> 0 | I27: =+I10/I$17 -> 0 | J27: =+J10/J$17 -> 0 | K27: =+K10/K$17 -> 0 | ... AE27: =+AE10/AE$17 -> 0
A28: AG - Livestock (manure) | D28: =+D11/D$17 -> 0 | E28: =+E11/E$17 -> 0 | F28: =+F11/F$17 -> 0 | G28: =+G11/G$17 -> 0 | H28: =+H11/H$17 -> 0 | I28: =+I11/I$17 -> 0 | J28: =+J11/J$17 -> 0 | K28: =+K11/K$17 -> 0 | ... AE28: =+AE11/AE$17 -> 0
A29: LULUCF - Forest land | D29: =+D12/D$17 -> 0 | E29: =+E12/E$17 -> 0 | F29: =+F12/F$17 -> 0.0091629965 | G29: =+G12/G$17 -> 0.010950792 | H29: =+H12/H$17 -> 0.012394758 | I29: =+I12/I$17 -> 0.013495835 | J29: =+J12/J$17 -> 0.014311792 | K29: =+K12/K$17 -> 0.014876786 | ... AE29: =+AE12/AE$17 -> 0.014053381
D31: =+SUM(D20:D29) -> 0 | E31: =+SUM(E20:E29) -> 0 | F31: =+SUM(F20:F29) -> 0.025371667 | G31: =+SUM(G20:G29) -> 0.023949385 | H31: =+SUM(H20:H29) -> 0.041161641 | I31: =+SUM(I20:I29) -> 0.049649899 | J31: =+SUM(J20:J29) -> 0.091140753 | K31: =+SUM(K20:K29) -> 0.13083029 | ... AE31: =+SUM(AE20:AE29) -> 0.086435997
A33: Sector | B33: Agent | C33: % | D33: 2023 | E33: 2024 | F33: 2025 | G33: 2026 | H33: 2027 | I33: 2028 | J33: 2029 | K33: 2030 | L33: 2031 | M33: 2032 | N33: 2033 | O33: 2034 | P33: 2035 | Q33: 2036 | R33: 2037 | S33: 2038 | T33: 2039 | U33: 2040 | V33: 2041 | W33: 2042 | X33: 2043 | Y33: 2044 | Z33: 2045 | AA33: 2046 | AB33: 2047 | AC33: 2048 | AD33: 2049 | AE33: 2050
A34: EN - Power Industry | B34: Government | C34: =+C102 -> 0.25 | D34: =+D$3*$C34 -> 0 | E34: =+E$3*$C34 -> 0 | F34: =+F$3*$C34 -> 0.4101394 | G34: =+G$3*$C34 -> 0.086562561 | H34: =+H$3*$C34 -> 0.4793683 | I34: =+I$3*$C34 -> 0.64973903 | J34: =+J$3*$C34 -> 1.8553861 | K34: =+K$3*$C34 -> 3.0903248 | ... AE34: =+AE$3*$C34 -> 1.7803943
B35: Firms | C35: =+D102 -> 0.7 | D35: =+D$3*$C35 -> 0 | E35: =+E$3*$C35 -> 0 | F35: =+F$3*$C35 -> 1.1483903 | G35: =+G$3*$C35 -> 0.24237517 | H35: =+H$3*$C35 -> 1.3422312 | I35: =+I$3*$C35 -> 1.8192693 | J35: =+J$3*$C35 -> 5.1950811 | K35: =+K$3*$C35 -> 8.6529096 | ... AE35: =+AE$3*$C35 -> 4.9851042
B36: Households | C36: =+E102 -> 0.05 | D36: =+D$3*$C36 -> 0 | E36: =+E$3*$C36 -> 0 | F36: =+F$3*$C36 -> 0.082027879 | G36: =+G$3*$C36 -> 0.017312512 | H36: =+H$3*$C36 -> 0.095873659 | I36: =+I$3*$C36 -> 0.12994781 | J36: =+J$3*$C36 -> 0.37107722 | K36: =+K$3*$C36 -> 0.61806497 | ... AE36: =+AE$3*$C36 -> 0.35607887
A37: EN - Building | B37: Government | C37: =+C103 -> 0.1 | D37: =+D$4*$C37 -> 0 | E37: =+E$4*$C37 -> 0 | F37: =+F$4*$C37 -> 0 | G37: =+G$4*$C37 -> 0.0012392549 | H37: =+H$4*$C37 -> 0.0023961415 | I37: =+I$4*$C37 -> 0.0034716882 | J37: =+J$4*$C37 -> 0.004467692 | K37: =+K$4*$C37 -> 0.0064827291 | ... AE37: =+AE$4*$C37 -> 0.15214156
B38: Firms | C38: =+D103 -> 0.3 | D38: =+D$4*$C38 -> 0 | E38: =+E$4*$C38 -> 0 | F38: =+F$4*$C38 -> 0 | G38: =+G$4*$C38 -> 0.0037177647 | H38: =+H$4*$C38 -> 0.0071884245 | I38: =+I$4*$C38 -> 0.010415065 | J38: =+J$4*$C38 -> 0.013403076 | K38: =+K$4*$C38 -> 0.019448187 | ... AE38: =+AE$4*$C38 -> 0.45642469
B39: Households | C39: =+E103 -> 0.6 | D39: =+D$4*$C39 -> 0 | E39: =+E$4*$C39 -> 0 | F39: =+F$4*$C39 -> 0 | G39: =+G$4*$C39 -> 0.0074355293 | H39: =+H$4*$C39 -> 0.014376849 | I39: =+I$4*$C39 -> 0.020830129 | J39: =+J$4*$C39 -> 0.026806152 | K39: =+K$4*$C39 -> 0.038896374 | ... AE39: =+AE$4*$C39 -> 0.91284938
A40: EN - Transportation | B40: Government | C40: =+C104 -> 0.05 | D40: =+D$5*$C40 -> 0 | E40: =+E$5*$C40 -> 0 | F40: =+F$5*$C40 -> 3.5677391e-05 | G40: =+G$5*$C40 -> 0.00017419431 | H40: =+H$5*$C40 -> 0.00032079695 | I40: =+I$5*$C40 -> 0.00047576241 | J40: =+J$5*$C40 -> 0.00063975404 | K40: =+K$5*$C40 -> 0.00081266327 | ... AE40: =+AE$5*$C40 -> 0.036571274
B41: Firms | C41: =+D104 -> 0.4 | D41: =+D$5*$C41 -> 0 | E41: =+E$5*$C41 -> 0 | F41: =+F$5*$C41 -> 0.00028541912 | G41: =+G$5*$C41 -> 0.0013935545 | H41: =+H$5*$C41 -> 0.0025663756 | I41: =+I$5*$C41 -> 0.0038060992 | J41: =+J$5*$C41 -> 0.0051180323 | K41: =+K$5*$C41 -> 0.0065013062 | ... AE41: =+AE$5*$C41 -> 0.2925702
B42: Households | C42: =+E104 -> 0.55 | D42: =+D$5*$C42 -> 0 | E42: =+E$5*$C42 -> 0 | F42: =+F$5*$C42 -> 0.0003924513 | G42: =+G$5*$C42 -> 0.0019161374 | H42: =+H$5*$C42 -> 0.0035287664 | I42: =+I$5*$C42 -> 0.0052333865 | J42: =+J$5*$C42 -> 0.0070372944 | K42: =+K$5*$C42 -> 0.008939296 | ... AE42: =+AE$5*$C42 -> 0.40228402
A43: EN - Industrial combustion | B43: Government | C43: =+C105 -> 0.05 | D43: =+D$6*$C43 -> 0 | E43: =+E$6*$C43 -> 0 | F43: =+F$6*$C43 -> 0.00074892041 | G43: =+G$6*$C43 -> 0.0019299549 | H43: =+H$6*$C43 -> 0.0030925482 | I43: =+I$6*$C43 -> 0.0043864447 | J43: =+J$6*$C43 -> 0.0056638739 | K43: =+K$6*$C43 -> 0.0069285844 | ... AE43: =+AE$6*$C43 -> 0.03238713
B44: Firms | C44: =+D105 -> 0.95 | D44: =+D$6*$C44 -> 0 | E44: =+E$6*$C44 -> 0 | F44: =+F$6*$C44 -> 0.014229488 | G44: =+G$6*$C44 -> 0.036669143 | H44: =+H$6*$C44 -> 0.058758416 | I44: =+I$6*$C44 -> 0.08334245 | J44: =+J$6*$C44 -> 0.1076136 | K44: =+K$6*$C44 -> 0.1316431 | ... AE44: =+AE$6*$C44 -> 0.61535547
...

Sheet SAM
A1: Morocco SAM sector | B1: EN - Power Industry | C1: EN - Power Industry - Government | D1: EN - Power Industry - Firms | E1: EN - Power Industry - Households | F1: EN - Building | G1: EN - Building - Government | H1: EN - Building - Firms | I1: EN - Building - Households | J1: EN - Transportation | K1: EN - Transportation - Government | L1: EN - Transportation - Firms | M1: EN - Transportation - Households | N1: EN - Industrial combustion | O1: EN - Industrial combustion - Government | P1: EN - Industrial combustion - Firms | Q1: EN - Industrial combustion - Households | R1: IN - Industrial processes | S1: IN - Industrial processes - Government | T1: IN - Industrial processes - Firms | U1: IN - Industrial processes - Households | V1: Waste - Solid waste | W1: Waste - Solid waste - Government | X1: Waste - Solid waste - Firms | Y1: Waste - Solid waste - Households | Z1: Waste - Wastewater treatment (trww) | AA1: Waste - Wastewater treatment (trww) - Government | AB1: Waste - Wastewater treatment (trww) - Firms | AC1: Waste - Wastewater treatment (trww) - Households | AD1: Waste - Wastewater (liquid waste) | AE1: Waste - Wastewater (liquid waste) - Government | AF1: Waste - Wastewater (liquid waste) - Firms | AG1: Waste - Wastewater (liquid waste) - Households | AH1: AG - Livestock (manure) | AI1: AG - Livestock (manure) - Government | AJ1: AG - Livestock (manure) - Firms | AK1: AG - Livestock (manure) - Households | AL1: LULUCF - Forest land | AM1: LULUCF - Forest land - Government | AN1: LULUCF - Forest land - Firms | AO1: LULUCF - Forest land - Households
A2: crops | C2: =+$B2*Total!C$102 -> 0 | D2: =+$B2*Total!D$102 -> 0 | E2: =+$B2*Total!E$102 -> 0 | G2: =$F2*Total!C$103 -> 0 | H2: =$F2*Total!D$103 -> 0 | I2: =$F2*Total!E$103 -> 0 | K2: =$J2*Total!C$104 -> 0 | L2: =$J2*Total!D$104 -> 0 | M2: =$J2*Total!E$104 -> 0 | O2: =$N2*Total!C$105 -> 0 | P2: =$N2*Total!D$105 -> 0 | Q2: =$N2*Total!E$105 -> 0 | S2: =$R2*Total!C$106 -> 0 | T2: =$R2*Total!D$106 -> 0 | U2: =$R2*Total!E$106 -> 0 | W2: =$V2*Total!C$107 -> 0 | X2: =$V2*Total!D$107 -> 0 | Y2: =$V2*Total!E$107 -> 0 | AA2: =$Z2*Total!C$108 -> 0 | AB2: =$Z2*Total!D$108 -> 0 | AC2: =$Z2*Total!E$108 -> 0 | AE2: 0 | AF2: 0 | AG2: 0 | AI2: =$AH2*Total!C$110 -> 0 | AJ2: =$AH2*Total!D$110 -> 0 | AK2: =$AH2*Total!E$110 -> 0 | AL2: 0.15 | AM2: =$AL2*Total!C$111 -> 0.1275 | AN2: =$AL2*Total!D$111 -> 0.015 | AO2: =$AL2*Total!E$111 -> 0.0075
A3: forestry | C3: =+$B3*Total!C$102 -> 0 | D3: =+$B3*Total!D$102 -> 0 | E3: =+$B3*Total!E$102 -> 0 | G3: =$F3*Total!C$103 -> 0 | H3: =$F3*Total!D$103 -> 0 | I3: =$F3*Total!E$103 -> 0 | K3: =$J3*Total!C$104 -> 0 | L3: =$J3*Total!D$104 -> 0 | M3: =$J3*Total!E$104 -> 0 | O3: =$N3*Total!C$105 -> 0 | P3: =$N3*Total!D$105 -> 0 | Q3: =$N3*Total!E$105 -> 0 | S3: =$R3*Total!C$106 -> 0 | T3: =$R3*Total!D$106 -> 0 | U3: =$R3*Total!E$106 -> 0 | W3: =$V3*Total!C$107 -> 0 | X3: =$V3*Total!D$107 -> 0 | Y3: =$V3*Total!E$107 -> 0 | AA3: =$Z3*Total!C$108 -> 0 | AB3: =$Z3*Total!D$108 -> 0 | AC3: =$Z3*Total!E$108 -> 0 | AE3: 0 | AF3: 0 | AG3: 0 | AI3: =$AH3*Total!C$110 -> 0 | AJ3: =$AH3*Total!D$110 -> 0 | AK3: =$AH3*Total!E$110 -> 0 | AL3: 0.35 | AM3: =$AL3*Total!C$111 -> 0.2975 | AN3: =$AL3*Total!D$111 -> 0.035 | AO3: =$AL3*Total!E$111 -> 0.0175
A4: livestock | C4: =+$B4*Total!C$102 -> 0 | D4: =+$B4*Total!D$102 -> 0 | E4: =+$B4*Total!E$102 -> 0 | G4: =$F4*Total!C$103 -> 0 | H4: =$F4*Total!D$103 -> 0 | I4: =$F4*Total!E$103 -> 0 | K4: =$J4*Total!C$104 -> 0 | L4: =$J4*Total!D$104 -> 0 | M4: =$J4*Total!E$104 -> 0 | O4: =$N4*Total!C$105 -> 0 | P4: =$N4*Total!D$105 -> 0 | Q4: =$N4*Total!E$105 -> 0 | S4: =$R4*Total!C$106 -> 0 | T4: =$R4*Total!D$106 -> 0 | U4: =$R4*Total!E$106 -> 0 | W4: =$V4*Total!C$107 -> 0 | X4: =$V4*Total!D$107 -> 0 | Y4: =$V4*Total!E$107 -> 0 | AA4: =$Z4*Total!C$108 -> 0 | AB4: =$Z4*Total!D$108 -> 0 | AC4: =$Z4*Total!E$108 -> 0 | AE4: 0 | AF4: 0 | AG4: 0 | AI4: =$AH4*Total!C$110 -> 0 | AJ4: =$AH4*Total!D$110 -> 0 | AK4: =$AH4*Total!E$110 -> 0 | AM4: =$AL4*Total!C$111 -> 0 | AN4: =$AL4*Total!D$111 -> 0 | AO4: =$AL4*Total!E$111 -> 0
A5: fishery and aquaculture | C5: =+$B5*Total!C$102 -> 0 | D5: =+$B5*Total!D$102 -> 0 | E5: =+$B5*Total!E$102 -> 0 | G5: =$F5*Total!C$103 -> 0 | H5: =$F5*Total!D$103 -> 0 | I5: =$F5*Total!E$103 -> 0 | K5: =$J5*Total!C$104 -> 0 | L5: =$J5*Total!D$104 -> 0 | M5: =$J5*Total!E$104 -> 0 | O5: =$N5*Total!C$105 -> 0 | P5: =$N5*Total!D$105 -> 0 | Q5: =$N5*Total!E$105 -> 0 | S5: =$R5*Total!C$106 -> 0 | T5: =$R5*Total!D$106 -> 0 | U5: =$R5*Total!E$106 -> 0 | W5: =$V5*Total!C$107 -> 0 | X5: =$V5*Total!D$107 -> 0 | Y5: =$V5*Total!E$107 -> 0 | AA5: =$Z5*Total!C$108 -> 0 | AB5: =$Z5*Total!D$108 -> 0 | AC5: =$Z5*Total!E$108 -> 0 | AE5: 0 | AF5: 0 | AG5: 0 | AI5: =$AH5*Total!C$110 -> 0 | AJ5: =$AH5*Total!D$110 -> 0 | AK5: =$AH5*Total!E$110 -> 0 | AM5: =$AL5*Total!C$111 -> 0 | AN5: =$AL5*Total!D$111 -> 0 | AO5: =$AL5*Total!E$111 -> 0
A6: Extractive activities | C6: =+$B6*Total!C$102 -> 0 | D6: =+$B6*Total!D$102 -> 0 | E6: =+$B6*Total!E$102 -> 0 | G6: =$F6*Total!C$103 -> 0 | H6: =$F6*Total!D$103 -> 0 | I6: =$F6*Total!E$103 -> 0 | K6: =$J6*Total!C$104 -> 0 | L6: =$J6*Total!D$104 -> 0 | M6: =$J6*Total!E$104 -> 0 | O6: =$N6*Total!C$105 -> 0 | P6: =$N6*Total!D$105 -> 0 | Q6: =$N6*Total!E$105 -> 0 | S6: =$R6*Total!C$106 -> 0 | T6: =$R6*Total!D$106 -> 0 | U6: =$R6*Total!E$106 -> 0 | W6: =$V6*Total!C$107 -> 0 | X6: =$V6*Total!D$107 -> 0 | Y6: =$V6*Total!E$107 -> 0 | AA6: =$Z6*Total!C$108 -> 0 | AB6: =$Z6*Total!D$108 -> 0 | AC6: =$Z6*Total!E$108 -> 0 | AE6: 0 | AF6: 0 | AG6: 0 | AI6: =$AH6*Total!C$110 -> 0 | AJ6: =$AH6*Total!D$110 -> 0 | AK6: =$AH6*Total!E$110 -> 0 | AM6: =$AL6*Total!C$111 -> 0 | AN6: =$AL6*Total!D$111 -> 0 | AO6: =$AL6*Total!E$111 -> 0
A7: food manufacturing and beverage | C7: =+$B7*Total!C$102 -> 0 | D7: =+$B7*Total!D$102 -> 0 | E7: =+$B7*Total!E$102 -> 0 | G7: =$F7*Total!C$103 -> 0 | H7: =$F7*Total!D$103 -> 0 | I7: =$F7*Total!E$103 -> 0 | K7: =$J7*Total!C$104 -> 0 | L7: =$J7*Total!D$104 -> 0 | M7: =$J7*Total!E$104 -> 0 | O7: =$N7*Total!C$105 -> 0 | P7: =$N7*Total!D$105 -> 0 | Q7: =$N7*Total!E$105 -> 0 | S7: =$R7*Total!C$106 -> 0 | T7: =$R7*Total!D$106 -> 0 | U7: =$R7*Total!E$106 -> 0 | W7: =$V7*Total!C$107 -> 0 | X7: =$V7*Total!D$107 -> 0 | Y7: =$V7*Total!E$107 -> 0 | AA7: =$Z7*Total!C$108 -> 0 | AB7: =$Z7*Total!D$108 -> 0 | AC7: =$Z7*Total!E$108 -> 0 | AE7: 0 | AF7: 0 | AG7: 0 | AI7: =$AH7*Total!C$110 -> 0 | AJ7: =$AH7*Total!D$110 -> 0 | AK7: =$AH7*Total!E$110 -> 0 | AM7: =$AL7*Total!C$111 -> 0 | AN7: =$AL7*Total!D$111 -> 0 | AO7: =$AL7*Total!E$111 -> 0
A8: textile manufacturing and clothes | C8: =+$B8*Total!C$102 -> 0 | D8: =+$B8*Total!D$102 -> 0 | E8: =+$B8*Total!E$102 -> 0 | G8: =$F8*Total!C$103 -> 0 | H8: =$F8*Total!D$103 -> 0 | I8: =$F8*Total!E$103 -> 0 | K8: =$J8*Total!C$104 -> 0 | L8: =$J8*Total!D$104 -> 0 | M8: =$J8*Total!E$104 -> 0 | O8: =$N8*Total!C$105 -> 0 | P8: =$N8*Total!D$105 -> 0 | Q8: =$N8*Total!E$105 -> 0 | S8: =$R8*Total!C$106 -> 0 | T8: =$R8*Total!D$106 -> 0 | U8: =$R8*Total!E$106 -> 0 | W8: =$V8*Total!C$107 -> 0 | X8: =$V8*Total!D$107 -> 0 | Y8: =$V8*Total!E$107 -> 0 | AA8: =$Z8*Total!C$108 -> 0 | AB8: =$Z8*Total!D$108 -> 0 | AC8: =$Z8*Total!E$108 -> 0 | AE8: 0 | AF8: 0 | AG8: 0 | AI8: =$AH8*Total!C$110 -> 0 | AJ8: =$AH8*Total!D$110 -> 0 | AK8: =$AH8*Total!E$110 -> 0 | AM8: =$AL8*Total!C$111 -> 0 | AN8: =$AL8*Total!D$111 -> 0 | AO8: =$AL8*Total!E$111 -> 0
A9: Wood product manufacturing | C9: =+$B9*Total!C$102 -> 0 | D9: =+$B9*Total!D$102 -> 0 | E9: =+$B9*Total!E$102 -> 0 | F9: 0.03 | G9: =$F9*Total!C$103 -> 0.003 | H9: =$F9*Total!D$103 -> 0.009 | I9: =$F9*Total!E$103 -> 0.018 | K9: =$J9*Total!C$104 -> 0 | L9: =$J9*Total!D$104 -> 0 | M9: =$J9*Total!E$104 -> 0 | O9: =$N9*Total!C$105 -> 0 | P9: =$N9*Total!D$105 -> 0 | Q9: =$N9*Total!E$105 -> 0 | S9: =$R9*Total!C$106 -> 0 | T9: =$R9*Total!D$106 -> 0 | U9: =$R9*Total!E$106 -> 0 | W9: =$V9*Total!C$107 -> 0 | X9: =$V9*Total!D$107 -> 0 | Y9: =$V9*Total!E$107 -> 0 | AA9: =$Z9*Total!C$108 -> 0 | AB9: =$Z9*Total!D$108 -> 0 | AC9: =$Z9*Total!E$108 -> 0 | AE9: 0 | AF9: 0 | AG9: 0 | AI9: =$AH9*Total!C$110 -> 0 | AJ9: =$AH9*Total!D$110 -> 0 | AK9: =$AH9*Total!E$110 -> 0 | AM9: =$AL9*Total!C$111 -> 0 | AN9: =$AL9*Total!D$111 -> 0 | AO9: =$AL9*Total!E$111 -> 0
A10: coking and refining production | C10: =+$B10*Total!C$102 -> 0 | D10: =+$B10*Total!D$102 -> 0 | E10: =+$B10*Total!E$102 -> 0 | G10: =$F10*Total!C$103 -> 0 | H10: =$F10*Total!D$103 -> 0 | I10: =$F10*Total!E$103 -> 0 | K10: =$J10*Total!C$104 -> 0 | L10: =$J10*Total!D$104 -> 0 | M10: =$J10*Total!E$104 -> 0 | O10: =$N10*Total!C$105 -> 0 | P10: =$N10*Total!D$105 -> 0 | Q10: =$N10*Total!E$105 -> 0 | S10: =$R10*Total!C$106 -> 0 | T10: =$R10*Total!D$106 -> 0 | U10: =$R10*Total!E$106 -> 0 | W10: =$V10*Total!C$107 -> 0 | X10: =$V10*Total!D$107 -> 0 | Y10: =$V10*Total!E$107 -> 0 | AA10: =$Z10*Total!C$108 -> 0 | AB10: =$Z10*Total!D$108 -> 0 | AC10: =$Z10*Total!E$108 -> 0 | AE10: 0 | AF10: 0 | AG10: 0 | AI10: =$AH10*Total!C$110 -> 0 | AJ10: =$AH10*Total!D$110 -> 0 | AK10: =$AH10*Total!E$110 -> 0 | AM10: =$AL10*Total!C$111 -> 0 | AN10: =$AL10*Total!D$111 -> 0 | AO10: =$AL10*Total!E$111 -> 0
A11: chemical products | C11: =+$B11*Total!C$102 -> 0 | D11: =+$B11*Total!D$102 -> 0 | E11: =+$B11*Total!E$102 -> 0 | G11: =$F11*Total!C$103 -> 0 | H11: =$F11*Total!D$103 -> 0 | I11: =$F11*Total!E$103 -> 0 | K11: =$J11*Total!C$104 -> 0 | L11: =$J11*Total!D$104 -> 0 | M11: =$J11*Total!E$104 -> 0 | O11: =$N11*Total!C$105 -> 0 | P11: =$N11*Total!D$105 -> 0 | Q11: =$N11*Total!E$105 -> 0 | R11: 0.1 | S11: =$R11*Total!C$106 -> 0.005 | T11: =$R11*Total!D$106 -> 0.095 | U11: =$R11*Total!E$106 -> 0 | W11: =$V11*Total!C$107 -> 0 | X11: =$V11*Total!D$107 -> 0 | Y11: =$V11*Total!E$107 -> 0 | Z11: 0.04 | AA11: =$Z11*Total!C$108 -> 0.034 | AB11: =$Z11*Total!D$108 -> 0.006 | AC11: =$Z11*Total!E$108 -> 0 | AD11: 0.04 | AE11: =+$AD11*Total!C$109 -> 0.034 | AF11: =+$AD11*Total!D$109 -> 0.006 | AG11: =+$AD11*Total!E$109 -> 0 | AI11: =$AH11*Total!C$110 -> 0 | AJ11: =$AH11*Total!D$110 -> 0 | AK11: =$AH11*Total!E$110 -> 0 | AM11: =$AL11*Total!C$111 -> 0 | AN11: =$AL11*Total!D$111 -> 0 | AO11: =$AL11*Total!E$111 -> 0
A12: pharmaceutical products | C12: =+$B12*Total!C$102 -> 0 | D12: =+$B12*Total!D$102 -> 0 | E12: =+$B12*Total!E$102 -> 0 | G12: =$F12*Total!C$103 -> 0 | H12: =$F12*Total!D$103 -> 0 | I12: =$F12*Total!E$103 -> 0 | K12: =$J12*Total!C$104 -> 0 | L12: =$J12*Total!D$104 -> 0 | M12: =$J12*Total!E$104 -> 0 | O12: =$N12*Total!C$105 -> 0 | P12: =$N12*Total!D$105 -> 0 | Q12: =$N12*Total!E$105 -> 0 | S12: =$R12*Total!C$106 -> 0 | T12: =$R12*Total!D$106 -> 0 | U12: =$R12*Total!E$106 -> 0 | W12: =$V12*Total!C$107 -> 0 | X12: =$V12*Total!D$107 -> 0 | Y12: =$V12*Total!E$107 -> 0 | AA12: =$Z12*Total!C$108 -> 0 | AB12: =$Z12*Total!D$108 -> 0 | AC12: =$Z12*Total!E$108 -> 0 | AE12: 0 | AF12: 0 | AG12: 0 | AI12: =$AH12*Total!C$110 -> 0 | AJ12: =$AH12*Total!D$110 -> 0 | AK12: =$AH12*Total!E$110 -> 0 | AM12: =$AL12*Total!C$111 -> 0 | AN12: =$AL12*Total!D$111 -> 0 | AO12: =$AL12*Total!E$111 -> 0
A13: rubber manufacturing | C13: =+$B13*Total!C$102 -> 0 | D13: =+$B13*Total!D$102 -> 0 | E13: =+$B13*Total!E$102 -> 0 | G13: =$F13*Total!C$103 -> 0 | H13: =$F13*Total!D$103 -> 0 | I13: =$F13*Total!E$103 -> 0 | K13: =$J13*Total!C$104 -> 0 | L13: =$J13*Total!D$104 -> 0 | M13: =$J13*Total!E$104 -> 0 | O13: =$N13*Total!C$105 -> 0 | P13: =$N13*Total!D$105 -> 0 | Q13: =$N13*Total!E$105 -> 0 | S13: =$R13*Total!C$106 -> 0 | T13: =$R13*Total!D$106 -> 0 | U13: =$R13*Total!E$106 -> 0 | W13: =$V13*Total!C$107 -> 0 | X13: =$V13*Total!D$107 -> 0 | Y13: =$V13*Total!E$107 -> 0 | AA13: =$Z13*Total!C$108 -> 0 | AB13: =$Z13*Total!D$108 -> 0 | AC13: =$Z13*Total!E$108 -> 0 | AE13: 0 | AF13: 0 | AG13: 0 | AI13: =$AH13*Total!C$110 -> 0 | AJ13: =$AH13*Total!D$110 -> 0 | AK13: =$AH13*Total!E$110 -> 0 | AM13: =$AL13*Total!C$111 -> 0 | AN13: =$AL13*Total!D$111 -> 0 | AO13: =$AL13*Total!E$111 -> 0
A14: metalwork manufacturing | B14: 0.059 | C14: =+$B14*Total!C$102 -> 0.01475 | D14: =+$B14*Total!D$102 -> 0.0413 | E14: =+$B14*Total!E$102 -> 0.00295 | G14: =$F14*Total!C$103 -> 0 | H14: =$F14*Total!D$103 -> 0 | I14: =$F14*Total!E$103 -> 0 | K14: =$J14*Total!C$104 -> 0 | L14: =$J14*Total!D$104 -> 0 | M14: =$J14*Total!E$104 -> 0 | N14: 0.12 | O14: =$N14*Total!C$105 -> 0.006 | P14: =$N14*Total!D$105 -> 0.114 | Q14: =$N14*Total!E$105 -> 0 | R14: 0.15 | S14: =$R14*Total!C$106 -> 0.0075 | T14: =$R14*Total!D$106 -> 0.1425 | U14: =$R14*Total!E$106 -> 0 | W14: =$V14*Total!C$107 -> 0 | X14: =$V14*Total!D$107 -> 0 | Y14: =$V14*Total!E$107 -> 0 | AA14: =$Z14*Total!C$108 -> 0 | AB14: =$Z14*Total!D$108 -> 0 | AC14: =$Z14*Total!E$108 -> 0 | AE14: 0 | AF14: 0 | AG14: 0 | AI14: =$AH14*Total!C$110 -> 0 | AJ14: =$AH14*Total!D$110 -> 0 | AK14: =$AH14*Total!E$110 -> 0 | AM14: =$AL14*Total!C$111 -> 0 | AN14: =$AL14*Total!D$111 -> 0 | AO14: =$AL14*Total!E$111 -> 0
A15: Manufacture of computer, electronic and optical products | B15: 0.0111 | C15: =+$B15*Total!C$102 -> 0.002775 | D15: =+$B15*Total!D$102 -> 0.00777 | E15: =+$B15*Total!E$102 -> 0.000555 | G15: =$F15*Total!C$103 -> 0 | H15: =$F15*Total!D$103 -> 0 | I15: =$F15*Total!E$103 -> 0 | K15: =$J15*Total!C$104 -> 0 | L15: =$J15*Total!D$104 -> 0 | M15: =$J15*Total!E$104 -> 0 | O15: =$N15*Total!C$105 -> 0 | P15: =$N15*Total!D$105 -> 0 | Q15: =$N15*Total!E$105 -> 0 | S15: =$R15*Total!C$106 -> 0 | T15: =$R15*Total!D$106 -> 0 | U15: =$R15*Total!E$106 -> 0 | W15: =$V15*Total!C$107 -> 0 | X15: =$V15*Total!D$107 -> 0 | Y15: =$V15*Total!E$107 -> 0 | AA15: =$Z15*Total!C$108 -> 0 | AB15: =$Z15*Total!D$108 -> 0 | AC15: =$Z15*Total!E$108 -> 0 | AE15: 0 | AF15: 0 | AG15: 0 | AI15: =$AH15*Total!C$110 -> 0 | AJ15: =$AH15*Total!D$110 -> 0 | AK15: =$AH15*Total!E$110 -> 0 | AM15: =$AL15*Total!C$111 -> 0 | AN15: =$AL15*Total!D$111 -> 0 | AO15: =$AL15*Total!E$111 -> 0
A16: electrical equipment manufacturing | B16: 0.0872 | C16: =+$B16*Total!C$102 -> 0.0218 | D16: =+$B16*Total!D$102 -> 0.06104 | E16: =+$B16*Total!E$102 -> 0.00436 | F16: 0.15 | G16: =$F16*Total!C$103 -> 0.015 | H16: =$F16*Total!D$103 -> 0.045 | I16: =$F16*Total!E$103 -> 0.09 | J16: 0.08 | K16: =$J16*Total!C$104 -> 0.004 | L16: =$J16*Total!D$104 -> 0.032 | M16: =$J16*Total!E$104 -> 0.044 | N16: 0.08 | O16: =$N16*Total!C$105 -> 0.004 | P16: =$N16*Total!D$105 -> 0.076 | Q16: =$N16*Total!E$105 -> 0 | S16: =$R16*Total!C$106 -> 0 | T16: =$R16*Total!D$106 -> 0 | U16: =$R16*Total!E$106 -> 0 | W16: =$V16*Total!C$107 -> 0 | X16: =$V16*Total!D$107 -> 0 | Y16: =$V16*Total!E$107 -> 0 | AA16: =$Z16*Total!C$108 -> 0 | AB16: =$Z16*Total!D$108 -> 0 | AC16: =$Z16*Total!E$108 -> 0 | AE16: 0 | AF16: 0 | AG16: 0 | AI16: =$AH16*Total!C$110 -> 0 | AJ16: =$AH16*Total!D$110 -> 0 | AK16: =$AH16*Total!E$110 -> 0 | AM16: =$AL16*Total!C$111 -> 0 | AN16: =$AL16*Total!D$111 -> 0 | AO16: =$AL16*Total!E$111 -> 0
A17: machinery and equipment manufacturing | B17: 0.0772 | C17: =+$B17*Total!C$102 -> 0.0193 | D17: =+$B17*Total!D$102 -> 0.05404 | E17: =+$B17*Total!E$102 -> 0.00386 | F17: 0.05 | G17: =$F17*Total!C$103 -> 0.005 | H17: =$F17*Total!D$103 -> 0.015 | I17: =$F17*Total!E$103 -> 0.03 | K17: =$J17*Total!C$104 -> 0 | L17: =$J17*Total!D$104 -> 0 | M17: =$J17*Total!E$104 -> 0 | N17: 0.25 | O17: =$N17*Total!C$105 -> 0.0125 | P17: =$N17*Total!D$105 -> 0.2375 | Q17: =$N17*Total!E$105 -> 0 | R17: 0.3 | S17: =$R17*Total!C$106 -> 0.015 | T17: =$R17*Total!D$106 -> 0.285 | U17: =$R17*Total!E$106 -> 0 | V17: 0.2 | W17: =$V17*Total!C$107 -> 0.16 | X17: =$V17*Total!D$107 -> 0.04 | Y17: =$V17*Total!E$107 -> 0 | Z17: 0.15 | AA17: =$Z17*Total!C$108 -> 0.1275 | AB17: =$Z17*Total!D$108 -> 0.0225 | AC17: =$Z17*Total!E$108 -> 0 | AD17: 0.15 | AE17: =+$AD17*Total!C$109 -> 0.1275 | AF17: =+$AD17*Total!D$109 -> 0.0225 | AG17: =+$AD17*Total!E$109 -> 0 | AI17: =$AH17*Total!C$110 -> 0 | AJ17: =$AH17*Total!D$110 -> 0 | AK17: =$AH17*Total!E$110 -> 0 | AM17: =$AL17*Total!C$111 -> 0 | AN17: =$AL17*Total!D$111 -> 0 | AO17: =$AL17*Total!E$111 -> 0
A18: transport equipment manufacturing | B18: 0.0282 | C18: =+$B18*Total!C$102 -> 0.00705 | D18: =+$B18*Total!D$102 -> 0.01974 | E18: =+$B18*Total!E$102 -> 0.00141 | G18: =$F18*Total!C$103 -> 0 | H18: =$F18*Total!D$103 -> 0 | I18: =$F18*Total!E$103 -> 0 | J18: 0.15 | K18: =$J18*Total!C$104 -> 0.0075 | L18: =$J18*Total!D$104 -> 0.06 | M18: =$J18*Total!E$104 -> 0.0825 | O18: =$N18*Total!C$105 -> 0 | P18: =$N18*Total!D$105 -> 0 | Q18: =$N18*Total!E$105 -> 0 | S18: =$R18*Total!C$106 -> 0 | T18: =$R18*Total!D$106 -> 0 | U18: =$R18*Total!E$106 -> 0 | V18: 0.1 | W18: =$V18*Total!C$107 -> 0.08 | X18: =$V18*Total!D$107 -> 0.02 | Y18: =$V18*Total!E$107 -> 0 | AA18: =$Z18*Total!C$108 -> 0 | AB18: =$Z18*Total!D$108 -> 0 | AC18: =$Z18*Total!E$108 -> 0 | AE18: 0 | AF18: 0 | AG18: 0 | AI18: =$AH18*Total!C$110 -> 0 | AJ18: =$AH18*Total!D$110 -> 0 | AK18: =$AH18*Total!E$110 -> 0 | AM18: =$AL18*Total!C$111 -> 0 | AN18: =$AL18*Total!D$111 -> 0 | AO18: =$AL18*Total!E$111 -> 0
A19: other manufacturing | C19: =+$B19*Total!C$102 -> 0 | D19: =+$B19*Total!D$102 -> 0 | E19: =+$B19*Total!E$102 -> 0 | G19: =$F19*Total!C$103 -> 0 | H19: =$F19*Total!D$103 -> 0 | I19: =$F19*Total!E$103 -> 0 | K19: =$J19*Total!C$104 -> 0 | L19: =$J19*Total!D$104 -> 0 | M19: =$J19*Total!E$104 -> 0 | O19: =$N19*Total!C$105 -> 0 | P19: =$N19*Total!D$105 -> 0 | Q19: =$N19*Total!E$105 -> 0 | S19: =$R19*Total!C$106 -> 0 | T19: =$R19*Total!D$106 -> 0 | U19: =$R19*Total!E$106 -> 0 | W19: =$V19*Total!C$107 -> 0 | X19: =$V19*Total!D$107 -> 0 | Y19: =$V19*Total!E$107 -> 0 | AA19: =$Z19*Total!C$108 -> 0 | AB19: =$Z19*Total!D$108 -> 0 | AC19: =$Z19*Total!E$108 -> 0 | AE19: 0 | AF19: 0 | AG19: 0 | AI19: =$AH19*Total!C$110 -> 0 | AJ19: =$AH19*Total!D$110 -> 0 | AK19: =$AH19*Total!E$110 -> 0 | AM19: =$AL19*Total!C$111 -> 0 | AN19: =$AL19*Total!D$111 -> 0 | AO19: =$AL19*Total!E$111 -> 0
A20: electricity generation - coal | C20: =+$B20*Total!C$102 -> 0 | D20: =+$B20*Total!D$102 -> 0 | E20: =+$B20*Total!E$102 -> 0 | G20: =$F20*Total!C$103 -> 0 | H20: =$F20*Total!D$103 -> 0 | I20: =$F20*Total!E$103 -> 0 | K20: =$J20*Total!C$104 -> 0 | L20: =$J20*Total!D$104 -> 0 | M20: =$J20*Total!E$104 -> 0 | O20: =$N20*Total!C$105 -> 0 | P20: =$N20*Total!D$105 -> 0 | Q20: =$N20*Total!E$105 -> 0 | S20: =$R20*Total!C$106 -> 0 | T20: =$R20*Total!D$106 -> 0 | U20: =$R20*Total!E$106 -> 0 | W20: =$V20*Total!C$107 -> 0 | X20: =$V20*Total!D$107 -> 0 | Y20: =$V20*Total!E$107 -> 0 | AA20: =$Z20*Total!C$108 -> 0 | AB20: =$Z20*Total!D$108 -> 0 | AC20: =$Z20*Total!E$108 -> 0 | AE20: 0 | AF20: 0 | AG20: 0 | AI20: =$AH20*Total!C$110 -> 0 | AJ20: =$AH20*Total!D$110 -> 0 | AK20: =$AH20*Total!E$110 -> 0 | AM20: =$AL20*Total!C$111 -> 0 | AN20: =$AL20*Total!D$111 -> 0 | AO20: =$AL20*Total!E$111 -> 0
A21: electricity generation - oil | C21: =+$B21*Total!C$102 -> 0 | D21: =+$B21*Total!D$102 -> 0 | E21: =+$B21*Total!E$102 -> 0 | G21: =$F21*Total!C$103 -> 0 | H21: =$F21*Total!D$103 -> 0 | I21: =$F21*Total!E$103 -> 0 | K21: =$J21*Total!C$104 -> 0 | L21: =$J21*Total!D$104 -> 0 | M21: =$J21*Total!E$104 -> 0 | O21: =$N21*Total!C$105 -> 0 | P21: =$N21*Total!D$105 -> 0 | Q21: =$N21*Total!E$105 -> 0 | S21: =$R21*Total!C$106 -> 0 | T21: =$R21*Total!D$106 -> 0 | U21: =$R21*Total!E$106 -> 0 | W21: =$V21*Total!C$107 -> 0 | X21: =$V21*Total!D$107 -> 0 | Y21: =$V21*Total!E$107 -> 0 | AA21: =$Z21*Total!C$108 -> 0 | AB21: =$Z21*Total!D$108 -> 0 | AC21: =$Z21*Total!E$108 -> 0 | AE21: 0 | AF21: 0 | AG21: 0 | AI21: =$AH21*Total!C$110 -> 0 | AJ21: =$AH21*Total!D$110 -> 0 | AK21: =$AH21*Total!E$110 -> 0 | AM21: =$AL21*Total!C$111 -> 0 | AN21: =$AL21*Total!D$111 -> 0 | AO21: =$AL21*Total!E$111 -> 0
A22: electricity generation - natural gas | C22: =+$B22*Total!C$102 -> 0 | D22: =+$B22*Total!D$102 -> 0 | E22: =+$B22*Total!E$102 -> 0 | G22: =$F22*Total!C$103 -> 0 | H22: =$F22*Total!D$103 -> 0 | I22: =$F22*Total!E$103 -> 0 | K22: =$J22*Total!C$104 -> 0 | L22: =$J22*Total!D$104 -> 0 | M22: =$J22*Total!E$104 -> 0 | O22: =$N22*Total!C$105 -> 0 | P22: =$N22*Total!D$105 -> 0 | Q22: =$N22*Total!E$105 -> 0 | S22: =$R22*Total!C$106 -> 0 | T22: =$R22*Total!D$106 -> 0 | U22: =$R22*Total!E$106 -> 0 | W22: =$V22*Total!C$107 -> 0 | X22: =$V22*Total!D$107 -> 0 | Y22: =$V22*Total!E$107 -> 0 | AA22: =$Z22*Total!C$108 -> 0 | AB22: =$Z22*Total!D$108 -> 0 | AC22: =$Z22*Total!E$108 -> 0 | AE22: 0 | AF22: 0 | AG22: 0 | AI22: =$AH22*Total!C$110 -> 0 | AJ22: =$AH22*Total!D$110 -> 0 | AK22: =$AH22*Total!E$110 -> 0 | AM22: =$AL22*Total!C$111 -> 0 | AN22: =$AL22*Total!D$111 -> 0 | AO22: =$AL22*Total!E$111 -> 0
A23: electricity generation - hydro | C23: =+$B23*Total!C$102 -> 0 | D23: =+$B23*Total!D$102 -> 0 | E23: =+$B23*Total!E$102 -> 0 | G23: =$F23*Total!C$103 -> 0 | H23: =$F23*Total!D$103 -> 0 | I23: =$F23*Total!E$103 -> 0 | K23: =$J23*Total!C$104 -> 0 | L23: =$J23*Total!D$104 -> 0 | M23: =$J23*Total!E$104 -> 0 | O23: =$N23*Total!C$105 -> 0 | P23: =$N23*Total!D$105 -> 0 | Q23: =$N23*Total!E$105 -> 0 | S23: =$R23*Total!C$106 -> 0 | T23: =$R23*Total!D$106 -> 0 | U23: =$R23*Total!E$106 -> 0 | W23: =$V23*Total!C$107 -> 0 | X23: =$V23*Total!D$107 -> 0 | Y23: =$V23*Total!E$107 -> 0 | AA23: =$Z23*Total!C$108 -> 0 | AB23: =$Z23*Total!D$108 -> 0 | AC23: =$Z23*Total!E$108 -> 0 | AE23: 0 | AF23: 0 | AG23: 0 | AI23: =$AH23*Total!C$110 -> 0 | AJ23: =$AH23*Total!D$110 -> 0 | AK23: =$AH23*Total!E$110 -> 0 | AM23: =$AL23*Total!C$111 -> 0 | AN23: =$AL23*Total!D$111 -> 0 | AO23: =$AL23*Total!E$111 -> 0
A24: electricity generation - wind | C24: =+$B24*Total!C$102 -> 0 | D24: =+$B24*Total!D$102 -> 0 | E24: =+$B24*Total!E$102 -> 0 | G24: =$F24*Total!C$103 -> 0 | H24: =$F24*Total!D$103 -> 0 | I24: =$F24*Total!E$103 -> 0 | K24: =$J24*Total!C$104 -> 0 | L24: =$J24*Total!D$104 -> 0 | M24: =$J24*Total!E$104 -> 0 | O24: =$N24*Total!C$105 -> 0 | P24: =$N24*Total!D$105 -> 0 | Q24: =$N24*Total!E$105 -> 0 | S24: =$R24*Total!C$106 -> 0 | T24: =$R24*Total!D$106 -> 0 | U24: =$R24*Total!E$106 -> 0 | W24: =$V24*Total!C$107 -> 0 | X24: =$V24*Total!D$107 -> 0 | Y24: =$V24*Total!E$107 -> 0 | AA24: =$Z24*Total!C$108 -> 0 | AB24: =$Z24*Total!D$108 -> 0 | AC24: =$Z24*Total!E$108 -> 0 | AE24: 0 | AF24: 0 | AG24: 0 | AI24: =$AH24*Total!C$110 -> 0 | AJ24: =$AH24*Total!D$110 -> 0 | AK24: =$AH24*Total!E$110 -> 0 | AM24: =$AL24*Total!C$111 -> 0 | AN24: =$AL24*Total!D$111 -> 0 | AO24: =$AL24*Total!E$111 -> 0
A25: electricity generation - solar | C25: =+$B25*Total!C$102 -> 0 | D25: =+$B25*Total!D$102 -> 0 | E25: =+$B25*Total!E$102 -> 0 | G25: =$F25*Total!C$103 -> 0 | H25: =$F25*Total!D$103 -> 0 | I25: =$F25*Total!E$103 -> 0 | K25: =$J25*Total!C$104 -> 0 | L25: =$J25*Total!D$104 -> 0 | M25: =$J25*Total!E$104 -> 0 | O25: =$N25*Total!C$105 -> 0 | P25: =$N25*Total!D$105 -> 0 | Q25: =$N25*Total!E$105 -> 0 | S25: =$R25*Total!C$106 -> 0 | T25: =$R25*Total!D$106 -> 0 | U25: =$R25*Total!E$106 -> 0 | W25: =$V25*Total!C$107 -> 0 | X25: =$V25*Total!D$107 -> 0 | Y25: =$V25*Total!E$107 -> 0 | AA25: =$Z25*Total!C$108 -> 0 | AB25: =$Z25*Total!D$108 -> 0 | AC25: =$Z25*Total!E$108 -> 0 | AE25: 0 | AF25: 0 | AG25: 0 | AI25: =$AH25*Total!C$110 -> 0 | AJ25: =$AH25*Total!D$110 -> 0 | AK25: =$AH25*Total!E$110 -> 0 | AM25: =$AL25*Total!C$111 -> 0 | AN25: =$AL25*Total!D$111 -> 0 | AO25: =$AL25*Total!E$111 -> 0
A26: electricity generation - other sources | C26: =+$B26*Total!C$102 -> 0 | D26: =+$B26*Total!D$102 -> 0 | E26: =+$B26*Total!E$102 -> 0 | G26: =$F26*Total!C$103 -> 0 | H26: =$F26*Total!D$103 -> 0 | I26: =$F26*Total!E$103 -> 0 | K26: =$J26*Total!C$104 -> 0 | L26: =$J26*Total!D$104 -> 0 | M26: =$J26*Total!E$104 -> 0 | O26: =$N26*Total!C$105 -> 0 | P26: =$N26*Total!D$105 -> 0 | Q26: =$N26*Total!E$105 -> 0 | S26: =$R26*Total!C$106 -> 0 | T26: =$R26*Total!D$106 -> 0 | U26: =$R26*Total!E$106 -> 0 | W26: =$V26*Total!C$107 -> 0 | X26: =$V26*Total!D$107 -> 0 | Y26: =$V26*Total!E$107 -> 0 | AA26: =$Z26*Total!C$108 -> 0 | AB26: =$Z26*Total!D$108 -> 0 | AC26: =$Z26*Total!E$108 -> 0 | AE26: 0 | AF26: 0 | AG26: 0 | AI26: =$AH26*Total!C$110 -> 0 | AJ26: =$AH26*Total!D$110 -> 0 | AK26: =$AH26*Total!E$110 -> 0 | AM26: =$AL26*Total!C$111 -> 0 | AN26: =$AL26*Total!D$111 -> 0 | AO26: =$AL26*Total!E$111 -> 0
A27: electricity transmission and distribution | C27: =+$B27*Total!C$102 -> 0 | D27: =+$B27*Total!D$102 -> 0 | E27: =+$B27*Total!E$102 -> 0 | G27: =$F27*Total!C$103 -> 0 | H27: =$F27*Total!D$103 -> 0 | I27: =$F27*Total!E$103 -> 0 | K27: =$J27*Total!C$104 -> 0 | L27: =$J27*Total!D$104 -> 0 | M27: =$J27*Total!E$104 -> 0 | O27: =$N27*Total!C$105 -> 0 | P27: =$N27*Total!D$105 -> 0 | Q27: =$N27*Total!E$105 -> 0 | S27: =$R27*Total!C$106 -> 0 | T27: =$R27*Total!D$106 -> 0 | U27: =$R27*Total!E$106 -> 0 | W27: =$V27*Total!C$107 -> 0 | X27: =$V27*Total!D$107 -> 0 | Y27: =$V27*Total!E$107 -> 0 | AA27: =$Z27*Total!C$108 -> 0 | AB27: =$Z27*Total!D$108 -> 0 | AC27: =$Z27*Total!E$108 -> 0 | AE27: 0 | AF27: 0 | AG27: 0 | AI27: =$AH27*Total!C$110 -> 0 | AJ27: =$AH27*Total!D$110 -> 0 | AK27: =$AH27*Total!E$110 -> 0 | AM27: =$AL27*Total!C$111 -> 0 | AN27: =$AL27*Total!D$111 -> 0 | AO27: =$AL27*Total!E$111 -> 0
A28: gas manufacture, distribution | C28: =+$B28*Total!C$102 -> 0 | D28: =+$B28*Total!D$102 -> 0 | E28: =+$B28*Total!E$102 -> 0 | G28: =$F28*Total!C$103 -> 0 | H28: =$F28*Total!D$103 -> 0 | I28: =$F28*Total!E$103 -> 0 | K28: =$J28*Total!C$104 -> 0 | L28: =$J28*Total!D$104 -> 0 | M28: =$J28*Total!E$104 -> 0 | O28: =$N28*Total!C$105 -> 0 | P28: =$N28*Total!D$105 -> 0 | Q28: =$N28*Total!E$105 -> 0 | S28: =$R28*Total!C$106 -> 0 | T28: =$R28*Total!D$106 -> 0 | U28: =$R28*Total!E$106 -> 0 | W28: =$V28*Total!C$107 -> 0 | X28: =$V28*Total!D$107 -> 0 | Y28: =$V28*Total!E$107 -> 0 | AA28: =$Z28*Total!C$108 -> 0 | AB28: =$Z28*Total!D$108 -> 0 | AC28: =$Z28*Total!E$108 -> 0 | AE28: 0 | AF28: 0 | AG28: 0 | AI28: =$AH28*Total!C$110 -> 0 | AJ28: =$AH28*Total!D$110 -> 0 | AK28: =$AH28*Total!E$110 -> 0 | AM28: =$AL28*Total!C$111 -> 0 | AN28: =$AL28*Total!D$111 -> 0 | AO28: =$AL28*Total!E$111 -> 0
A29: water supply and sewerage | C29: =+$B29*Total!C$102 -> 0 | D29: =+$B29*Total!D$102 -> 0 | E29: =+$B29*Total!E$102 -> 0 | G29: =$F29*Total!C$103 -> 0 | H29: =$F29*Total!D$103 -> 0 | I29: =$F29*Total!E$103 -> 0 | K29: =$J29*Total!C$104 -> 0 | L29: =$J29*Total!D$104 -> 0 | M29: =$J29*Total!E$104 -> 0 | O29: =$N29*Total!C$105 -> 0 | P29: =$N29*Total!D$105 -> 0 | Q29: =$N29*Total!E$105 -> 0 | S29: =$R29*Total!C$106 -> 0 | T29: =$R29*Total!D$106 -> 0 | U29: =$R29*Total!E$106 -> 0 | W29: =$V29*Total!C$107 -> 0 | X29: =$V29*Total!D$107 -> 0 | Y29: =$V29*Total!E$107 -> 0 | Z29: 0.12 | AA29: =$Z29*Total!C$108 -> 0.102 | AB29: =$Z29*Total!D$108 -> 0.018 | AC29: =$Z29*Total!E$108 -> 0 | AD29: 0.12 | AE29: =+$AD29*Total!C$109 -> 0.102 | AF29: =+$AD29*Total!D$109 -> 0.018 | AG29: =+$AD29*Total!E$109 -> 0 | AI29: =$AH29*Total!C$110 -> 0 | AJ29: =$AH29*Total!D$110 -> 0 | AK29: =$AH29*Total!E$110 -> 0 | AM29: =$AL29*Total!C$111 -> 0 | AN29: =$AL29*Total!D$111 -> 0 | AO29: =$AL29*Total!E$111 -> 0
A30: construction | B30: 0.2252 | C30: =+$B30*Total!C$102 -> 0.0563 | D30: =+$B30*Total!D$102 -> 0.15764 | E30: =+$B30*Total!E$102 -> 0.01126 | F30: 0.25 | G30: =$F30*Total!C$103 -> 0.025 | H30: =$F30*Total!D$103 -> 0.075 | I30: =$F30*Total!E$103 -> 0.15 | J30: 0.07 | K30: =$J30*Total!C$104 -> 0.0035 | L30: =$J30*Total!D$104 -> 0.028 | M30: =$J30*Total!E$104 -> 0.0385 | N30: 0.1 | O30: =$N30*Total!C$105 -> 0.005 | P30: =$N30*Total!D$105 -> 0.095 | Q30: =$N30*Total!E$105 -> 0 | R30: 0.2 | S30: =$R30*Total!C$106 -> 0.01 | T30: =$R30*Total!D$106 -> 0.19 | U30: =$R30*Total!E$106 -> 0 | V30: 0.4 | W30: =$V30*Total!C$107 -> 0.32 | X30: =$V30*Total!D$107 -> 0.08 | Y30: =$V30*Total!E$107 -> 0 | Z30: 0.55 | AA30: =$Z30*Total!C$108 -> 0.4675 | AB30: =$Z30*Total!D$108 -> 0.0825 | AC30: =$Z30*Total!E$108 -> 0 | AD30: 0.55 | AE30: =+$AD30*Total!C$109 -> 0.4675 | AF30: =+$AD30*Total!D$109 -> 0.0825 | AG30: =+$AD30*Total!E$109 -> 0 | AH30: 1 | AI30: =$AH30*Total!C$110 -> 0.5 | AJ30: =$AH30*Total!D$110 -> 0.5 | AK30: =$AH30*Total!E$110 -> 0 | AL30: 0.08 | AM30: =$AL30*Total!C$111 -> 0.068 | AN30: =$AL30*Total!D$111 -> 0.008 | AO30: =$AL30*Total!E$111 -> 0.004
A31: repair of motor vehicles and motorcycles | C31: =+$B31*Total!C$102 -> 0 | D31: =+$B31*Total!D$102 -> 0 | E31: =+$B31*Total!E$102 -> 0 | G31: =$F31*Total!C$103 -> 0 | H31: =$F31*Total!D$103 -> 0 | I31: =$F31*Total!E$103 -> 0 | J31: 0.1 | K31: =$J31*Total!C$104 -> 0.005 | L31: =$J31*Total!D$104 -> 0.04 | M31: =$J31*Total!E$104 -> 0.055 | O31: =$N31*Total!C$105 -> 0 | P31: =$N31*Total!D$105 -> 0 | Q31: =$N31*Total!E$105 -> 0 | S31: =$R31*Total!C$106 -> 0 | T31: =$R31*Total!D$106 -> 0 | U31: =$R31*Total!E$106 -> 0 | W31: =$V31*Total!C$107 -> 0 | X31: =$V31*Total!D$107 -> 0 | Y31: =$V31*Total!E$107 -> 0 | AA31: =$Z31*Total!C$108 -> 0 | AB31: =$Z31*Total!D$108 -> 0 | AC31: =$Z31*Total!E$108 -> 0 | AE31: 0 | AF31: 0 | AG31: 0 | AI31: =$AH31*Total!C$110 -> 0 | AJ31: =$AH31*Total!D$110 -> 0 | AK31: =$AH31*Total!E$110 -> 0 | AM31: =$AL31*Total!C$111 -> 0 | AN31: =$AL31*Total!D$111 -> 0 | AO31: =$AL31*Total!E$111 -> 0
A32: transport and warehouse | C32: =+$B32*Total!C$102 -> 0 | D32: =+$B32*Total!D$102 -> 0 | E32: =+$B32*Total!E$102 -> 0 | G32: =$F32*Total!C$103 -> 0 | H32: =$F32*Total!D$103 -> 0 | I32: =$F32*Total!E$103 -> 0 | K32: =$J32*Total!C$104 -> 0 | L32: =$J32*Total!D$104 -> 0 | M32: =$J32*Total!E$104 -> 0 | O32: =$N32*Total!C$105 -> 0 | P32: =$N32*Total!D$105 -> 0 | Q32: =$N32*Total!E$105 -> 0 | S32: =$R32*Total!C$106 -> 0 | T32: =$R32*Total!D$106 -> 0 | U32: =$R32*Total!E$106 -> 0 | W32: =$V32*Total!C$107 -> 0 | X32: =$V32*Total!D$107 -> 0 | Y32: =$V32*Total!E$107 -> 0 | AA32: =$Z32*Total!C$108 -> 0 | AB32: =$Z32*Total!D$108 -> 0 | AC32: =$Z32*Total!E$108 -> 0 | AE32: 0 | AF32: 0 | AG32: 0 | AI32: =$AH32*Total!C$110 -> 0 | AJ32: =$AH32*Total!D$110 -> 0 | AK32: =$AH32*Total!E$110 -> 0 | AL32: 0.07 | AM32: =$AL32*Total!C$111 -> 0.0595 | AN32: =$AL32*Total!D$111 -> 0.007 | AO32: =$AL32*Total!E$111 -> 0.0035
A33: Accommodation, Food and service activities | C33: =+$B33*Total!C$102 -> 0 | D33: =+$B33*Total!D$102 -> 0 | E33: =+$B33*Total!E$102 -> 0 | G33: =$F33*Total!C$103 -> 0 | H33: =$F33*Total!D$103 -> 0 | I33: =$F33*Total!E$103 -> 0 | K33: =$J33*Total!C$104 -> 0 | L33: =$J33*Total!D$104 -> 0 | M33: =$J33*Total!E$104 -> 0 | O33: =$N33*Total!C$105 -> 0 | P33: =$N33*Total!D$105 -> 0 | Q33: =$N33*Total!E$105 -> 0 | S33: =$R33*Total!C$106 -> 0 | T33: =$R33*Total!D$106 -> 0 | U33: =$R33*Total!E$106 -> 0 | W33: =$V33*Total!C$107 -> 0 | X33: =$V33*Total!D$107 -> 0 | Y33: =$V33*Total!E$107 -> 0 | AA33: =$Z33*Total!C$108 -> 0 | AB33: =$Z33*Total!D$108 -> 0 | AC33: =$Z33*Total!E$108 -> 0 | AE33: 0 | AF33: 0 | AG33: 0 | AI33: =$AH33*Total!C$110 -> 0 | AJ33: =$AH33*Total!D$110 -> 0 | AK33: =$AH33*Total!E$110 -> 0 | AM33: =$AL33*Total!C$111 -> 0 | AN33: =$AL33*Total!D$111 -> 0 | AO33: =$AL33*Total!E$111 -> 0
A34: Information and communication | C34: =+$B34*Total!C$102 -> 0 | D34: =+$B34*Total!D$102 -> 0 | E34: =+$B34*Total!E$102 -> 0 | G34: =$F34*Total!C$103 -> 0 | H34: =$F34*Total!D$103 -> 0 | I34: =$F34*Total!E$103 -> 0 | K34: =$J34*Total!C$104 -> 0 | L34: =$J34*Total!D$104 -> 0 | M34: =$J34*Total!E$104 -> 0 | O34: =$N34*Total!C$105 -> 0 | P34: =$N34*Total!D$105 -> 0 | Q34: =$N34*Total!E$105 -> 0 | S34: =$R34*Total!C$106 -> 0 | T34: =$R34*Total!D$106 -> 0 | U34: =$R34*Total!E$106 -> 0 | W34: =$V34*Total!C$107 -> 0 | X34: =$V34*Total!D$107 -> 0 | Y34: =$V34*Total!E$107 -> 0 | AA34: =$Z34*Total!C$108 -> 0 | AB34: =$Z34*Total!D$108 -> 0 | AC34: =$Z34*Total!E$108 -> 0 | AE34: 0 | AF34: 0 | AG34: 0 | AI34: =$AH34*Total!C$110 -> 0 | AJ34: =$AH34*Total!D$110 -> 0 | AK34: =$AH34*Total!E$110 -> 0 | AM34: =$AL34*Total!C$111 -> 0 | AN34: =$AL34*Total!D$111 -> 0 | AO34: =$AL34*Total!E$111 -> 0
A35: financial and insurance activities | C35: =+$B35*Total!C$102 -> 0 | D35: =+$B35*Total!D$102 -> 0 | E35: =+$B35*Total!E$102 -> 0 | G35: =$F35*Total!C$103 -> 0 | H35: =$F35*Total!D$103 -> 0 | I35: =$F35*Total!E$103 -> 0 | K35: =$J35*Total!C$104 -> 0 | L35: =$J35*Total!D$104 -> 0 | M35: =$J35*Total!E$104 -> 0 | O35: =$N35*Total!C$105 -> 0 | P35: =$N35*Total!D$105 -> 0 | Q35: =$N35*Total!E$105 -> 0 | S35: =$R35*Total!C$106 -> 0 | T35: =$R35*Total!D$106 -> 0 | U35: =$R35*Total!E$106 -> 0 | W35: =$V35*Total!C$107 -> 0 | X35: =$V35*Total!D$107 -> 0 | Y35: =$V35*Total!E$107 -> 0 | AA35: =$Z35*Total!C$108 -> 0 | AB35: =$Z35*Total!D$108 -> 0 | AC35: =$Z35*Total!E$108 -> 0 | AE35: 0 | AF35: 0 | AG35: 0 | AI35: =$AH35*Total!C$110 -> 0 | AJ35: =$AH35*Total!D$110 -> 0 | AK35: =$AH35*Total!E$110 -> 0 | AM35: =$AL35*Total!C$111 -> 0 | AN35: =$AL35*Total!D$111 -> 0 | AO35: =$AL35*Total!E$111 -> 0
A36: real estate | C36: =+$B36*Total!C$102 -> 0 | D36: =+$B36*Total!D$102 -> 0 | E36: =+$B36*Total!E$102 -> 0 | G36: =$F36*Total!C$103 -> 0 | H36: =$F36*Total!D$103 -> 0 | I36: =$F36*Total!E$103 -> 0 | K36: =$J36*Total!C$104 -> 0 | L36: =$J36*Total!D$104 -> 0 | M36: =$J36*Total!E$104 -> 0 | O36: =$N36*Total!C$105 -> 0 | P36: =$N36*Total!D$105 -> 0 | Q36: =$N36*Total!E$105 -> 0 | S36: =$R36*Total!C$106 -> 0 | T36: =$R36*Total!D$106 -> 0 | U36: =$R36*Total!E$106 -> 0 | W36: =$V36*Total!C$107 -> 0 | X36: =$V36*Total!D$107 -> 0 | Y36: =$V36*Total!E$107 -> 0 | AA36: =$Z36*Total!C$108 -> 0 | AB36: =$Z36*Total!D$108 -> 0 | AC36: =$Z36*Total!E$108 -> 0 | AE36: 0 | AF36: 0 | AG36: 0 | AI36: =$AH36*Total!C$110 -> 0 | AJ36: =$AH36*Total!D$110 -> 0 | AK36: =$AH36*Total!E$110 -> 0 | AM36: =$AL36*Total!C$111 -> 0 | AN36: =$AL36*Total!D$111 -> 0 | AO36: =$AL36*Total!E$111 -> 0
A37: research and development; travel agencies; support activities | B37: 0.0532 | C37: =+$B37*Total!C$102 -> 0.0133 | D37: =+$B37*Total!D$102 -> 0.03724 | E37: =+$B37*Total!E$102 -> 0.00266 | F37: 0.07 | G37: =$F37*Total!C$103 -> 0.007 | H37: =$F37*Total!D$103 -> 0.021 | I37: =$F37*Total!E$103 -> 0.042 | J37: 0.05 | K37: =$J37*Total!C$104 -> 0.0025 | L37: =$J37*Total!D$104 -> 0.02 | M37: =$J37*Total!E$104 -> 0.0275 | N37: 0.05 | O37: =$N37*Total!C$105 -> 0.0025 | P37: =$N37*Total!D$105 -> 0.0475 | Q37: =$N37*Total!E$105 -> 0 | R37: 0.1 | S37: =$R37*Total!C$106 -> 0.005 | T37: =$R37*Total!D$106 -> 0.095 | U37: =$R37*Total!E$106 -> 0 | V37: 0.08 | W37: =$V37*Total!C$107 -> 0.064 | X37: =$V37*Total!D$107 -> 0.016 | Y37: =$V37*Total!E$107 -> 0 | Z37: 0.06 | AA37: =$Z37*Total!C$108 -> 0.051 | AB37: =$Z37*Total!D$108 -> 0.009 | AC37: =$Z37*Total!E$108 -> 0 | AD37: 0.06 | AE37: =+$AD37*Total!C$109 -> 0.051 | AF37: =+$AD37*Total!D$109 -> 0.009 | AG37: =+$AD37*Total!E$109 -> 0 | AI37: =$AH37*Total!C$110 -> 0 | AJ37: =$AH37*Total!D$110 -> 0 | AK37: =$AH37*Total!E$110 -> 0 | AL37: 0.15 | AM37: =$AL37*Total!C$111 -> 0.1275 | AN37: =$AL37*Total!D$111 -> 0.015 | AO37: =$AL37*Total!E$111 -> 0.0075
A38: public administration | C38: =+$B38*Total!C$102 -> 0 | D38: =+$B38*Total!D$102 -> 0 | E38: =+$B38*Total!E$102 -> 0 | G38: =$F38*Total!C$103 -> 0 | H38: =$F38*Total!D$103 -> 0 | I38: =$F38*Total!E$103 -> 0 | K38: =$J38*Total!C$104 -> 0 | L38: =$J38*Total!D$104 -> 0 | M38: =$J38*Total!E$104 -> 0 | O38: =$N38*Total!C$105 -> 0 | P38: =$N38*Total!D$105 -> 0 | Q38: =$N38*Total!E$105 -> 0 | S38: =$R38*Total!C$106 -> 0 | T38: =$R38*Total!D$106 -> 0 | U38: =$R38*Total!E$106 -> 0 | W38: =$V38*Total!C$107 -> 0 | X38: =$V38*Total!D$107 -> 0 | Y38: =$V38*Total!E$107 -> 0 | AA38: =$Z38*Total!C$108 -> 0 | AB38: =$Z38*Total!D$108 -> 0 | AC38: =$Z38*Total!E$108 -> 0 | AE38: 0 | AF38: 0 | AG38: 0 | AI38: =$AH38*Total!C$110 -> 0 | AJ38: =$AH38*Total!D$110 -> 0 | AK38: =$AH38*Total!E$110 -> 0 | AL38: 0.1 | AM38: =$AL38*Total!C$111 -> 0.085 | AN38: =$AL38*Total!D$111 -> 0.01 | AO38: =$AL38*Total!E$111 -> 0.005
A39: education; health and social work | C39: =+$B39*Total!C$102 -> 0 | D39: =+$B39*Total!D$102 -> 0 | E39: =+$B39*Total!E$102 -> 0 | G39: =$F39*Total!C$103 -> 0 | H39: =$F39*Total!D$103 -> 0 | I39: =$F39*Total!E$103 -> 0 | K39: =$J39*Total!C$104 -> 0 | L39: =$J39*Total!D$104 -> 0 | M39: =$J39*Total!E$104 -> 0 | O39: =$N39*Total!C$105 -> 0 | P39: =$N39*Total!D$105 -> 0 | Q39: =$N39*Total!E$105 -> 0 | S39: =$R39*Total!C$106 -> 0 | T39: =$R39*Total!D$106 -> 0 | U39: =$R39*Total!E$106 -> 0 | W39: =$V39*Total!C$107 -> 0 | X39: =$V39*Total!D$107 -> 0 | Y39: =$V39*Total!E$107 -> 0 | AA39: =$Z39*Total!C$108 -> 0 | AB39: =$Z39*Total!D$108 -> 0 | AC39: =$Z39*Total!E$108 -> 0 | AE39: 0 | AF39: 0 | AG39: 0 | AI39: =$AH39*Total!C$110 -> 0 | AJ39: =$AH39*Total!D$110 -> 0 | AK39: =$AH39*Total!E$110 -> 0 | AM39: =$AL39*Total!C$111 -> 0 | AN39: =$AL39*Total!D$111 -> 0 | AO39: =$AL39*Total!E$111 -> 0
A40: other services | C40: =+$B40*Total!C$102 -> 0 | D40: =+$B40*Total!D$102 -> 0 | E40: =+$B40*Total!E$102 -> 0 | G40: =$F40*Total!C$103 -> 0 | H40: =$F40*Total!D$103 -> 0 | I40: =$F40*Total!E$103 -> 0 | K40: =$J40*Total!C$104 -> 0 | L40: =$J40*Total!D$104 -> 0 | M40: =$J40*Total!E$104 -> 0 | O40: =$N40*Total!C$105 -> 0 | P40: =$N40*Total!D$105 -> 0 | Q40: =$N40*Total!E$105 -> 0 | S40: =$R40*Total!C$106 -> 0 | T40: =$R40*Total!D$106 -> 0 | U40: =$R40*Total!E$106 -> 0 | V40: 0.1 | W40: =$V40*Total!C$107 -> 0.08 | X40: =$V40*Total!D$107 -> 0.02 | Y40: =$V40*Total!E$107 -> 0 | AA40: =$Z40*Total!C$108 -> 0 | AB40: =$Z40*Total!D$108 -> 0 | AC40: =$Z40*Total!E$108 -> 0 | AE40: 0 | AF40: 0 | AG40: 0 | AI40: =$AH40*Total!C$110 -> 0 | AJ40: =$AH40*Total!D$110 -> 0 | AK40: =$AH40*Total!E$110 -> 0 | AL40: 0.1 | AM40: =$AL40*Total!C$111 -> 0.085 | AN40: =$AL40*Total!D$111 -> 0.01 | AO40: =$AL40*Total!E$111 -> 0.005
...

Sheet Government
C1: LTS
A2: Sector | D2: 2023 | E2: 2024 | F2: 2025 | G2: 2026 | H2: 2027 | I2: 2028 | J2: 2029 | K2: 2030 | L2: 2031 | M2: 2032 | N2: 2033 | O2: 2034 | P2: 2035 | Q2: 2036 | R2: 2037 | S2: 2038 | T2: 2039 | U2: 2040 | V2: 2041 | W2: 2042 | X2: 2043 | Y2: 2044 | Z2: 2045 | AA2: 2046 | AB2: 2047 | AC2: 2048 | AD2: 2049 | AE2: 2050
A3: EN - Power Industry | D3: =+Total!D3 -> 0 | E3: =+Total!E3 -> 0 | F3: =+Total!F3 -> 1.6405576 | G3: =+Total!G3 -> 0.34625024 | H3: =+Total!H3 -> 1.9174732 | I3: =+Total!I3 -> 2.5989561 | J3: =+Total!J3 -> 7.4215444 | K3: =+Total!K3 -> 12.361299 | ... AE3: =+Total!AE3 -> 7.1215774
A4: EN - Building | D4: =+Total!D4 -> 0 | E4: =+Total!E4 -> 0 | F4: =+Total!F4 -> 0 | G4: =+Total!G4 -> 0.012392549 | H4: =+Total!H4 -> 0.023961415 | I4: =+Total!I4 -> 0.034716882 | J4: =+Total!J4 -> 0.04467692 | K4: =+Total!K4 -> 0.064827291 | ... AE4: =+Total!AE4 -> 1.5214156
A5: EN - Transportation | D5: =+Total!D5 -> 0 | E5: =+Total!E5 -> 0 | F5: =+Total!F5 -> 0.00071354781 | G5: =+Total!G5 -> 0.0034838861 | H5: =+Total!H5 -> 0.0064159389 | I5: =+Total!I5 -> 0.0095152481 | J5: =+Total!J5 -> 0.012795081 | K5: =+Total!K5 -> 0.016253265 | ... AE5: =+Total!AE5 -> 0.73142549
A6: EN - Industrial combustion | D6: =+Total!D6 -> 0 | E6: =+Total!E6 -> 0 | F6: =+Total!F6 -> 0.014978408 | G6: =+Total!G6 -> 0.038599098 | H6: =+Total!H6 -> 0.061850965 | I6: =+Total!I6 -> 0.087728895 | J6: =+Total!J6 -> 0.11327748 | K6: =+Total!K6 -> 0.13857169 | ... AE6: =+Total!AE6 -> 0.6477426
A7: IN - Industrial processes | D7: =+Total!D7 -> 0 | E7: =+Total!E7 -> 0 | F7: =+Total!F7 -> 0 | G7: =+Total!G7 -> 0.81392292 | H7: =+Total!H7 -> 0.9083042 | I7: =+Total!I7 -> 1.0048392 | J7: =+Total!J7 -> 1.1037592 | K7: =+Total!K7 -> 1.2048031 | ... AE7: =+Total!AE7 -> 3.6692709
A8: Waste - Solid waste | D8: =+Total!D8 -> 0 | E8: =+Total!E8 -> 0 | F8: =+Total!F8 -> 0.087052446 | G8: =+Total!G8 -> 0.11358144 | H8: =+Total!H8 -> 0.1399269 | I8: =+Total!I8 -> 0.16354773 | J8: =+Total!J8 -> 0.1829564 | K8: =+Total!K8 -> 0.19795117 | ... AE8: =+Total!AE8 -> 0.24983327
A9: Waste - Wastewater treatment (trww) | D9: =+Total!D9 -> 0 | E9: =+Total!E9 -> 0 | F9: =+Total!F9 -> 0 | G9: =+Total!G9 -> 0.11709818 | H9: =+Total!H9 -> 0.24928301 | I9: =+Total!I9 -> 0.39763456 | J9: =+Total!J9 -> 0.56345437 | K9: =+Total!K9 -> 0.74777457 | ... AE9: =+Total!AE9 -> 2.9393447
A10: Waste - Wastewater (liquid waste) | D10: =+Total!D10 -> 0 | E10: =+Total!E10 -> 0 | F10: =+Total!F10 -> 0 | G10: =+Total!G10 -> 0 | H10: =+Total!H10 -> 0 | I10: =+Total!I10 -> 0 | J10: =+Total!J10 -> 0 | K10: =+Total!K10 -> 0 | ... AE10: =+Total!AE10 -> 0
A11: AG - Livestock (manure) | D11: =+Total!D11 -> 0 | E11: =+Total!E11 -> 0 | F11: =+Total!F11 -> 0 | G11: =+Total!G11 -> 0 | H11: =+Total!H11 -> 0 | I11: =+Total!I11 -> 0 | J11: =+Total!J11 -> 0 | K11: =+Total!K11 -> 0 | ... AE11: =+Total!AE11 -> 0
A12: LULUCF - Forest land | D12: =+Total!D12 -> 0 | E12: =+Total!E12 -> 0 | F12: =+Total!F12 -> 0.98551391 | G12: =+Total!G12 -> 1.217631 | H12: =+Total!H12 -> 1.4249767 | I12: =+Total!I12 -> 1.6039905 | J12: =+Total!J12 -> 1.7589536 | K12: =+Total!K12 -> 1.8900428 | ... AE12: =+Total!AE12 -> 3.2774395
A14: units: billion 2019 USD
A16: Sector | B16: SAM destination | C16: Government rate | D16: 2023 | E16: 2024 | F16: 2025 | G16: 2026 | H16: 2027 | I16: 2028 | J16: 2029 | K16: 2030 | L16: 2031 | M16: 2032 | N16: 2033 | O16: 2034 | P16: 2035 | Q16: 2036 | R16: 2037 | S16: 2038 | T16: 2039 | U16: 2040 | V16: 2041 | W16: 2042 | X16: 2043 | Y16: 2044 | Z16: 2045 | AA16: 2046 | AB16: 2047 | AC16: 2048 | AD16: 2049 | AE16: 2050
A17: EN - Power Industry | B17: crops | C17: =+SAM!C2 -> 0 | D17: =+$C17*D$3 -> 0 | E17: =+$C17*E$3 -> 0 | F17: =+$C17*F$3 -> 0 | G17: =+$C17*G$3 -> 0 | H17: =+$C17*H$3 -> 0 | I17: =+$C17*I$3 -> 0 | J17: =+$C17*J$3 -> 0 | K17: =+$C17*K$3 -> 0 | ... AE17: =+$C17*AE$3 -> 0
B18: forestry | C18: =+SAM!C3 -> 0 | D18: =+$C18*D$3 -> 0 | E18: =+$C18*E$3 -> 0 | F18: =+$C18*F$3 -> 0 | G18: =+$C18*G$3 -> 0 | H18: =+$C18*H$3 -> 0 | I18: =+$C18*I$3 -> 0 | J18: =+$C18*J$3 -> 0 | K18: =+$C18*K$3 -> 0 | ... AE18: =+$C18*AE$3 -> 0
B19: livestock | C19: =+SAM!C4 -> 0 | D19: =+$C19*D$3 -> 0 | E19: =+$C19*E$3 -> 0 | F19: =+$C19*F$3 -> 0 | G19: =+$C19*G$3 -> 0 | H19: =+$C19*H$3 -> 0 | I19: =+$C19*I$3 -> 0 | J19: =+$C19*J$3 -> 0 | K19: =+$C19*K$3 -> 0 | ... AE19: =+$C19*AE$3 -> 0
B20: fishery and aquaculture | C20: =+SAM!C5 -> 0 | D20: =+$C20*D$3 -> 0 | E20: =+$C20*E$3 -> 0 | F20: =+$C20*F$3 -> 0 | G20: =+$C20*G$3 -> 0 | H20: =+$C20*H$3 -> 0 | I20: =+$C20*I$3 -> 0 | J20: =+$C20*J$3 -> 0 | K20: =+$C20*K$3 -> 0 | ... AE20: =+$C20*AE$3 -> 0
B21: Extractive activities | C21: =+SAM!C6 -> 0 | D21: =+$C21*D$3 -> 0 | E21: =+$C21*E$3 -> 0 | F21: =+$C21*F$3 -> 0 | G21: =+$C21*G$3 -> 0 | H21: =+$C21*H$3 -> 0 | I21: =+$C21*I$3 -> 0 | J21: =+$C21*J$3 -> 0 | K21: =+$C21*K$3 -> 0 | ... AE21: =+$C21*AE$3 -> 0
B22: food manufacturing and beverage | C22: =+SAM!C7 -> 0 | D22: =+$C22*D$3 -> 0 | E22: =+$C22*E$3 -> 0 | F22: =+$C22*F$3 -> 0 | G22: =+$C22*G$3 -> 0 | H22: =+$C22*H$3 -> 0 | I22: =+$C22*I$3 -> 0 | J22: =+$C22*J$3 -> 0 | K22: =+$C22*K$3 -> 0 | ... AE22: =+$C22*AE$3 -> 0
B23: textile manufacturing and clothes | C23: =+SAM!C8 -> 0 | D23: =+$C23*D$3 -> 0 | E23: =+$C23*E$3 -> 0 | F23: =+$C23*F$3 -> 0 | G23: =+$C23*G$3 -> 0 | H23: =+$C23*H$3 -> 0 | I23: =+$C23*I$3 -> 0 | J23: =+$C23*J$3 -> 0 | K23: =+$C23*K$3 -> 0 | ... AE23: =+$C23*AE$3 -> 0
B24: Wood product manufacturing | C24: =+SAM!C9 -> 0 | D24: =+$C24*D$3 -> 0 | E24: =+$C24*E$3 -> 0 | F24: =+$C24*F$3 -> 0 | G24: =+$C24*G$3 -> 0 | H24: =+$C24*H$3 -> 0 | I24: =+$C24*I$3 -> 0 | J24: =+$C24*J$3 -> 0 | K24: =+$C24*K$3 -> 0 | ... AE24: =+$C24*AE$3 -> 0
B25: coking and refining production | C25: =+SAM!C10 -> 0 | D25: =+$C25*D$3 -> 0 | E25: =+$C25*E$3 -> 0 | F25: =+$C25*F$3 -> 0 | G25: =+$C25*G$3 -> 0 | H25: =+$C25*H$3 -> 0 | I25: =+$C25*I$3 -> 0 | J25: =+$C25*J$3 -> 0 | K25: =+$C25*K$3 -> 0 | ... AE25: =+$C25*AE$3 -> 0
B26: chemical products | C26: =+SAM!C11 -> 0 | D26: =+$C26*D$3 -> 0 | E26: =+$C26*E$3 -> 0 | F26: =+$C26*F$3 -> 0 | G26: =+$C26*G$3 -> 0 | H26: =+$C26*H$3 -> 0 | I26: =+$C26*I$3 -> 0 | J26: =+$C26*J$3 -> 0 | K26: =+$C26*K$3 -> 0 | ... AE26: =+$C26*AE$3 -> 0
B27: pharmaceutical products | C27: =+SAM!C12 -> 0 | D27: =+$C27*D$3 -> 0 | E27: =+$C27*E$3 -> 0 | F27: =+$C27*F$3 -> 0 | G27: =+$C27*G$3 -> 0 | H27: =+$C27*H$3 -> 0 | I27: =+$C27*I$3 -> 0 | J27: =+$C27*J$3 -> 0 | K27: =+$C27*K$3 -> 0 | ... AE27: =+$C27*AE$3 -> 0
B28: rubber manufacturing | C28: =+SAM!C13 -> 0 | D28: =+$C28*D$3 -> 0 | E28: =+$C28*E$3 -> 0 | F28: =+$C28*F$3 -> 0 | G28: =+$C28*G$3 -> 0 | H28: =+$C28*H$3 -> 0 | I28: =+$C28*I$3 -> 0 | J28: =+$C28*J$3 -> 0 | K28: =+$C28*K$3 -> 0 | ... AE28: =+$C28*AE$3 -> 0
B29: metalwork manufacturing | C29: =+SAM!C14 -> 0.01475 | D29: =+$C29*D$3 -> 0 | E29: =+$C29*E$3 -> 0 | F29: =+$C29*F$3 -> 0.024198224 | G29: =+$C29*G$3 -> 0.0051071911 | H29: =+$C29*H$3 -> 0.02828273 | I29: =+$C29*I$3 -> 0.038334603 | J29: =+$C29*J$3 -> 0.10946778 | K29: =+$C29*K$3 -> 0.18232917 | ... AE29: =+$C29*AE$3 -> 0.10504327
... B56: imports | C56: =+SAM!C41 -> 0.114725 | D56: =+$C56*D$3 -> 0 | E56: =+$C56*E$3 -> 0 | F56: =+$C56*F$3 -> 0.18821297 | G56: =+$C56*G$3 -> 0.039723559 | H56: =+$C56*H$3 -> 0.21998211 | I56: =+$C56*I$3 -> 0.29816524 | J56: =+$C56*J$3 -> 0.85143668 | K56: =+$C56*K$3 -> 1.4181501 | ... AE56: =+$C56*AE$3 -> 0.81702296
A57: EN - Building | B57: crops | C57: =+SAM!G2 -> 0 | D57: =+$C57*D$4 -> 0 | E57: =+$C57*E$4 -> 0 | F57: =+$C57*F$4 -> 0 | G57: =+$C57*G$4 -> 0 | H57: =+$C57*H$4 -> 0 | I57: =+$C57*I$4 -> 0 | J57: =+$C57*J$4 -> 0 | K57: =+$C57*K$4 -> 0 | ... AE57: =+$C57*AE$4 -> 0
B58: forestry | C58: =+SAM!G3 -> 0 | D58: =+$C58*D$4 -> 0 | E58: =+$C58*E$4 -> 0 | F58: =+$C58*F$4 -> 0 | G58: =+$C58*G$4 -> 0 | H58: =+$C58*H$4 -> 0 | I58: =+$C58*I$4 -> 0 | J58: =+$C58*J$4 -> 0 | K58: =+$C58*K$4 -> 0 | ... AE58: =+$C58*AE$4 -> 0
B59: livestock | C59: =+SAM!G4 -> 0 | D59: =+$C59*D$4 -> 0 | E59: =+$C59*E$4 -> 0 | F59: =+$C59*F$4 -> 0 | G59: =+$C59*G$4 -> 0 | H59: =+$C59*H$4 -> 0 | I59: =+$C59*I$4 -> 0 | J59: =+$C59*J$4 -> 0 | K59: =+$C59*K$4 -> 0 | ... AE59: =+$C59*AE$4 -> 0
B60: fishery and aquaculture | C60: =+SAM!G5 -> 0 | D60: =+$C60*D$4 -> 0 | E60: =+$C60*E$4 -> 0 | F60: =+$C60*F$4 -> 0 | G60: =+$C60*G$4 -> 0 | H60: =+$C60*H$4 -> 0 | I60: =+$C60*I$4 -> 0 | J60: =+$C60*J$4 -> 0 | K60: =+$C60*K$4 -> 0 | ... AE60: =+$C60*AE$4 -> 0
B61: Extractive activities | C61: =+SAM!G6 -> 0 | D61: =+$C61*D$4 -> 0 | E61: =+$C61*E$4 -> 0 | F61: =+$C61*F$4 -> 0 | G61: =+$C61*G$4 -> 0 | H61: =+$C61*H$4 -> 0 | I61: =+$C61*I$4 -> 0 | J61: =+$C61*J$4 -> 0 | K61: =+$C61*K$4 -> 0 | ... AE61: =+$C61*AE$4 -> 0
B62: food manufacturing and beverage | C62: =+SAM!G7 -> 0 | D62: =+$C62*D$4 -> 0 | E62: =+$C62*E$4 -> 0 | F62: =+$C62*F$4 -> 0 | G62: =+$C62*G$4 -> 0 | H62: =+$C62*H$4 -> 0 | I62: =+$C62*I$4 -> 0 | J62: =+$C62*J$4 -> 0 | K62: =+$C62*K$4 -> 0 | ... AE62: =+$C62*AE$4 -> 0
