Workbook

Sheet README
A1: Morocco investment & benefits crosswalk
A2: Units: billion 2019 USD, cumulative 2023-2050 unless noted. Source run: LEDS (LTS) vs BASE (no-action).
A4: STRUCTURE — each investment path is decomposed two independent ways, each summing to 100%:
A5: (A) AGENT split : who finances it — government / firms / households (depends on financing judgment).
A6: (B) COST VECTOR : what it buys — a vector across SAM sectors + IMPORTS (supply chain; independent of financing).
A7: Final SAM allocation = investment(sector) x cost-vector(sector). Final agent allocation = investment(sector) x agent-share(sector).
A9: IMPORTS is a synthetic destination inside the 100% (the SAM has no imports row). Solar modules, wind turbines,
A10: EV drivetrains and heat pumps are largely imported; allocating them domestically would overstate domestic activity.
A11: 'territorial correction' (SAM row 43) is excluded — it is a balancing item, not a sector.
A13: TABS
A14: T1_agent_split : investment x {gov, firms, hh} shares + applied bn + documented source per sector.
A15: T1_cost_vectors : share matrix, SAM destination x investment sector (blue = editable inputs; each column sums to 1).
... A34: LEGEND: blue = editable input (share/assumption) · black = formula · yellow = key assumption to review.

Sheet T1_agent_split
A1: Investment sector | B1: Investment (bn) | C1: Gov % | D1: Firms % | E1: HH % | F1: Gov (bn) | G1: Firms (bn) | H1: HH (bn) | I1: Row check | J1: Source (documented judgment)
A2: EN - Power Industry | B2: 65.5003 | C2: 0.25 | D2: 0.7 | E2: 0.05 | F2: =$B2*C2 -> 16.375075 | G2: =$B2*D2 -> 45.85021 | H2: =$B2*E2 -> 3.275015 | I2: =C2+D2+E2 -> 1 | J2: Morocco RE build-out is predominantly private IPP (MASEN/ACWA Power PPAs) with state offtake via ONEE; ~25% public/SOE (ONEE grid-side generation), ~5% distributed rooftop PV by households. Judgment informed by IEA Morocco 2023 & World Bank MAR energy PPPs.
A3: EN - Building | B3: 20.3366 | C3: 0.1 | D3: 0.3 | E3: 0.6 | F3: =$B3*C3 -> 2.03366 | G3: =$B3*D3 -> 6.10098 | H3: =$B3*E3 -> 12.20196 | I3: =C3+D3+E3 -> 1 | J3: Building heat-pump / efficiency retrofits are mostly owner-financed: households (residential) 60%, commercial firms 30%, government 10% (public buildings). Our judgment.
A4: EN - Transportation | B4: 8.9113 | C4: 0.05 | D4: 0.4 | E4: 0.55 | F4: =$B4*C4 -> 0.445565 | G4: =$B4*D4 -> 3.56452 | H4: =$B4*E4 -> 4.901215 | I4: =C4+D4+E4 -> 1 | J4: EV purchases: private households 55%, commercial/fleet firms 40%, public fleets 5%. Our judgment (Morocco has no large public EV programme yet).
A5: EN - Industrial combustion | B5: 8.5337 | C5: 0.05 | D5: 0.95 | E5: 0 | F5: =$B5*C5 -> 0.426685 | G5: =$B5*D5 -> 8.107015 | H5: =$B5*E5 -> 0 | I5: =C5+D5+E5 -> 1 | J5: Industrial fuel-switch / heat equipment is financed by industrial firms; ~5% public co-funding via decarbonisation support. Our judgment.
A6: IN - Industrial processes | B6: 53.5531 | C6: 0.05 | D6: 0.95 | E6: 0 | F6: =$B6*C6 -> 2.677655 | G6: =$B6*D6 -> 50.875445 | H6: =$B6*E6 -> 0 | I6: =C6+D6+E6 -> 1 | J6: Cement/steel material-efficiency retrofits financed by industrial firms; minor public co-funding. Our judgment.
A7: Waste - Solid waste | B7: 5.7893 | C7: 0.8 | D7: 0.2 | E7: 0 | F7: =$B7*C7 -> 4.63144 | G7: =$B7*D7 -> 1.15786 | H7: =$B7*E7 -> 0 | I7: =C7+D7+E7 -> 1 | J7: Solid-waste management is a municipal/public responsibility with private operators (delegated management, e.g. Averda/SOS-NDD): government 80%, firms 20%. Our judgment informed by Morocco PNDM waste programme.
A8: Waste - Wastewater treatment (trww) | B8: 46.3378 | C8: 0.85 | D8: 0.15 | E8: 0 | F8: =$B8*C8 -> 39.38713 | G8: =$B8*D8 -> 6.95067 | H8: =$B8*E8 -> 0 | I8: =C8+D8+E8 -> 1 | J8: Wastewater treatment (ONEP/ONEE-Eau, municipal utilities) is public-led with private delegated operators: government 85%, firms 15%. Our judgment informed by PNA sanitation programme.
A9: Waste - Wastewater (liquid waste) | B9: 0 | C9: 0.85 | D9: 0.15 | E9: 0 | F9: =$B9*C9 -> 0 | G9: =$B9*D9 -> 0 | H9: =$B9*E9 -> 0 | I9: =C9+D9+E9 -> 1 | J9: Zero investment in this path; shares carried for completeness.
A10: AG - Livestock (manure) | B10: 0 | C10: 0.5 | D10: 0.5 | E10: 0 | F10: =$B10*C10 -> 0 | G10: =$B10*D10 -> 0 | H10: =$B10*E10 -> 0 | I10: =C10+D10+E10 -> 1 | J10: Zero investment in this path; shares carried for completeness.
A11: LULUCF - Forest land | B11: 64.5649 | C11: 0.85 | D11: 0.1 | E11: 0.05 | F11: =$B11*C11 -> 54.880165 | G11: =$B11*D11 -> 6.45649 | H11: =$B11*E11 -> 3.228245 | I11: =C11+D11+E11 -> 1 | J11: Reforestation is government-led (Eaux et Forets / Forets du Maroc 2020-2030 programme) 85%, private forestry firms 10%, community/household woodlots 5%. Our judgment.
A12: TOTAL | B12: =SUM(B2:B11) -> 273.527 | F12: =SUM(F2:F11) -> 120.85738 | G12: =SUM(G2:G11) -> 129.06319 | H12: =SUM(H2:H11) -> 23.606435

Sheet T1_cost_vectors
A1: SAM destination | B1: EN - Power Industry | C1: EN - Building | D1: EN - Transportation | E1: EN - Industrial combustion | F1: IN - Industrial processes | G1: Waste - Solid waste | H1: Waste - Wastewater treatment (trww) | I1: Waste - Wastewater (liquid waste) | J1: AG - Livestock (manure) | K1: LULUCF - Forest land
A2: Investment (bn) -> | B2: 65.5003 | C2: 20.3366 | D2: 8.9113 | E2: 8.5337 | F2: 53.5531 | G2: 5.7893 | H2: 46.3378 | I2: 0 | J2: 0 | K2: 64.5649
A3: crops | B3: 0 | C3: 0 | D3: 0 | E3: 0 | F3: 0 | G3: 0 | H3: 0 | I3: 0 | J3: 0 | K3: 0.15
A4: forestry | B4: 0 | C4: 0 | D4: 0 | E4: 0 | F4: 0 | G4: 0 | H4: 0 | I4: 0 | J4: 0 | K4: 0.35
A5: livestock | B5: 0 | C5: 0 | D5: 0 | E5: 0 | F5: 0 | G5: 0 | H5: 0 | I5: 0 | J5: 0 | K5: 0
A6: fishery and aquaculture | B6: 0 | C6: 0 | D6: 0 | E6: 0 | F6: 0 | G6: 0 | H6: 0 | I6: 0 | J6: 0 | K6: 0
A7: Extractive activities | B7: 0 | C7: 0 | D7: 0 | E7: 0 | F7: 0 | G7: 0 | H7: 0 | I7: 0 | J7: 0 | K7: 0
A8: food manufacturing and beverage | B8: 0 | C8: 0 | D8: 0 | E8: 0 | F8: 0 | G8: 0 | H8: 0 | I8: 0 | J8: 0 | K8: 0
A9: textile manufacturing and clothes | B9: 0 | C9: 0 | D9: 0 | E9: 0 | F9: 0 | G9: 0 | H9: 0 | I9: 0 | J9: 0 | K9: 0
A10: Wood product manufacturing | B10: 0 | C10: 0.03 | D10: 0 | E10: 0 | F10: 0 | G10: 0 | H10: 0 | I10: 0 | J10: 0 | K10: 0
A11: coking and refining production | B11: 0 | C11: 0 | D11: 0 | E11: 0 | F11: 0 | G11: 0 | H11: 0 | I11: 0 | J11: 0 | K11: 0
A12: chemical products | B12: 0 | C12: 0 | D12: 0 | E12: 0 | F12: 0.1 | G12: 0 | H12: 0.04 | I12: 0 | J12: 0 | K12: 0
A13: pharmaceutical products | B13: 0 | C13: 0 | D13: 0 | E13: 0 | F13: 0 | G13: 0 | H13: 0 | I13: 0 | J13: 0 | K13: 0
... A42: IMPORTS (rest of world) | B42: 0.4589 | C42: 0.45 | D42: 0.55 | E42: 0.4 | F42: 0.15 | G42: 0.12 | H42: 0.08 | I42: 0 | J42: 0 | K42: 0
A43: SUM (must = 100%) | B43: =SUM(B3:B42) -> 1 | C43: =SUM(C3:C42) -> 1 | D43: =SUM(D3:D42) -> 1 | E43: =SUM(E3:E42) -> 1 | F43: =SUM(F3:F42) -> 1 | G43: =SUM(G3:G42) -> 1 | H43: =SUM(H3:H42) -> 1 | I43: =SUM(I3:I42) -> 1 | ... K43: =SUM(K3:K42) -> 1

Sheet T1_applied_SAM
A1: SAM destination (bn 2019 USD) | B1: EN - Power Industry | C1: EN - Building | D1: EN - Transportation | E1: EN - Industrial combustion | F1: IN - Industrial processes | G1: Waste - Solid waste | H1: Waste - Wastewater treatment (trww) | I1: Waste - Wastewater (liquid waste) | J1: AG - Livestock (manure) | K1: LULUCF - Forest land | L1: TOTAL
A2: crops | B2: =T1_cost_vectors!B3*T1_cost_vectors!B$2 -> 0 | C2: =T1_cost_vectors!C3*T1_cost_vectors!C$2 -> 0 | D2: =T1_cost_vectors!D3*T1_cost_vectors!D$2 -> 0 | E2: =T1_cost_vectors!E3*T1_cost_vectors!E$2 -> 0 | F2: =T1_cost_vectors!F3*T1_cost_vectors!F$2 -> 0 | G2: =T1_cost_vectors!G3*T1_cost_vectors!G$2 -> 0 | H2: =T1_cost_vectors!H3*T1_cost_vectors!H$2 -> 0 | I2: =T1_cost_vectors!I3*T1_cost_vectors!I$2 -> 0 | ... K2: =T1_cost_vectors!K3*T1_cost_vectors!K$2 -> 9.684735 | L2: =SUM(B2:K2) -> 9.684735
A3: forestry | B3: =T1_cost_vectors!B4*T1_cost_vectors!B$2 -> 0 | C3: =T1_cost_vectors!C4*T1_cost_vectors!C$2 -> 0 | D3: =T1_cost_vectors!D4*T1_cost_vectors!D$2 -> 0 | E3: =T1_cost_vectors!E4*T1_cost_vectors!E$2 -> 0 | F3: =T1_cost_vectors!F4*T1_cost_vectors!F$2 -> 0 | G3: =T1_cost_vectors!G4*T1_cost_vectors!G$2 -> 0 | H3: =T1_cost_vectors!H4*T1_cost_vectors!H$2 -> 0 | I3: =T1_cost_vectors!I4*T1_cost_vectors!I$2 -> 0 | ... K3: =T1_cost_vectors!K4*T1_cost_vectors!K$2 -> 22.597715 | L3: =SUM(B3:K3) -> 22.597715
A4: livestock | B4: =T1_cost_vectors!B5*T1_cost_vectors!B$2 -> 0 | C4: =T1_cost_vectors!C5*T1_cost_vectors!C$2 -> 0 | D4: =T1_cost_vectors!D5*T1_cost_vectors!D$2 -> 0 | E4: =T1_cost_vectors!E5*T1_cost_vectors!E$2 -> 0 | F4: =T1_cost_vectors!F5*T1_cost_vectors!F$2 -> 0 | G4: =T1_cost_vectors!G5*T1_cost_vectors!G$2 -> 0 | H4: =T1_cost_vectors!H5*T1_cost_vectors!H$2 -> 0 | I4: =T1_cost_vectors!I5*T1_cost_vectors!I$2 -> 0 | ... K4: =T1_cost_vectors!K5*T1_cost_vectors!K$2 -> 0 | L4: =SUM(B4:K4) -> 0
A5: fishery and aquaculture | B5: =T1_cost_vectors!B6*T1_cost_vectors!B$2 -> 0 | C5: =T1_cost_vectors!C6*T1_cost_vectors!C$2 -> 0 | D5: =T1_cost_vectors!D6*T1_cost_vectors!D$2 -> 0 | E5: =T1_cost_vectors!E6*T1_cost_vectors!E$2 -> 0 | F5: =T1_cost_vectors!F6*T1_cost_vectors!F$2 -> 0 | G5: =T1_cost_vectors!G6*T1_cost_vectors!G$2 -> 0 | H5: =T1_cost_vectors!H6*T1_cost_vectors!H$2 -> 0 | I5: =T1_cost_vectors!I6*T1_cost_vectors!I$2 -> 0 | ... K5: =T1_cost_vectors!K6*T1_cost_vectors!K$2 -> 0 | L5: =SUM(B5:K5) -> 0
A6: Extractive activities | B6: =T1_cost_vectors!B7*T1_cost_vectors!B$2 -> 0 | C6: =T1_cost_vectors!C7*T1_cost_vectors!C$2 -> 0 | D6: =T1_cost_vectors!D7*T1_cost_vectors!D$2 -> 0 | E6: =T1_cost_vectors!E7*T1_cost_vectors!E$2 -> 0 | F6: =T1_cost_vectors!F7*T1_cost_vectors!F$2 -> 0 | G6: =T1_cost_vectors!G7*T1_cost_vectors!G$2 -> 0 | H6: =T1_cost_vectors!H7*T1_cost_vectors!H$2 -> 0 | I6: =T1_cost_vectors!I7*T1_cost_vectors!I$2 -> 0 | ... K6: =T1_cost_vectors!K7*T1_cost_vectors!K$2 -> 0 | L6: =SUM(B6:K6) -> 0
A7: food manufacturing and beverage | B7: =T1_cost_vectors!B8*T1_cost_vectors!B$2 -> 0 | C7: =T1_cost_vectors!C8*T1_cost_vectors!C$2 -> 0 | D7: =T1_cost_vectors!D8*T1_cost_vectors!D$2 -> 0 | E7: =T1_cost_vectors!E8*T1_cost_vectors!E$2 -> 0 | F7: =T1_cost_vectors!F8*T1_cost_vectors!F$2 -> 0 | G7: =T1_cost_vectors!G8*T1_cost_vectors!G$2 -> 0 | H7: =T1_cost_vectors!H8*T1_cost_vectors!H$2 -> 0 | I7: =T1_cost_vectors!I8*T1_cost_vectors!I$2 -> 0 | ... K7: =T1_cost_vectors!K8*T1_cost_vectors!K$2 -> 0 | L7: =SUM(B7:K7) -> 0
A8: textile manufacturing and clothes | B8: =T1_cost_vectors!B9*T1_cost_vectors!B$2 -> 0 | C8: =T1_cost_vectors!C9*T1_cost_vectors!C$2 -> 0 | D8: =T1_cost_vectors!D9*T1_cost_vectors!D$2 -> 0 | E8: =T1_cost_vectors!E9*T1_cost_vectors!E$2 -> 0 | F8: =T1_cost_vectors!F9*T1_cost_vectors!F$2 -> 0 | G8: =T1_cost_vectors!G9*T1_cost_vectors!G$2 -> 0 | H8: =T1_cost_vectors!H9*T1_cost_vectors!H$2 -> 0 | I8: =T1_cost_vectors!I9*T1_cost_vectors!I$2 -> 0 | ... K8: =T1_cost_vectors!K9*T1_cost_vectors!K$2 -> 0 | L8: =SUM(B8:K8) -> 0
A9: Wood product manufacturing | B9: =T1_cost_vectors!B10*T1_cost_vectors!B$2 -> 0 | C9: =T1_cost_vectors!C10*T1_cost_vectors!C$2 -> 0.610098 | D9: =T1_cost_vectors!D10*T1_cost_vectors!D$2 -> 0 | E9: =T1_cost_vectors!E10*T1_cost_vectors!E$2 -> 0 | F9: =T1_cost_vectors!F10*T1_cost_vectors!F$2 -> 0 | G9: =T1_cost_vectors!G10*T1_cost_vectors!G$2 -> 0 | H9: =T1_cost_vectors!H10*T1_cost_vectors!H$2 -> 0 | I9: =T1_cost_vectors!I10*T1_cost_vectors!I$2 -> 0 | ... K9: =T1_cost_vectors!K10*T1_cost_vectors!K$2 -> 0 | L9: =SUM(B9:K9) -> 0.610098
A10: coking and refining production | B10: =T1_cost_vectors!B11*T1_cost_vectors!B$2 -> 0 | C10: =T1_cost_vectors!C11*T1_cost_vectors!C$2 -> 0 | D10: =T1_cost_vectors!D11*T1_cost_vectors!D$2 -> 0 | E10: =T1_cost_vectors!E11*T1_cost_vectors!E$2 -> 0 | F10: =T1_cost_vectors!F11*T1_cost_vectors!F$2 -> 0 | G10: =T1_cost_vectors!G11*T1_cost_vectors!G$2 -> 0 | H10: =T1_cost_vectors!H11*T1_cost_vectors!H$2 -> 0 | I10: =T1_cost_vectors!I11*T1_cost_vectors!I$2 -> 0 | ... K10: =T1_cost_vectors!K11*T1_cost_vectors!K$2 -> 0 | L10: =SUM(B10:K10) -> 0
A11: chemical products | B11: =T1_cost_vectors!B12*T1_cost_vectors!B$2 -> 0 | C11: =T1_cost_vectors!C12*T1_cost_vectors!C$2 -> 0 | D11: =T1_cost_vectors!D12*T1_cost_vectors!D$2 -> 0 | E11: =T1_cost_vectors!E12*T1_cost_vectors!E$2 -> 0 | F11: =T1_cost_vectors!F12*T1_cost_vectors!F$2 -> 5.35531 | G11: =T1_cost_vectors!G12*T1_cost_vectors!G$2 -> 0 | H11: =T1_cost_vectors!H12*T1_cost_vectors!H$2 -> 1.853512 | I11: =T1_cost_vectors!I12*T1_cost_vectors!I$2 -> 0 | ... K11: =T1_cost_vectors!K12*T1_cost_vectors!K$2 -> 0 | L11: =SUM(B11:K11) -> 7.208822
A12: pharmaceutical products | B12: =T1_cost_vectors!B13*T1_cost_vectors!B$2 -> 0 | C12: =T1_cost_vectors!C13*T1_cost_vectors!C$2 -> 0 | D12: =T1_cost_vectors!D13*T1_cost_vectors!D$2 -> 0 | E12: =T1_cost_vectors!E13*T1_cost_vectors!E$2 -> 0 | F12: =T1_cost_vectors!F13*T1_cost_vectors!F$2 -> 0 | G12: =T1_cost_vectors!G13*T1_cost_vectors!G$2 -> 0 | H12: =T1_cost_vectors!H13*T1_cost_vectors!H$2 -> 0 | I12: =T1_cost_vectors!I13*T1_cost_vectors!I$2 -> 0 | ... K12: =T1_cost_vectors!K13*T1_cost_vectors!K$2 -> 0 | L12: =SUM(B12:K12) -> 0
A13: rubber manufacturing | B13: =T1_cost_vectors!B14*T1_cost_vectors!B$2 -> 0 | C13: =T1_cost_vectors!C14*T1_cost_vectors!C$2 -> 0 | D13: =T1_cost_vectors!D14*T1_cost_vectors!D$2 -> 0 | E13: =T1_cost_vectors!E14*T1_cost_vectors!E$2 -> 0 | F13: =T1_cost_vectors!F14*T1_cost_vectors!F$2 -> 0 | G13: =T1_cost_vectors!G14*T1_cost_vectors!G$2 -> 0 | H13: =T1_cost_vectors!H14*T1_cost_vectors!H$2 -> 0 | I13: =T1_cost_vectors!I14*T1_cost_vectors!I$2 -> 0 | ... K13: =T1_cost_vectors!K14*T1_cost_vectors!K$2 -> 0 | L13: =SUM(B13:K13) -> 0
... A41: IMPORTS (rest of world) | B41: =T1_cost_vectors!B42*T1_cost_vectors!B$2 -> 30.058088 | C41: =T1_cost_vectors!C42*T1_cost_vectors!C$2 -> 9.15147 | D41: =T1_cost_vectors!D42*T1_cost_vectors!D$2 -> 4.901215 | E41: =T1_cost_vectors!E42*T1_cost_vectors!E$2 -> 3.41348 | F41: =T1_cost_vectors!F42*T1_cost_vectors!F$2 -> 8.032965 | G41: =T1_cost_vectors!G42*T1_cost_vectors!G$2 -> 0.694716 | H41: =T1_cost_vectors!H42*T1_cost_vectors!H$2 -> 3.707024 | I41: =T1_cost_vectors!I42*T1_cost_vectors!I$2 -> 0 | ... K41: =T1_cost_vectors!K42*T1_cost_vectors!K$2 -> 0 | L41: =SUM(B41:K41) -> 59.958958
A42: TOTAL | B42: =SUM(B2:B41) -> 65.5003 | C42: =SUM(C2:C41) -> 20.3366 | D42: =SUM(D2:D41) -> 8.9113 | E42: =SUM(E2:E41) -> 8.5337 | F42: =SUM(F2:F41) -> 53.5531 | G42: =SUM(G2:G41) -> 5.7893 | H42: =SUM(H2:H41) -> 46.3378 | I42: =SUM(I2:I41) -> 0 | ... L42: =SUM(L2:L41) -> 273.527

Sheet T2_fuel_savings
A1: Task 2 — Power-sector FUEL COST SAVINGS by generation technology
A2: HOW THIS WAS COMPUTED (fuel cost savings by generation technology):
A3: 1. Raw data: for each fuel, the value of fuel consumed by the power sector, per scenario and year, straight
A4: from NEMOMOD column totalvalue_enfu_fuel_consumed_entc_fuel_<fuel> (= physical consumption x fuel price).
A5: 2. Two raw blocks below show that variable in BASE (no-action) and in LEDS (LTS), in bn 2019 USD.
A6: 3. Saving = BASE minus LEDS (the CALC block; every cell is a live formula subtracting the two raw cells).
A7: 4. Each fuel is mapped 1:1 to the plant that burns it (coal->pp_coal, natural gas->pp_gas, oil->pp_oil, ...).
A8: Renewables (solar/wind/hydro) burn no fuel -> no row here -> zero saving (correct: the saving is the
A9: avoided coal/oil/gas purchase). This is NOT the CB 'Fuel cost savings (power sector)' row (a residual).
A11: RAW — fuel value in BASE / no-action (bn)
A12: Year | B12: coal (pp_coal) | C12: oil (pp_oil) | D12: natural_gas (pp_gas) | E12: biogas (pp_biogas) | F12: biomass (pp_biomass) | G12: nuclear (pp_nuclear) | H12: waste (pp_waste_incineration)
A13: 2023 | B13: 1.8034 | C13: 0.3245 | D13: 0.2213 | E13: 0.0004 | F13: 0.0358 | G13: 0.0131 | H13: 0.0008
A14: 2024 | B14: 1.839 | C14: 0.3309 | D14: 0.2257 | E14: 0.0004 | F14: 0.042 | G14: 0.0133 | H14: 0.0008
A15: 2025 | B15: 1.8751 | C15: 0.3374 | D15: 0.2303 | E15: 0.0004 | F15: 0.0498 | G15: 0.0136 | H15: 0.0008
A16: 2026 | B16: 1.9131 | C16: 0.3442 | D16: 0.235 | E16: 0.0004 | F16: 0.0562 | G16: 0.0138 | H16: 0.0008
A17: 2027 | B17: 1.9521 | C17: 0.3513 | D17: 0.2399 | E17: 0.0004 | F17: 0.0562 | G17: 0.0141 | H17: 0.0008
A18: 2028 | B18: 1.9919 | C18: 0.3584 | D18: 0.2448 | E18: 0.0004 | F18: 0.0563 | G18: 0.0144 | H18: 0.0009
A19: 2029 | B19: 2.0329 | C19: 0.3658 | D19: 0.25 | E19: 0.0004 | F19: 0.0563 | G19: 0.0147 | H19: 0.0009
A20: 2030 | B20: 2.0745 | C20: 0.3733 | D20: 0.2552 | E20: 0.0004 | F20: 0.0564 | G20: 0.0161 | H20: 0.0009
A21: 2031 | B21: 2.1165 | C21: 0.3808 | D21: 0.2604 | E21: 0.0004 | F21: 0.0545 | G21: 0.0172 | H21: 0.0009
A22: 2032 | B22: 2.1589 | C22: 0.3885 | D22: 0.2658 | E22: 0.0004 | F22: 0.0523 | G22: 0.0184 | H22: 0.0009
A23: 2033 | B23: 2.2018 | C23: 0.3962 | D23: 0.2712 | E23: 0.0005 | F23: 0.0503 | G23: 0.0195 | H23: 0.0009
A24: 2034 | B24: 2.2452 | C24: 0.404 | D24: 0.2766 | E24: 0.0005 | F24: 0.0484 | G24: 0.0206 | H24: 0.001
... A40: 2050 | B40: 3.0253 | C40: 0.5444 | D40: 0.3755 | E40: 0.0006 | F40: 0.0031 | G40: 0.043 | H40: 0.0013
A41: source: coal (pp_coal)=totalvalue_enfu_fuel_consumed_entc_fuel_coal, oil (pp_oil)=totalvalue_enfu_fuel_consumed_entc_fuel_oil ...
A43: RAW — fuel value in LEDS / LTS (bn)
A44: Year | B44: coal (pp_coal) | C44: oil (pp_oil) | D44: natural_gas (pp_gas) | E44: biogas (pp_biogas) | F44: biomass (pp_biomass) | G44: nuclear (pp_nuclear) | H44: waste (pp_waste_incineration)
A45: 2023 | B45: 1.9139 | C45: 0.3444 | D45: 0.2375 | E45: 0.0008 | F45: 0.0546 | G45: 0.0139 | H45: 0.0007
A46: 2024 | B46: 1.9513 | C46: 0.3511 | D46: 0.2437 | E46: 0.001 | F46: 0.0552 | G46: 0.015 | H46: 0.0007
A47: 2025 | B47: 1.9567 | C47: 0.3521 | D47: 0.2454 | E47: 0.0012 | F47: 0.0502 | G47: 0.015 | H47: 0.0007
A48: 2026 | B48: 1.916 | C48: 0.3438 | D48: 0.2343 | E48: 0.0067 | F48: 0.0615 | G48: 0.0151 | H48: 0.0007
A49: 2027 | B49: 1.8109 | C49: 0.3248 | D49: 0.2214 | E49: 0.0129 | F49: 0.0277 | G49: 0.0153 | H49: 0.0007
A50: 2028 | B50: 1.5637 | C50: 0.2798 | D50: 0.1994 | E50: 0.02 | F50: 0.0169 | G50: 0.0154 | H50: 0.0007
A51: 2029 | B51: 1.0771 | C51: 0.1938 | D51: 0.1603 | E51: 0.028 | F51: 0 | G51: 0.0156 | H51: 0.0008
A52: 2030 | B52: 0.5955 | C52: 0.1071 | D52: 0.1012 | E52: 0.037 | F52: 0 | G52: 0.0159 | H52: 0.0008
A53: 2031 | B53: 0.3341 | C53: 0.0601 | D53: 0.041 | E53: 0.047 | F53: 0 | G53: 0.0166 | H53: 0.0008
A54: 2032 | B54: 0.2067 | C54: 0.0372 | D54: 0.0254 | E54: 0.0581 | F54: 0 | G54: 0.0171 | H54: 0.0008
A55: 2033 | B55: 0.1334 | C55: 0.024 | D55: 0.0164 | E55: 0.0704 | F55: 0 | G55: 0.0182 | H55: 0.0008
A56: 2034 | B56: 0.0685 | C56: 0.0123 | D56: 0.0084 | E56: 0.084 | F56: 0 | G56: 0.0213 | H56: 0.0008
... A72: 2050 | B72: 0 | C72: 0 | D72: 0 | E72: 0.1425 | F72: 0.0015 | G72: 0.0553 | H72: 0.0011
...

Sheet T2_capex_by_tech
A1: Task 2 — Generation CAPEX by technology (discounted)
A2: HOW THIS WAS COMPUTED (generation capex by technology):
A3: 1. Raw data: discounted capital investment by plant technology, per scenario and year, straight from NEMOMOD
A4: column nemomod_entc_discounted_capital_investment_pp_<tech>, in bn 2019 USD.
A5: 2. Two raw blocks below show that variable in BASE (no-action) and in LEDS (LTS).
A6: 3. Incremental capex = LEDS minus BASE (the CALC block; every cell is a live formula). Positive = extra build
A7: in the LTS; negative = fossil capex avoided. Gross positive additions drive the per-technology power cost
A8: vector in Task 1 (T1_cost_vectors). Net (all techs) = 55.8 bn = the generation part of the 65.5 bn power path.
A10: RAW — capex in BASE / no-action (bn)
A11: Year | B11: pp_wind | C11: pp_solar | D11: pp_coal | E11: pp_biogas | F11: pp_gas | G11: pp_oil | H11: pp_nuclear | I11: pp_hydropower | J11: pp_waste_incineration
A12: 2023 | B12: 0 | C12: 0 | D12: 0 | E12: 0 | F12: 0 | G12: 0 | H12: 0 | I12: 0 | J12: 0
A13: 2024 | B13: 0 | C13: 0 | D13: 0 | E13: 0 | F13: 0 | G13: 0 | H13: 0 | I13: 0 | J13: 0
A14: 2025 | B14: 0 | C14: 0 | D14: 0 | E14: 0 | F14: 0 | G14: 0 | H14: 0 | I14: 0 | J14: 0
A15: 2026 | B15: 0 | C15: 0 | D15: 0 | E15: 0 | F15: 0 | G15: 0 | H15: 0.059 | I15: 0 | J15: 0
A16: 2027 | B16: 0.3669 | C16: 0 | D16: 0 | E16: 0 | F16: 0 | G16: 0 | H16: 0.0652 | I16: 0 | J16: 0.0001
A17: 2028 | B17: 0.1415 | C17: 0 | D17: 0 | E17: 0 | F17: 0 | G17: 0 | H17: 0.0665 | I17: 0 | J17: 0.0001
A18: 2029 | B18: 0.6409 | C18: 0 | D18: 0 | E18: 0 | F18: 0 | G18: 0 | H18: 0.0686 | I18: 0 | J18: 0.0001
A19: 2030 | B19: 0.141 | C19: 0 | D19: 0 | E19: 0 | F19: 0 | G19: 0 | H19: 0.0694 | I19: 0 | J19: 0.0002
A20: 2031 | B20: 0.1393 | C20: 0.0304 | D20: 0 | E20: 0 | F20: 0 | G20: 0 | H20: 0.0629 | I20: 0 | J20: 0.0072
A21: 2032 | B21: 0.1376 | C21: 0.04 | D21: 0 | E21: 0.0004 | F21: 0 | G21: 0 | H21: 0.0702 | I21: 0 | J21: 0.0003
A22: 2033 | B22: 0.6354 | C22: 0.0395 | D22: 0.2295 | E22: 0 | F22: 0 | G22: 0 | H22: 0.0715 | I22: 0 | J22: 0.0003
A23: 2034 | B23: 1.0887 | C23: 0.039 | D23: 0.2659 | E23: 0 | F23: 0 | G23: 0.2052 | H23: 0.0722 | I23: 0 | J23: 0.0003
... A39: 2050 | B39: 0.2215 | C39: 0.0157 | D39: 0.3433 | E39: 0.0002 | F39: 0.023 | G39: 0.0125 | H39: 0.0745 | I39: 0.1412 | J39: 0.0004
A40: source: pp_wind=nemomod_entc_discounted_capital_investment_pp_wind, pp_solar=nemomod_entc_discounted_capital_investment_pp_solar ...
A42: RAW — capex in LEDS / LTS (bn)
A43: Year | B43: pp_wind | C43: pp_solar | D43: pp_coal | E43: pp_biogas | F43: pp_gas | G43: pp_oil | H43: pp_nuclear | I43: pp_hydropower | J43: pp_waste_incineration
A44: 2023 | B44: 0 | C44: 0 | D44: 0 | E44: 0.0277 | F44: 0 | G44: 0 | H44: 0.0786 | I44: 0 | J44: 0
A45: 2024 | B45: 1.2973 | C45: 0 | D45: 0 | E45: 0.0056 | F45: 0 | G45: 0 | H45: 0.1902 | I45: 0 | J45: 0
A46: 2025 | B46: 1.5358 | C46: 0.1048 | D46: 0 | E46: 0 | F46: 0 | G46: 0 | H46: 0 | I46: 0 | J46: 0
A47: 2026 | B47: 0 | C47: 0.4052 | D47: 0 | E47: 0 | F47: 0 | G47: 0 | H47: 0 | I47: 0 | J47: 0
A48: 2027 | B48: 1.6586 | C48: 0.6587 | D48: 0 | E48: 0.0324 | F48: 0 | G48: 0 | H48: 0 | I48: 0 | J48: 0
A49: 2028 | B49: 1.4082 | C49: 1.399 | D49: 0 | E49: 0 | F49: 0 | G49: 0 | H49: 0 | I49: 0 | J49: 0
A50: 2029 | B50: 4.789 | C50: 3.3422 | D50: 0 | E50: 0 | F50: 0 | G50: 0 | H50: 0 | I50: 0 | J50: 0
A51: 2030 | B51: 9.9951 | C51: 2.5542 | D51: 0 | E51: 0.0225 | F51: 0 | G51: 0 | H51: 0 | I51: 0 | J51: 0
A52: 2031 | B52: 5.9139 | C52: 4.7882 | D52: 0 | E52: 0.0697 | F52: 0 | G52: 0 | H52: 0 | I52: 0 | J52: 0
A53: 2032 | B53: 2.7135 | C53: 0 | D53: 0 | E53: 0.0577 | F53: 0 | G53: 0 | H53: 0 | I53: 0 | J53: 0.0001
A54: 2033 | B54: 0 | C54: 0 | D54: 0 | E54: 0.0076 | F54: 0 | G54: 0 | H54: 0 | I54: 0 | J54: 0
A55: 2034 | B55: 0 | C55: 0 | D55: 0 | E55: 0.0256 | F55: 0 | G55: 0 | H55: 0 | I55: 0 | J55: 0
... A71: 2050 | B71: 7.257 | C71: 0.3121 | D71: 0 | E71: 0.1741 | F71: 0 | G71: 0 | H71: 0.2105 | I71: 0 | J71: 0
A74: CALC — Incremental capex = LEDS minus BASE (bn) [each cell = a raw-BASE cell minus the raw-LEDS cell above]
...

Sheet T2_note
A1: Task 2 note — fuel savings & capex by generation technology (for Moulaye)
A3: WHY THIS DOES NOT MATCH THE 'Fuel cost savings (power sector)' ROW IN THE COST-BENEFIT FILE
A4: That CB row (cb_type = 'savings_opex') sums to 9.76 bn cumulative. Despite its name it is a RESIDUAL
A5: bucket: it aggregates demand-side, sector-level fuel expenditures and electricity costs allocated to
A6: each demand sector from NEMOMOD. It is NOT generation fuel expenditure.
A8: The series here are computed straight from NEMOMOD:
A9: Fuel savings by tech = change in ENTC fuel consumption value (BASE - LEDS), by fuel, mapped to the
A10: plant that burns it (coal->pp_coal, natural gas->pp_gas, oil->pp_oil, ...). Source column:
A11: totalvalue_enfu_fuel_consumed_entc_fuel_<fuel> (= consumption x fuel price, model-consistent).
A12: Cumulative: coal 52.95, oil 9.53, gas 6.47, biomass 0.59, biogas -2.27 -> ~67 bn total.
A14: RENEWABLES RECEIVE ZERO FUEL SAVINGS — THIS IS CORRECT, NOT A BUG.
A15: Solar, wind, hydro burn no fuel, so they carry no fuel expenditure and no saving. The saving from
... A28: is NOT in this table; add it on the demand side of the SAM if you want the refinery output effect.

Sheet T3_agent_split
A1: Benefit category | B1: Value (bn) | C1: Gov % | D1: Firms % | E1: HH % | F1: Gov (bn) | G1: Firms (bn) | H1: HH (bn) | I1: Row check | J1: Side recorded | K1: Source
A2: Avoided Production Costs (IPPU) | B2: 3.1932 | C2: 0 | D2: 1 | E2: 0 | F2: =$B2*C2 -> 0 | G2: =$B2*D2 -> 3.1932 | H2: =$B2*E2 -> 0 | I2: =C2+D2+E2 -> 1 | J2: Producer cost reduction (cement + steel firms). Mirror: lower output of those producing sectors. | K2: Cement/steel material-efficiency savings accrue to industrial producers. other_manuf as cement proxy (SAM has no cement line), metalwork = steel. Firms 100%. Our judgment.
A3: Crop value | B3: 25.6939 | C3: 0 | D3: 0.7 | E3: 0.3 | F3: =$B3*C3 -> 0 | G3: =$B3*D3 -> 17.98573 | H3: =$B3*E3 -> 7.70817 | I3: =C3+D3+E3 -> 1 | J3: Change in crop production value (recorded on the crops account; can be negative in early years). | K3: Accrues to agricultural producers: commercial farms (firms) 70%, smallholder households 30%. Maps to SAM 'crops'. Our judgment.
A4: Food consumer savings | B4: 64.7589 | C4: 0 | D4: 0 | E4: 1 | F4: =$B4*C4 -> 0 | G4: =$B4*D4 -> 0 | H4: =$B4*E4 -> 64.7589 | I4: =C4+D4+E4 -> 1 | J4: Household food-expenditure reduction (demand side, recorded on food retail/manufacturing). NOT crops. | K4: Savings accrue to households; the demand change runs through food manufacturing/beverage and food-service retail, NOT crops (crop value already covers the production side). Our judgment.
A5: Fuel cost savings (industry, buldings & transport) | B5: 409.4326 | C5: 0.1 | D5: 0.55 | E5: 0.35 | F5: =$B5*C5 -> 40.94326 | G5: =$B5*D5 -> 225.18793 | H5: =$B5*E5 -> 143.30141 | I5: =C5+D5+E5 -> 1 | J5: Recorded as the SUPPLY-side demand reduction on fuel-supplying sectors. Mirror: buyers' freed income (agent split shows who). | K5: Buyers save fuel spend: industry (firms), buildings & private transport (households), public (gov). Supply side maps to domestic refining, imported fuels and gas distribution. Our judgment.
A6: Fuel cost savings (power sector) | B6: 9.7622 | C6: 0.15 | D6: 0.55 | E6: 0.3 | F6: =$B6*C6 -> 1.46433 | G6: =$B6*D6 -> 5.36921 | H6: =$B6*E6 -> 2.92866 | I6: =C6+D6+E6 -> 1 | J6: RESIDUAL bucket (demand-side fuel + allocated electricity cost) — see T2_note. Recorded supply-side. | K6: Per T2_note this row is a residual, not generation fuel expenditure. Allocated to electricity-consuming agents; supply side proxied to refining/gas/imports. Our judgment. For generation fuel savings by tech, use the T2 tabs.
A7: Human Health (air quality) | B7: 46.2885 | C7: 0.3 | D7: 0 | E7: 0.7 | F7: =$B7*C7 -> 13.88655 | G7: =$B7*D7 -> 0 | H7: =$B7*E7 -> 32.40195 | I7: =C7+D7+E7 -> 1 | J7: Avoided external health cost (welfare value proxied onto the health-services account). | K7: Avoided morbidity/mortality borne by households (70%) and the public health system (gov 30%). Proxied to SAM 'education; health and social work'. Welfare value, no direct transaction. Our judgment.
A8: Human Health (diets and Sanitation) | B8: 32.5896 | C8: 0.3 | D8: 0 | E8: 0.7 | F8: =$B8*C8 -> 9.77688 | G8: =$B8*D8 -> 0 | H8: =$B8*E8 -> 22.81272 | I8: =C8+D8+E8 -> 1 | J8: Avoided health cost (welfare) + sanitation service. Proxied onto health & water/sewerage accounts. | K8: Household health benefit (70%) + public sanitation (gov 30%). Health services + water/sewerage sectors. Our judgment.
A9: Livestock value | B9: -3.4013 | C9: 0 | D9: 0.7 | E9: 0.3 | F9: =$B9*C9 -> 0 | G9: =$B9*D9 -> -2.38091 | H9: =$B9*E9 -> -1.02039 | I9: =C9+D9+E9 -> 1 | J9: Change in livestock production value — NEGATIVE overall (-3.40 bn); the minus sign is preserved into the SAM. | K9: Accrues to livestock producers: firms 70%, households 30%. Maps to SAM 'livestock'. Value is negative (herd reduction from dietary shift) — sign kept. Our judgment.
A10: O&M savings | B10: 12.106 | C10: 0.1 | D10: 0.6 | E10: 0.3 | F10: =$B10*C10 -> 1.2106 | G10: =$B10*D10 -> 7.2636 | H10: =$B10*E10 -> 3.6318 | I10: =C10+D10+E10 -> 1 | J10: Avoided operating & maintenance spend (recorded on the sectors that would have supplied it). | K10: Lower EV drivetrain maintenance (repair sector), industrial O&M, avoided fertilizer (chemical). Firms 60%, households 30%, gov 10%. Our judgment.
A11: Transporation Infrastructure Costs Savings | B11: 167.066 | C11: 0.5 | D11: 0.4 | E11: 0.1 | F11: =$B11*C11 -> 83.533 | G11: =$B11*D11 -> 66.8264 | H11: =$B11*E11 -> 16.7066 | I11: =C11+D11+E11 -> 1 | J11: System cost of providing transport service (capital+operating, excl. fuel). Recorded on transport & construction. | K11: Mode-shift lowers transport system cost: public provision (gov 50%), private operators (firms 40%), households 10%. Transport & warehouse + infrastructure construction. Our judgment.
A12: Transport (congestion) | B12: 25.8554 | C12: 0 | D12: 0.3 | E12: 0.7 | F12: =$B12*C12 -> 0 | G12: =$B12*D12 -> 7.75662 | H12: =$B12*E12 -> 18.09878 | I12: =C12+D12+E12 -> 1 | J12: Avoided congestion (time value) — welfare, proxied onto transport & services accounts. | K12: Time saved by road users: households 70%, commercial/freight firms 30%. Welfare value proxied to transport & services. Our judgment.
A13: Transport (road safety) | B13: 32.7576 | C13: 0.1 | D13: 0.2 | E13: 0.7 | F13: =$B13*C13 -> 3.27576 | G13: =$B13*D13 -> 6.55152 | H13: =$B13*E13 -> 22.93032 | I13: =C13+D13+E13 -> 1 | J13: Avoided crash cost (medical + insurance + other) — welfare, proxied onto health/insurance accounts. | K13: Crash costs avoided by households (70%), firms (20%), public (gov 10%). Medical (health), insurance (financial), other. Welfare value. Our judgment.
A14: TOTAL (crosswalked) | B14: =SUM(B2:B13) -> 826.1026 | F14: =SUM(F2:F13) -> 154.09038 | G14: =SUM(G2:G13) -> 337.7533 | H14: =SUM(H2:H13) -> 334.25892
A16: EXCLUDED from crosswalk:
A17: Net Reduction in Capital Costs — covered by the investment file (Task 1).
A18: Ecosystem services = 4.79 bn — non-market welfare value, no agent/transaction.
A19: Reduce Environmental Damage (fertilizers) = 0.05 bn — non-market welfare value, no agent/transaction.
A20: Reduce Environmental Damage (waste pollution) = 8.13 bn — non-market welfare value, no agent/transaction.
A21: Reduce Environmental Damage (water pollution) = 17.43 bn — non-market welfare value, no agent/transaction.
A22: (4 non-market categories = 30.40 bn.) Crosswalked 826.10 + excluded 30.40 = 856.51 bn (16-category total).

Sheet T3_cost_vectors
A1: SAM destination | B1: Avoided Production Costs (IPPU) | C1: Crop value | D1: Food consumer savings | E1: Fuel cost savings (industry, buldings & transport) | F1: Fuel cost savings (power sector) | G1: Human Health (air quality) | H1: Human Health (diets and Sanitation) | I1: Livestock value | J1: O&M savings | K1: Transporation Infrastructure Costs Savings | L1: Transport (congestion) | M1: Transport (road safety)
A2: Value (bn) -> | B2: 3.1932 | C2: 25.6939 | D2: 64.7589 | E2: 409.4326 | F2: 9.7622 | G2: 46.2885 | H2: 32.5896 | I2: -3.4013 | J2: 12.106 | K2: 167.066 | L2: 25.8554 | M2: 32.7576
A3: crops | B3: 0 | C3: 1 | D3: 0 | E3: 0 | F3: 0 | G3: 0 | H3: 0 | I3: 0 | J3: 0 | K3: 0 | L3: 0 | M3: 0
A4: forestry | B4: 0 | C4: 0 | D4: 0 | E4: 0 | F4: 0 | G4: 0 | H4: 0 | I4: 0 | J4: 0 | K4: 0 | L4: 0 | M4: 0
A5: livestock | B5: 0 | C5: 0 | D5: 0 | E5: 0 | F5: 0 | G5: 0 | H5: 0 | I5: 1 | J5: 0 | K5: 0 | L5: 0 | M5: 0
A6: fishery and aquaculture | B6: 0 | C6: 0 | D6: 0 | E6: 0 | F6: 0 | G6: 0 | H6: 0 | I6: 0 | J6: 0 | K6: 0 | L6: 0 | M6: 0
A7: Extractive activities | B7: 0 | C7: 0 | D7: 0 | E7: 0 | F7: 0 | G7: 0 | H7: 0 | I7: 0 | J7: 0 | K7: 0 | L7: 0 | M7: 0
A8: food manufacturing and beverage | B8: 0 | C8: 0 | D8: 0.6 | E8: 0 | F8: 0 | G8: 0 | H8: 0 | I8: 0 | J8: 0 | K8: 0 | L8: 0 | M8: 0
A9: textile manufacturing and clothes | B9: 0 | C9: 0 | D9: 0 | E9: 0 | F9: 0 | G9: 0 | H9: 0 | I9: 0 | J9: 0 | K9: 0 | L9: 0 | M9: 0
A10: Wood product manufacturing | B10: 0 | C10: 0 | D10: 0 | E10: 0 | F10: 0 | G10: 0 | H10: 0 | I10: 0 | J10: 0 | K10: 0 | L10: 0 | M10: 0
A11: coking and refining production | B11: 0 | C11: 0 | D11: 0 | E11: 0.55 | F11: 0.5 | G11: 0 | H11: 0 | I11: 0 | J11: 0 | K11: 0 | L11: 0 | M11: 0
A12: chemical products | B12: 0 | C12: 0 | D12: 0 | E12: 0 | F12: 0 | G12: 0 | H12: 0 | I12: 0 | J12: 0.2 | K12: 0 | L12: 0 | M12: 0
A13: pharmaceutical products | B13: 0 | C13: 0 | D13: 0 | E13: 0 | F13: 0 | G13: 0 | H13: 0 | I13: 0 | J13: 0 | K13: 0 | L13: 0 | M13: 0
... A42: IMPORTS (rest of world) | B42: 0 | C42: 0 | D42: 0 | E42: 0.3 | F42: 0.25 | G42: 0 | H42: 0 | I42: 0 | J42: 0 | K42: 0 | L42: 0 | M42: 0
A43: SUM (must = 100%) | B43: =SUM(B3:B42) -> 1 | C43: =SUM(C3:C42) -> 1 | D43: =SUM(D3:D42) -> 1 | E43: =SUM(E3:E42) -> 1 | F43: =SUM(F3:F42) -> 1 | G43: =SUM(G3:G42) -> 1 | H43: =SUM(H3:H42) -> 1 | I43: =SUM(I3:I42) -> 1 | ... M43: =SUM(M3:M42) -> 1

Sheet T3_applied_SAM
A1: SAM destination (bn 2019 USD) | B1: Avoided Production Costs (IPPU) | C1: Crop value | D1: Food consumer savings | E1: Fuel cost savings (industry, buldings & transport) | F1: Fuel cost savings (power sector) | G1: Human Health (air quality) | H1: Human Health (diets and Sanitation) | I1: Livestock value | J1: O&M savings | K1: Transporation Infrastructure Costs Savings | L1: Transport (congestion) | M1: Transport (road safety) | N1: TOTAL
A2: crops | B2: =T3_cost_vectors!B3*T3_cost_vectors!B$2 -> 0 | C2: =T3_cost_vectors!C3*T3_cost_vectors!C$2 -> 25.6939 | D2: =T3_cost_vectors!D3*T3_cost_vectors!D$2 -> 0 | E2: =T3_cost_vectors!E3*T3_cost_vectors!E$2 -> 0 | F2: =T3_cost_vectors!F3*T3_cost_vectors!F$2 -> 0 | G2: =T3_cost_vectors!G3*T3_cost_vectors!G$2 -> 0 | H2: =T3_cost_vectors!H3*T3_cost_vectors!H$2 -> 0 | I2: =T3_cost_vectors!I3*T3_cost_vectors!I$2 -> 0 | ... M2: =T3_cost_vectors!M3*T3_cost_vectors!M$2 -> 0 | N2: =SUM(B2:M2) -> 25.6939
A3: forestry | B3: =T3_cost_vectors!B4*T3_cost_vectors!B$2 -> 0 | C3: =T3_cost_vectors!C4*T3_cost_vectors!C$2 -> 0 | D3: =T3_cost_vectors!D4*T3_cost_vectors!D$2 -> 0 | E3: =T3_cost_vectors!E4*T3_cost_vectors!E$2 -> 0 | F3: =T3_cost_vectors!F4*T3_cost_vectors!F$2 -> 0 | G3: =T3_cost_vectors!G4*T3_cost_vectors!G$2 -> 0 | H3: =T3_cost_vectors!H4*T3_cost_vectors!H$2 -> 0 | I3: =T3_cost_vectors!I4*T3_cost_vectors!I$2 -> 0 | ... M3: =T3_cost_vectors!M4*T3_cost_vectors!M$2 -> 0 | N3: =SUM(B3:M3) -> 0
A4: livestock | B4: =T3_cost_vectors!B5*T3_cost_vectors!B$2 -> 0 | C4: =T3_cost_vectors!C5*T3_cost_vectors!C$2 -> 0 | D4: =T3_cost_vectors!D5*T3_cost_vectors!D$2 -> 0 | E4: =T3_cost_vectors!E5*T3_cost_vectors!E$2 -> 0 | F4: =T3_cost_vectors!F5*T3_cost_vectors!F$2 -> 0 | G4: =T3_cost_vectors!G5*T3_cost_vectors!G$2 -> 0 | H4: =T3_cost_vectors!H5*T3_cost_vectors!H$2 -> 0 | I4: =T3_cost_vectors!I5*T3_cost_vectors!I$2 -> -3.4013 | ... M4: =T3_cost_vectors!M5*T3_cost_vectors!M$2 -> 0 | N4: =SUM(B4:M4) -> -3.4013
A5: fishery and aquaculture | B5: =T3_cost_vectors!B6*T3_cost_vectors!B$2 -> 0 | C5: =T3_cost_vectors!C6*T3_cost_vectors!C$2 -> 0 | D5: =T3_cost_vectors!D6*T3_cost_vectors!D$2 -> 0 | E5: =T3_cost_vectors!E6*T3_cost_vectors!E$2 -> 0 | F5: =T3_cost_vectors!F6*T3_cost_vectors!F$2 -> 0 | G5: =T3_cost_vectors!G6*T3_cost_vectors!G$2 -> 0 | H5: =T3_cost_vectors!H6*T3_cost_vectors!H$2 -> 0 | I5: =T3_cost_vectors!I6*T3_cost_vectors!I$2 -> 0 | ... M5: =T3_cost_vectors!M6*T3_cost_vectors!M$2 -> 0 | N5: =SUM(B5:M5) -> 0
A6: Extractive activities | B6: =T3_cost_vectors!B7*T3_cost_vectors!B$2 -> 0 | C6: =T3_cost_vectors!C7*T3_cost_vectors!C$2 -> 0 | D6: =T3_cost_vectors!D7*T3_cost_vectors!D$2 -> 0 | E6: =T3_cost_vectors!E7*T3_cost_vectors!E$2 -> 0 | F6: =T3_cost_vectors!F7*T3_cost_vectors!F$2 -> 0 | G6: =T3_cost_vectors!G7*T3_cost_vectors!G$2 -> 0 | H6: =T3_cost_vectors!H7*T3_cost_vectors!H$2 -> 0 | I6: =T3_cost_vectors!I7*T3_cost_vectors!I$2 -> 0 | ... M6: =T3_cost_vectors!M7*T3_cost_vectors!M$2 -> 0 | N6: =SUM(B6:M6) -> 0
A7: food manufacturing and beverage | B7: =T3_cost_vectors!B8*T3_cost_vectors!B$2 -> 0 | C7: =T3_cost_vectors!C8*T3_cost_vectors!C$2 -> 0 | D7: =T3_cost_vectors!D8*T3_cost_vectors!D$2 -> 38.85534 | E7: =T3_cost_vectors!E8*T3_cost_vectors!E$2 -> 0 | F7: =T3_cost_vectors!F8*T3_cost_vectors!F$2 -> 0 | G7: =T3_cost_vectors!G8*T3_cost_vectors!G$2 -> 0 | H7: =T3_cost_vectors!H8*T3_cost_vectors!H$2 -> 0 | I7: =T3_cost_vectors!I8*T3_cost_vectors!I$2 -> 0 | ... M7: =T3_cost_vectors!M8*T3_cost_vectors!M$2 -> 0 | N7: =SUM(B7:M7) -> 38.85534
A8: textile manufacturing and clothes | B8: =T3_cost_vectors!B9*T3_cost_vectors!B$2 -> 0 | C8: =T3_cost_vectors!C9*T3_cost_vectors!C$2 -> 0 | D8: =T3_cost_vectors!D9*T3_cost_vectors!D$2 -> 0 | E8: =T3_cost_vectors!E9*T3_cost_vectors!E$2 -> 0 | F8: =T3_cost_vectors!F9*T3_cost_vectors!F$2 -> 0 | G8: =T3_cost_vectors!G9*T3_cost_vectors!G$2 -> 0 | H8: =T3_cost_vectors!H9*T3_cost_vectors!H$2 -> 0 | I8: =T3_cost_vectors!I9*T3_cost_vectors!I$2 -> 0 | ... M8: =T3_cost_vectors!M9*T3_cost_vectors!M$2 -> 0 | N8: =SUM(B8:M8) -> 0
A9: Wood product manufacturing | B9: =T3_cost_vectors!B10*T3_cost_vectors!B$2 -> 0 | C9: =T3_cost_vectors!C10*T3_cost_vectors!C$2 -> 0 | D9: =T3_cost_vectors!D10*T3_cost_vectors!D$2 -> 0 | E9: =T3_cost_vectors!E10*T3_cost_vectors!E$2 -> 0 | F9: =T3_cost_vectors!F10*T3_cost_vectors!F$2 -> 0 | G9: =T3_cost_vectors!G10*T3_cost_vectors!G$2 -> 0 | H9: =T3_cost_vectors!H10*T3_cost_vectors!H$2 -> 0 | I9: =T3_cost_vectors!I10*T3_cost_vectors!I$2 -> 0 | ... M9: =T3_cost_vectors!M10*T3_cost_vectors!M$2 -> 0 | N9: =SUM(B9:M9) -> 0
A10: coking and refining production | B10: =T3_cost_vectors!B11*T3_cost_vectors!B$2 -> 0 | C10: =T3_cost_vectors!C11*T3_cost_vectors!C$2 -> 0 | D10: =T3_cost_vectors!D11*T3_cost_vectors!D$2 -> 0 | E10: =T3_cost_vectors!E11*T3_cost_vectors!E$2 -> 225.18793 | F10: =T3_cost_vectors!F11*T3_cost_vectors!F$2 -> 4.8811 | G10: =T3_cost_vectors!G11*T3_cost_vectors!G$2 -> 0 | H10: =T3_cost_vectors!H11*T3_cost_vectors!H$2 -> 0 | I10: =T3_cost_vectors!I11*T3_cost_vectors!I$2 -> 0 | ... M10: =T3_cost_vectors!M11*T3_cost_vectors!M$2 -> 0 | N10: =SUM(B10:M10) -> 230.06903
A11: chemical products | B11: =T3_cost_vectors!B12*T3_cost_vectors!B$2 -> 0 | C11: =T3_cost_vectors!C12*T3_cost_vectors!C$2 -> 0 | D11: =T3_cost_vectors!D12*T3_cost_vectors!D$2 -> 0 | E11: =T3_cost_vectors!E12*T3_cost_vectors!E$2 -> 0 | F11: =T3_cost_vectors!F12*T3_cost_vectors!F$2 -> 0 | G11: =T3_cost_vectors!G12*T3_cost_vectors!G$2 -> 0 | H11: =T3_cost_vectors!H12*T3_cost_vectors!H$2 -> 0 | I11: =T3_cost_vectors!I12*T3_cost_vectors!I$2 -> 0 | ... M11: =T3_cost_vectors!M12*T3_cost_vectors!M$2 -> 0 | N11: =SUM(B11:M11) -> 2.4212
A12: pharmaceutical products | B12: =T3_cost_vectors!B13*T3_cost_vectors!B$2 -> 0 | C12: =T3_cost_vectors!C13*T3_cost_vectors!C$2 -> 0 | D12: =T3_cost_vectors!D13*T3_cost_vectors!D$2 -> 0 | E12: =T3_cost_vectors!E13*T3_cost_vectors!E$2 -> 0 | F12: =T3_cost_vectors!F13*T3_cost_vectors!F$2 -> 0 | G12: =T3_cost_vectors!G13*T3_cost_vectors!G$2 -> 0 | H12: =T3_cost_vectors!H13*T3_cost_vectors!H$2 -> 0 | I12: =T3_cost_vectors!I13*T3_cost_vectors!I$2 -> 0 | ... M12: =T3_cost_vectors!M13*T3_cost_vectors!M$2 -> 0 | N12: =SUM(B12:M12) -> 0
A13: rubber manufacturing | B13: =T3_cost_vectors!B14*T3_cost_vectors!B$2 -> 0 | C13: =T3_cost_vectors!C14*T3_cost_vectors!C$2 -> 0 | D13: =T3_cost_vectors!D14*T3_cost_vectors!D$2 -> 0 | E13: =T3_cost_vectors!E14*T3_cost_vectors!E$2 -> 0 | F13: =T3_cost_vectors!F14*T3_cost_vectors!F$2 -> 0 | G13: =T3_cost_vectors!G14*T3_cost_vectors!G$2 -> 0 | H13: =T3_cost_vectors!H14*T3_cost_vectors!H$2 -> 0 | I13: =T3_cost_vectors!I14*T3_cost_vectors!I$2 -> 0 | ... M13: =T3_cost_vectors!M14*T3_cost_vectors!M$2 -> 0 | N13: =SUM(B13:M13) -> 0
... A41: IMPORTS (rest of world) | B41: =T3_cost_vectors!B42*T3_cost_vectors!B$2 -> 0 | C41: =T3_cost_vectors!C42*T3_cost_vectors!C$2 -> 0 | D41: =T3_cost_vectors!D42*T3_cost_vectors!D$2 -> 0 | E41: =T3_cost_vectors!E42*T3_cost_vectors!E$2 -> 122.82978 | F41: =T3_cost_vectors!F42*T3_cost_vectors!F$2 -> 2.44055 | G41: =T3_cost_vectors!G42*T3_cost_vectors!G$2 -> 0 | H41: =T3_cost_vectors!H42*T3_cost_vectors!H$2 -> 0 | I41: =T3_cost_vectors!I42*T3_cost_vectors!I$2 -> 0 | ... M41: =T3_cost_vectors!M42*T3_cost_vectors!M$2 -> 0 | N41: =SUM(B41:M41) -> 125.27033
A42: TOTAL | B42: =SUM(B2:B41) -> 3.1932 | C42: =SUM(C2:C41) -> 25.6939 | D42: =SUM(D2:D41) -> 64.7589 | E42: =SUM(E2:E41) -> 409.4326 | F42: =SUM(F2:F41) -> 9.7622 | G42: =SUM(G2:G41) -> 46.2885 | H42: =SUM(H2:H41) -> 32.5896 | I42: =SUM(I2:I41) -> -3.4013 | ... N42: =SUM(N2:N41) -> 826.1026

Sheet T4_vehicles
A1: Task 4 — Number of vehicles (fleet), LEDS scenario
A2: Fleet = VKT / annual-km-per-vehicle. Annual km: road_light 15,000; freight 60,000; regional 55,000; public 45,000; powered_bikes 8,000. VKT from vehicle_distance_traveled_trns_*.
A3: Year | B3: road_light (total) | C3: road_heavy_freight (total) | D3: road_heavy_regional (total) | E3: public (total) | F3: powered_bikes (total) | G3: road_light (electric) | H3: road_heavy_freight (electric) | I3: road_heavy_regional (electric) | J3: public (electric) | K3: powered_bikes (electric)
A4: 2023 | B4: 3994725.9 | C4: 36470.321 | D4: 2662.355 | E4: 13868.626 | F4: 36304.161 | G4: 0 | H4: 52.1 | I4: 3.803 | J4: 450.73 | K4: 19966.844
A5: 2024 | B5: 4159801.9 | C5: 37846.711 | D5: 2772.373 | E5: 14441.726 | F5: 37804.375 | G5: 0 | H5: 108.133 | I5: 7.921 | J5: 505.46 | K5: 20791.944
A6: 2025 | B6: 4341051 | C6: 39346.349 | D6: 2893.17 | E6: 15070.974 | F6: 39451.572 | G6: 0 | H6: 168.627 | I6: 12.399 | J6: 565.162 | K6: 21697.882
A7: 2026 | B7: 4467228.7 | C7: 40329.034 | D7: 2977.263 | E7: 15509.03 | F7: 40598.277 | G7: 0 | H7: 230.452 | I7: 17.013 | J7: 620.361 | K7: 22328.556
A8: 2027 | B8: 4597049.7 | C8: 41332.871 | D8: 3063.785 | E8: 15959.734 | F8: 41778.094 | G8: 0 | H8: 295.235 | I8: 21.884 | J8: 678.289 | K8: 22977.44
A9: 2028 | B9: 4728764.2 | C9: 42343.751 | D9: 3151.568 | E9: 16417.011 | F9: 42975.118 | G9: 0 | H9: 362.946 | I9: 27.013 | J9: 738.766 | K9: 23635.789
A10: 2029 | B10: 4865295.5 | C10: 43383.656 | D10: 3242.562 | E10: 16891.012 | F10: 44215.917 | G10: 0 | H10: 433.837 | I10: 32.426 | J10: 802.323 | K10: 24318.214
A11: 2030 | B11: 5002309.4 | C11: 44418.734 | D11: 3333.877 | E11: 17366.687 | F11: 45461.103 | G11: 0 | H11: 507.643 | I11: 38.101 | J11: 868.334 | K11: 25003.05
A12: 2031 | B12: 5139590.9 | C12: 45447.051 | D12: 3425.371 | E12: 17843.292 | F12: 46708.72 | G12: 0 | H12: 584.319 | I12: 44.04 | J12: 936.773 | K12: 25689.225
A13: 2032 | B13: 5276908.1 | C13: 46466.596 | D13: 3516.888 | E13: 18320.021 | F13: 47956.662 | G13: 0 | H13: 663.809 | I13: 50.241 | J13: 1007.601 | K13: 26375.577
A14: 2033 | B14: 5414010.7 | C14: 47475.284 | D14: 3608.263 | E14: 18796.005 | F14: 49202.654 | G14: 300778.37 | H14: 1033.858 | I14: 78.576 | J14: 1685.051 | K14: 28290.958
A15: 2034 | B15: 5550630.8 | C15: 48470.953 | D15: 3699.316 | E15: 19270.314 | F15: 50444.261 | G15: 616736.76 | H15: 1410.029 | I15: 107.614 | J15: 2387.472 | K15: 30266.008
... A31: 2050 | B31: 7600019.7 | C31: 62073.317 | D31: 5065.167 | E31: 26385.247 | F31: 69069.153 | G31: 7600019.7 | H31: 7790.201 | I31: 635.678 | J31: 16886.558 | K31: 69069.153
A33: Assumptions are documented judgment / prior-notebook values (trucks 60,000 km/yr). Counts are vehicles, not thousands. road_light is fully electric by 2050 under LEDS.

Sheet T4_elec_generation
A1: Task 4 — Electricity generation by technology (LEDS)
A2: NemoMod Production by Technology, from the Tableau 'drivers' datasource. Storage (st_*) shown separately below. Units: model output units (PJ/GWh as in dashboard).
A3: Year | B3: pp_biogas | C3: pp_biomass | D3: pp_coal | E3: pp_gas | F3: pp_hydropower | G3: pp_nuclear | H3: pp_oil | I3: pp_solar | J3: pp_waste_incineration | K3: pp_wind
A4: 2018 | B4: 0.002 | C4: 0.416 | D4: 88.131 | E4: 14.215 | F4: 2.843 | G4: 1.421 | H4: 7.107 | I4: 6.325 | J4: 0.013 | K4: 21.688
A5: 2019 | B5: 0.004 | C5: 0.715 | D5: 101.254 | E5: 16.331 | F5: 3.266 | G5: 1.633 | H5: 8.166 | I5: 6.533 | J5: 0.02 | K5: 25.415
A6: 2020 | B6: 0.005 | C6: 0.123 | D6: 97.353 | E6: 15.702 | F6: 3.14 | G6: 1.57 | H6: 7.851 | I6: 7.142 | J6: 0.026 | K6: 24.139
A7: 2021 | B7: 0.008 | C7: 1.006 | D7: 103.496 | E7: 16.693 | F7: 3.339 | G7: 1.669 | H7: 8.346 | I7: 7.341 | J7: 0.034 | K7: 25.039
A8: 2022 | B8: 0.01 | C8: 1.157 | D8: 105.117 | E8: 16.954 | F8: 3.391 | G8: 1.695 | H8: 8.477 | I8: 7.321 | J8: 0.034 | K8: 25.431
A9: 2023 | B9: 0.012 | C9: 1.744 | D9: 111.274 | E9: 17.947 | F9: 3.589 | G9: 1.795 | H9: 8.974 | I9: 7.23 | J9: 0.034 | K9: 26.921
A10: 2024 | B10: 0.016 | C10: 1.762 | D10: 113.453 | E10: 18.299 | F10: 3.66 | G10: 1.94 | H10: 9.149 | I10: 9.68 | J10: 0.034 | K10: 29.864
A11: 2025 | B11: 0.02 | C11: 1.601 | D11: 113.763 | E11: 18.349 | F11: 3.67 | G11: 1.938 | H11: 9.174 | I11: 12.385 | J11: 0.034 | K11: 32.905
A12: 2026 | B12: 0.108 | C12: 1.963 | D12: 111.073 | E12: 17.915 | F12: 3.583 | G12: 1.963 | H12: 8.957 | I12: 15.569 | J12: 0.034 | K12: 35.276
A13: 2027 | B13: 0.209 | C13: 0.884 | D13: 104.94 | E13: 16.926 | F13: 3.385 | G13: 1.98 | H13: 8.463 | I13: 20.867 | J13: 0.034 | K13: 40.581
A14: 2028 | B14: 0.323 | C14: 0.541 | D14: 90.413 | E14: 14.583 | F14: 4.376 | G14: 2 | H14: 7.291 | I14: 32.381 | J14: 0.034 | K14: 48.422
A15: 2029 | B15: 0.452 | C15: 0 | D15: 62.627 | E15: 10.101 | F15: 4.042 | G15: 2.02 | H15: 5.051 | I15: 53.536 | J15: 0.034 | K15: 64.647
... A36: 2050 | B36: 2.3 | C36: 0.049 | D36: 0 | E36: 0 | F36: 1.855 | G36: 7.172 | H36: 0 | I36: 207.032 | J36: 0.051 | K36: 207.032
A38: Storage (st_*) — discharge, listed separately from generation
A39: Year | B39: st_batteries | C39: st_compressed_air | D39: st_flywheels | E39: st_pumped_hydro
A40: 2018 | B40: 0 | C40: 0 | D40: 0 | E40: 0
A41: 2019 | B41: 0 | C41: 0 | D41: 0 | E41: 0
A42: 2020 | B42: 0 | C42: 0 | D42: 0 | E42: 0
A43: 2021 | B43: 0 | C43: 0 | D43: 0 | E43: 0
A44: 2022 | B44: 0 | C44: 0 | D44: 0 | E44: 0
A45: 2023 | B45: 0 | C45: 0 | D45: 0 | E45: 0
A46: 2024 | B46: 0 | C46: 0 | D46: 0 | E46: 0
A47: 2025 | B47: 0.002 | C47: 0 | D47: 0 | E47: 0
A48: 2026 | B48: 0.14 | C48: 0 | D48: 0 | E48: 0
A49: 2027 | B49: 0 | C49: 0 | D49: 0 | E49: 0
A50: 2028 | B50: 0 | C50: 0 | D50: 0 | E50: 0
A51: 2029 | B51: 0 | C51: 0 | D51: 0 | E51: 0
... A72: 2050 | B72: 27.097 | C72: 24.75 | D72: 0 | E72: 13.424

Sheet T4_energy_by_fuel
A1: Task 4 — Total final energy demand by fuel (LEDS)
A2: Total Energy Demand by Fuel, from the Tableau 'drivers' datasource. Per-sector splits (Transport, Buildings/SCOE, Industry) available in the drivers data on request.
A3: Year | B3: fuel_ammonia | C3: fuel_biofuels | D3: fuel_biogas | E3: fuel_biomass | F3: fuel_coal | G3: fuel_coke | H3: fuel_crude | I3: fuel_diesel | J3: fuel_electricity | K3: fuel_furnace_gas | L3: fuel_gasoline | M3: fuel_geothermal | N3: fuel_hydrocarbon_gas_liquids | O3: fuel_hydrogen | P3: fuel_kerosene | Q3: fuel_natural_gas | R3: fuel_natural_gas_liquid | S3: fuel_nuclear | T3: fuel_ocean | U3: fuel_oil | V3: fuel_other | W3: fuel_solar | X3: fuel_waste | Y3: fuel_water | Z3: fuel_wind
A4: 2018 | B4: 0 | C4: 0 | D4: 0.007 | E4: 81.009 | F4: 401.216 | G4: 24.016 | H4: 0 | I4: 171.17 | J4: 118.686 | K4: 0 | L4: 77.367 | M4: 0 | N4: 156.208 | O4: 0 | P4: 42.804 | Q4: 33.868 | R4: 0 | S4: 526.469 | T4: 0 | U4: 49.126 | V4: 0 | W4: 6.325 | X4: 0.033 | Y4: 2.843 | Z4: 21.688
A5: 2019 | B5: 0 | C5: 0 | D5: 0.011 | E5: 100.036 | F5: 460.873 | G5: 24.229 | H5: 0 | I5: 175.819 | J5: 136.364 | K5: 0 | L5: 79.152 | M5: 0 | N5: 191.231 | O5: 0 | P5: 44.783 | Q5: 38.592 | R5: 0 | S5: 604.864 | T5: 0 | U5: 52.405 | V5: 0 | W5: 6.533 | X5: 0.051 | Y5: 3.266 | Z5: 25.415
A6: 2020 | B6: 0 | C6: 0 | D6: 0.014 | E6: 92.374 | F6: 443.125 | G6: 23.611 | H6: 0 | I6: 170.575 | J6: 131.117 | K6: 0 | L6: 78.768 | M6: 0 | N6: 190.542 | O6: 0 | P6: 23.348 | Q6: 37.135 | R6: 0 | S6: 581.56 | T6: 0 | U6: 50.765 | V6: 0 | W6: 7.142 | X6: 0.065 | Y6: 3.14 | Z6: 24.139
A7: 2021 | B7: 0 | C7: 0 | D7: 0.023 | E7: 102.802 | F7: 471.064 | G7: 24.343 | H7: 0 | I7: 175.385 | J7: 139.397 | K7: 0 | L7: 80.774 | M7: 0 | N7: 201.678 | O7: 0 | P7: 38.951 | Q7: 39.406 | R7: 0 | S7: 618.254 | T7: 0 | U7: 53.059 | V7: 0 | W7: 7.341 | X7: 0.085 | Y7: 3.339 | Z7: 25.039
A8: 2022 | B8: 0 | C8: 0 | D8: 0.03 | E8: 101.79 | F8: 478.433 | G8: 24.359 | H8: 0 | I8: 175.937 | J8: 141.581 | K8: 0 | L8: 81.088 | M8: 0.145 | N8: 198.616 | O8: 0.145 | P8: 39.099 | Q8: 54.366 | R8: 0 | S8: 627.937 | T8: 0 | U8: 53.451 | V8: 0 | W8: 7.321 | X8: 0.085 | Y8: 3.391 | Z8: 25.431
A9: 2023 | B9: 0 | C9: 0 | D9: 0.037 | E9: 107.162 | F9: 506.427 | G9: 24.528 | H9: 0 | I9: 177.955 | J9: 149.875 | K9: 0 | L9: 81.968 | M9: 0.348 | N9: 201.806 | O9: 0.358 | P9: 39.351 | Q9: 76.835 | R9: 0 | S9: 664.722 | T9: 0 | U9: 55.073 | V9: 0 | W9: 7.23 | X9: 0.084 | Y9: 3.589 | Z9: 26.921
A10: 2024 | B10: 0 | C10: 0 | D10: 0.047 | E10: 109.158 | F10: 516.343 | G10: 25.064 | H10: 0 | I10: 183.4 | J10: 156.832 | K10: 0 | L10: 84.656 | M10: 0.538 | N10: 202.821 | O10: 0.556 | P10: 40.444 | Q10: 96.466 | R10: 0 | S10: 718.378 | T10: 0 | U10: 56.218 | V10: 0 | W10: 9.68 | X10: 0.084 | Y10: 3.66 | Z10: 29.864
A11: 2025 | B11: 0 | C11: 0 | D11: 0.059 | E11: 110.864 | F11: 517.76 | G11: 25.388 | H11: 0 | I11: 189.261 | J11: 161.829 | K11: 0 | L11: 87.604 | M11: 0.659 | N11: 204.006 | O11: 0.688 | P11: 41.641 | Q11: 108.714 | R11: 0 | S11: 717.72 | T11: 0 | U11: 56.678 | V11: 0 | W11: 12.385 | X11: 0.085 | Y11: 3.67 | Z11: 32.905
A12: 2026 | B12: 0 | C12: 0 | D12: 0.321 | E12: 113.447 | F12: 507.001 | G12: 24.748 | H12: 0 | I12: 192.325 | J12: 164.533 | K12: 0 | L12: 89.367 | M12: 0.731 | N12: 202.67 | O12: 0.77 | P12: 42.247 | Q12: 113.765 | R12: 0 | S12: 727.032 | T12: 0 | U12: 55.407 | V12: 0 | W12: 15.569 | X12: 0.084 | Y12: 3.583 | Z12: 35.276
A13: 2027 | B13: 0 | C13: 0 | D13: 0.622 | E13: 112.579 | F13: 479.194 | G13: 24.138 | H13: 0 | I13: 195.459 | J13: 166.719 | K13: 0 | L13: 91.167 | M13: 0.779 | N13: 201.541 | O13: 0.829 | P13: 42.863 | Q13: 116.231 | R13: 0 | S13: 733.433 | T13: 0 | U13: 53.37 | V13: 0 | W13: 20.867 | X13: 0.084 | Y13: 3.385 | Z13: 40.581
A14: 2028 | B14: 0 | C14: 0 | D14: 0.964 | E14: 113.537 | F14: 413.854 | G14: 22.735 | H14: 0 | I14: 198.167 | J14: 169.083 | K14: 0 | L14: 92.923 | M14: 0.818 | N14: 200.568 | O14: 2.42 | P14: 43.425 | Q14: 116.231 | R14: 0 | S14: 740.766 | T14: 0 | U14: 48.426 | V14: 0 | W14: 32.381 | X14: 0.084 | Y14: 4.376 | Z14: 48.422
A15: 2029 | B15: 0 | C15: 0 | D15: 1.35 | E15: 114.172 | F15: 285.22 | G15: 21.391 | H15: 0 | I15: 200.998 | J15: 171.501 | K15: 0 | L15: 94.739 | M15: 0.855 | N15: 199.817 | O15: 3.936 | P15: 44.008 | Q15: 113.041 | R15: 0 | S15: 748.229 | T15: 0 | U15: 40.485 | V15: 0 | W15: 53.536 | X15: 0.085 | Y15: 4.042 | Z15: 64.647
... A36: 2050 | B36: 0 | C36: 0 | D36: 6.866 | E36: 9.503 | F36: 0.059 | G36: 2.284 | H36: 0 | I36: 14.918 | J36: 361.853 | K36: 0 | L36: 0.274 | M36: 0.96 | N36: 14.755 | O36: 43.023 | P36: 50.699 | Q36: 94.316 | R36: 0 | S36: 2656.329 | T36: 0 | U36: 2.936 | V36: 0 | W36: 207.032 | X36: 0.127 | Y36: 1.855 | Z36: 207.032

Sheet T5_ecosystem_split
A1: Task 5 — Ecosystem services: evidence-based split of the $500/ha/yr forest value
A2: Source: de Groot et al. (2012) Table 2, temperate forest (Int$/ha/yr, 2007) — the unit-value basis of Costanza (2014). Morocco-specific refinement: Taye (2021).
A3: The $500/ha is ALREADY NET of food provisioning and carbon (climate regulation); those two services are stripped below and the remainder renormalised, so there is NO double-count against crop value.
A5: Ecosystem service (grouped) | B5: de Groot Int$/ha | C5: Share of net | D5: Applied $/ha (of 500)
A6: Provisioning (non-food: water, raw materials, genetic) | B6: 372 | C6: =B6/B$10 -> 0.14514241 | D6: =C6*500 -> 72.571206
A7: Regulating (non-climate: water flow, waste treatment, erosion, nutrient, pollination, bio-control) | B7: 339 | C7: =B7/B$10 -> 0.13226687 | D7: =C7*500 -> 66.133437
A8: Habitat / biodiversity (nursery, genetic diversity) | B8: 862 | C8: =B8/B$10 -> 0.33632462 | D8: =C8*500 -> 168.16231
A9: Cultural (recreation/TOURISM, aesthetic, inspiration) | B9: 990 | C9: =B9/B$10 -> 0.38626609 | D9: =C9*500 -> 193.13305
A10: NET BASE (food + carbon excluded) | B10: =SUM(B6:B9) -> 2563 | D10: =SUM(D6:D9) -> 500
A12: STRIPPED before renormalisation (already counted elsewhere):
A13: Food (provisioning) | B13: 299 | C13: excluded
A14: Climate regulation (carbon) | B14: 152 | C14: excluded
A16: KEY POINT for Moulaye: TOURISM is a SUBSET of ecosystem-service value — it is the cultural (recreation)
A17: service line above (~$192 of the $500/ha, since recreation is ~989/990 of the cultural total). It is NOT a
A18: parallel category alongside 'environment'. The split must be a partition of ONE total, not two overlapping ones.
A20: Do NOT re-add food or carbon: the $500 figure already excludes them. Pulling the full Costanza/de Groot
A21: breakdown without stripping food + climate would double-count against Crop value (food) and the carbon benefit.

Sheet T5_memo
A1: Task 5 — answers to Moulaye's two disaggregation questions
A3: Q1. ECOSYSTEM SERVICES — can the value be split by service type? YES, evidence-based (see T5_ecosystem_split).
A4: - Factors come from Costanza (2014), whose unit values are de Groot et al. (2012) Table 2. Both break value
A5: down by service type, so we use their temperate-forest breakdown rather than inventing percentages.
A6: - CRITICAL: the $500/ha (primary) and $300/ha (secondary) figures are ALREADY NET of food provisioning and
A7: carbon. We strip those two services out of the de Groot breakdown and renormalise the rest to 100% before
A8: applying to $500/ha. Skipping this step would reintroduce double-counting against Crop value and the carbon benefit.
A9: - TOURISM is a cultural (recreation) service — a SUBSET of the ecosystem-service total, not a separate category
A10: parallel to 'environment'. Present the split as a partition of one total. Recreation is ~$192 of the $500/ha.
A11: - Taye (2021) gives Morocco/Mediterranean-specific values that can refine the shares; the method is unchanged.
A13: Q2. FOOD CONSUMER SAVINGS by product — mostly NOT FEASIBLE. Say this early rather than inventing detail.
A14: Food consumer savings (64.76 bn cumulative) is built from three components, ALL using flat factors with no
... A24: state plainly that the waste and conservation-agriculture components are not decomposable by product.

Sheet T7_pct_change
A1: Task 7 — (LTS - SNBC) / SNBC, both vs a common no-action (BASE) reference. Cumulative 2023-2050, bn 2019 USD.
A2: SNBC = PFLO:BAU minus BASE. LTS = PFLO:LEDS minus BASE. numerator = LTS - SNBC (= plain LTS-SNBC).
A3: FINDING: in the reused runs, PFLO:BAU is ~identical to BASE (BAU-BASE ~ 0 for almost every category), so the SNBC denominator collapses and the % is structurally undefined. A meaningful % needs a DISTINCT SNBC-ambition run.
A5: Benefit category | B5: SNBC (bn) | C5: LTS (bn) | D5: numerator (bn) | E5: % change | F5: Reason / flag
A6: Fuel cost savings (industry, buldings & transport) | B6: 24.539 | C6: 409.433 | D6: 384.893 | E6: — | F6: SUPPRESSED (denominator changes sign over horizon; % meaningless)
A7: Transporation Infrastructure Costs Savings | B7: 0 | C7: 167.066 | D7: 167.066 | E7: — | F7: SUPPRESSED (near-zero denominator)
A8: Food consumer savings | B8: 0 | C8: 64.759 | D8: 64.759 | E8: — | F8: SUPPRESSED (near-zero denominator)
A9: Human Health (air quality) | B9: 6.297 | C9: 46.288 | D9: 39.991 | E9: — | F9: SUPPRESSED (denominator changes sign over horizon; % meaningless)
A10: Transport (road safety) | B10: 0 | C10: 32.758 | D10: 32.758 | E10: — | F10: SUPPRESSED (near-zero denominator)
A11: Human Health (diets and Sanitation) | B11: 0 | C11: 32.59 | D11: 32.59 | E11: — | F11: SUPPRESSED (near-zero denominator)
A12: Transport (congestion) | B12: 0 | C12: 25.855 | D12: 25.855 | E12: — | F12: SUPPRESSED (near-zero denominator)
A13: Crop value | B13: 0 | C13: 25.694 | D13: 25.694 | E13: — | F13: SUPPRESSED (denominator changes sign over horizon; % meaningless)
A14: Reduce Environmental Damage (water pollution) | B14: 0 | C14: 17.427 | D14: 17.427 | E14: — | F14: SUPPRESSED (denominator changes sign over horizon; % meaningless)
A15: O&M savings | B15: 0 | C15: 12.106 | D15: 12.106 | E15: — | F15: SUPPRESSED (near-zero denominator)
A16: Fuel cost savings (power sector) | B16: 13.629 | C16: 9.762 | D16: -3.867 | E16: — | F16: SUPPRESSED (denominator changes sign over horizon; % meaningless)
A17: Reduce Environmental Damage (waste pollution) | B17: 0 | C17: 8.135 | D17: 8.135 | E17: — | F17: SUPPRESSED (near-zero denominator)
... A21: Livestock value | B21: 0 | C21: -3.401 | D21: -3.401 | E21: — | F21: SUPPRESSED (near-zero denominator)
A23: Rules applied (per the task):
A24: - Fertilizer DROPPED — within $2.7m of zero in all 28 years.
A25: - Sign-change categories SUPPRESSED (a % across a sign change is meaningless): crop value, both fuel-savings rows,
A26: air-quality health, water pollution — plus any other whose SNBC increment crosses zero over the horizon.
A27: - Near-zero SNBC denominator SUPPRESSED; O&M-type near-zero denominators flagged.
A28: - Absolute values (SNBC, LTS, numerator) shown next to every % so nothing is hidden by suppression.
A29: - Validation PASSED: sum(numerator) = sum(LTS) - sum(SNBC), and the LTS column reproduces the cost-benefit file.
A31: Because BAU ~ BASE here, the numerator (LTS - SNBC) essentially equals LTS-vs-no-action and IS delivered; only the
A32: percentages are undefined. To get real percentages, run a distinct SNBC-ambition scenario (the 'new SNBC run' option).
