Workbook

Sheet Sheet 1
B1: LTS
A2: CB Type | B2: 2023 | C2: 2024 | D2: 2025 | E2: 2026 | F2: 2027 | G2: 2028 | H2: 2029 | I2: 2030 | J2: 2031 | K2: 2032 | L2: 2033 | M2: 2034 | N2: 2035 | O2: 2036 | P2: 2037 | Q2: 2038 | R2: 2039 | S2: 2040 | T2: 2041 | U2: 2042 | V2: 2043 | W2: 2044 | X2: 2045 | Y2: 2046 | Z2: 2047 | AA2: 2048 | AB2: 2049 | AC2: 2050
A3: Avoided Production Costs (IPPU) | B3: 0 | C3: 0 | D3: 0 | E3: 0.0078373616 | F3: 0.015908462 | G3: 0.024216916 | H3: 0.032772874 | I3: 0.04157313 | J3: 0.050618977 | K3: 0.059911569 | L3: 0.069451925 | M3: 0.07924092 | N3: 0.089279287 | O3: 0.099567608 | P3: 0.11010632 | Q3: 0.12089569 | R3: 0.13193584 | S3: 0.14322673 | T3: 0.15479317 | U3: 0.16664054 | V3: 0.17877429 | W3: 0.19120001 | X3: 0.20392335 | Y3: 0.21695009 | Z3: 0.2302861 | AA3: 0.24393735 | AB3: 0.25790991 | AC3: 0.27220999
A4: Crop value | B4: 0 | C4: 0 | D4: -0.13491357 | E4: -0.14295146 | F4: -0.13609068 | G4: -0.11369818 | H4: -0.077448325 | I4: -0.027433593 | J4: 0.036124138 | K4: 0.11316977 | L4: 0.20405888 | M4: 0.30952751 | N4: 0.43002515 | O4: 0.56451291 | P4: 0.70986994 | Q4: 0.86185574 | R4: 1.0167592 | S4: 1.1723417 | T4: 1.3282161 | U4: 1.4850273 | V4: 1.6440302 | W4: 1.806793 | X4: 1.9750302 | Y4: 2.1505157 | Z4: 2.3350295 | AA4: 2.530449 | AB4: 2.7254677 | AC4: 2.9276561
A5: Ecosystem services | B5: 0 | C5: 0 | D5: 0.073090449 | E5: 0.090305389 | F5: 0.10568565 | G5: 0.11896714 | H5: 0.13046737 | I5: 0.14019945 | J5: 0.1490204 | K5: 0.15719293 | L5: 0.16486732 | M5: 0.17220037 | N5: 0.17933183 | O5: 0.18635003 | P5: 0.1932738 | Q5: 0.20002224 | R5: 0.20651219 | S5: 0.21263024 | T5: 0.21823594 | U5: 0.22333162 | V5: 0.22763066 | W5: 0.23064631 | X5: 0.23295635 | Y5: 0.23454893 | Z5: 0.23535284 | AA5: 0.23528777 | AB5: 0.23289847 | AC5: 0.24379574
A6: Food consumer savings | B6: 0 | C6: 0 | D6: 0.10635272 | E6: 0.27861481 | F6: 0.45339474 | G6: 0.63065578 | H6: 0.81036015 | I6: 0.99245863 | J6: 1.1769057 | K6: 1.3636614 | L6: 1.5526971 | M6: 1.7439936 | N6: 1.9375274 | O6: 2.1332513 | P6: 2.3310929 | Q6: 2.5309805 | R6: 2.7328743 | S6: 2.9367645 | T6: 3.1426795 | U6: 3.3506471 | V6: 3.5607016 | W6: 3.7728934 | X6: 3.9872846 | Y6: 4.2039506 | Z6: 4.4229558 | AA6: 4.6443879 | AB6: 4.8678676 | AC6: 5.0939114
A7: Fuel cost savings (industry, buldings & transport) | B7: 0 | C7: 0 | D7: -0.9725118 | E7: -0.53297072 | F7: 0.0064800208 | G7: 0.57833619 | H7: 1.3164489 | I7: 2.1310154 | J7: 2.6942708 | K7: 3.4169734 | L7: 4.6546798 | M7: 6.2850394 | N7: 8.6209068 | O7: 11.705033 | P7: 15.315597 | Q7: 18.560851 | R7: 20.962078 | S7: 22.668715 | T7: 24.022835 | U7: 25.223429 | V7: 26.376868 | W7: 27.531059 | X7: 28.607687 | Y7: 29.703723 | Z7: 30.838913 | AA7: 32.013603 | AB7: 33.225861 | AC7: 34.477709
A8: Fuel cost savings (power sector) | B8: 0 | C8: 0 | D8: -0.06954077 | E8: -0.04459568 | F8: 0.011002801 | G8: 0.10658077 | H8: 0.24592446 | I8: 0.33160312 | J8: 0.30959197 | K8: 0.34785053 | L8: 0.38820521 | M8: 0.43138831 | N8: 0.46942485 | O8: 0.47142697 | P8: 0.45848654 | Q8: 0.44790401 | R8: 0.43974496 | S8: 0.43004035 | T8: 0.42644806 | U8: 0.42462423 | V8: 0.42451205 | W8: 0.51959501 | X8: 0.52062709 | Y8: 0.52302882 | Z8: 0.52640395 | AA8: 0.53186259 | AB8: 0.54081363 | AC8: 0.54925082
A9: Human Health (air quality) | B9: 0 | C9: 0 | D9: -0.0077440342 | E9: 0.043371331 | F9: 0.10637861 | G9: 0.20183512 | H9: 0.33766339 | I9: 0.47595555 | J9: 0.57899763 | K9: 0.66142016 | L9: 0.8308103 | M9: 1.003675 | N9: 1.1819836 | O9: 1.3534545 | P9: 1.5295016 | Q9: 1.7099753 | R9: 1.8947214 | S9: 2.0835756 | T9: 2.277247 | U9: 2.4757961 | V9: 2.6792722 | W9: 2.8877119 | X9: 3.101139 | Y9: 3.3195642 | Z9: 3.5429878 | AA9: 3.7713946 | AB9: 4.0047481 | AC9: 4.2430202
A10: Human Health (diets and Sanitation) | B10: 0 | C10: 0 | D10: 0.085082174 | E10: 0.171275 | F10: 0.25855413 | G10: 0.34689105 | H10: 0.43625377 | I10: 0.52660772 | J10: 0.61791664 | K10: 0.71014382 | L10: 0.80325363 | M10: 0.89721219 | N10: 0.99198698 | O10: 1.0875484 | P10: 1.1838697 | Q10: 1.2809259 | R10: 1.3786956 | S10: 1.4771604 | T10: 1.576306 | U10: 1.6761229 | V10: 1.7766053 | W10: 1.8777557 | X10: 1.9795818 | Y10: 2.0820974 | Z10: 2.1853094 | AA10: 2.2892351 | AB10: 2.3938956 | AC10: 2.4993127
A11: Livestock value | B11: 0 | C11: 0 | D11: -0.033880204 | E11: -0.042680188 | F11: -0.049429132 | G11: -0.054759132 | H11: -0.058772852 | I11: -0.062012948 | J11: -0.0652667 | K11: -0.069709404 | L11: -0.07699084 | M11: -0.088965992 | N11: -0.10672861 | O11: -0.1293138 | P11: -0.15360225 | Q11: -0.17602779 | R11: -0.19424854 | S11: -0.20741167 | T11: -0.2155514 | U11: -0.21910828 | V11: -0.21859966 | W11: -0.21442192 | X11: -0.20688204 | Y11: -0.19612354 | Z11: -0.18211381 | AA11: -0.16471219 | AB11: -0.12908799 | AC11: -0.084850374
A12: Net Reduction in Capital Costs | B12: 0 | C12: 0 | D12: -2.7280552 | E12: -2.661472 | F12: -4.7300427 | G12: -5.89818 | H12: -11.198122 | I12: -16.617731 | J12: -15.27626 | K12: -7.7725218 | L12: -5.8642822 | M12: -6.5224478 | N12: -7.255944 | O12: -7.9885693 | P12: -10.154021 | Q12: -10.589344 | R12: -10.820018 | S12: -10.210429 | T12: -11.468967 | U12: -11.739624 | V12: -12.022142 | W12: -11.205243 | X12: -13.490683 | Y12: -12.901062 | Z12: -14.021307 | AA12: -14.135802 | AB12: -15.948711 | AC12: -20.148944
A13: O&M savings | B13: 0 | C13: 0 | D13: 0.00046039399 | E13: 0.0012348757 | F13: 0.0020134499 | G13: 0.0028891176 | H13: 0.0037681266 | I13: 0.0046621332 | J13: 0.0055645414 | K13: 0.0064808733 | L13: 0.0617588 | M13: 0.11975534 | N13: 0.1804824 | O13: 0.24392573 | P13: 0.31000298 | Q13: 0.37858026 | R13: 0.44955078 | S13: 0.52284429 | T13: 0.59867931 | U13: 0.67707033 | V13: 0.75801287 | W13: 0.84148555 | X13: 0.92744374 | Y13: 1.0158425 | Z13: 1.1066185 | AA13: 1.1996893 | AB13: 1.2949476 | AC13: 1.3922819
A14: Reduce Environmental Damage (fertilizers) | B14: 0 | C14: 0 | D14: 0.0002291211 | E14: 0.00044716228 | F14: 0.00064589645 | G14: 0.00082576445 | H14: 0.00098961591 | I14: 0.0011386252 | J14: 0.0012743453 | K14: 0.0013984587 | L14: 0.0015125872 | M14: 0.0016181945 | N14: 0.0017166621 | O14: 0.0018095013 | P14: 0.0018984379 | Q14: 0.0019851581 | R14: 0.0020709167 | S14: 0.0021563252 | T14: 0.0022409423 | U14: 0.002323884 | V14: 0.0024039221 | W14: 0.0024795131 | X14: 0.002548904 | Y14: 0.0026101131 | Z14: 0.0026609478 | AA14: 0.0026989374 | AB14: 0.0027240376 | AC14: 0.0027319682
... A19: Transport (road safety) | B19: 0 | C19: 0 | D19: 0 | E19: 0.025316438 | F19: 0.052441447 | G19: 0.081459047 | H19: 0.11252428 | I19: 0.1456589 | J19: 0.18093062 | K19: 0.21840658 | L19: 0.35254514 | M19: 0.49211192 | N19: 0.63703685 | O19: 0.78723139 | P19: 0.94258769 | Q19: 1.1029783 | R19: 1.2682551 | S19: 1.4382488 | T19: 1.6135607 | U19: 1.7942427 | V19: 1.9803379 | W19: 2.171879 | X19: 2.3688871 | Y19: 2.5713718 | Z19: 2.7793345 | AA19: 2.9927614 | AB19: 3.2116243 | AC19: 3.4358817
A21: units: billion 2019 USD

Sheet fuel_cost_sav
D1: LTS
A2: Sector | B2: Fuel | C2: CB Type | D2: 2023 | E2: 2024 | F2: 2025 | G2: 2026 | H2: 2027 | I2: 2028 | J2: 2029 | K2: 2030 | L2: 2031 | M2: 2032 | N2: 2033 | O2: 2034 | P2: 2035 | Q2: 2036 | R2: 2037 | S2: 2038 | T2: 2039 | U2: 2040 | V2: 2041 | W2: 2042 | X2: 2043 | Y2: 2044 | Z2: 2045 | AA2: 2046 | AB2: 2047 | AC2: 2048 | AD2: 2049 | AE2: 2050
A3: ccsq | B3: electricity | C3: Fuel cost savings (industry, buldings & transport) | D3: 0 | E3: 0 | F3: -0.58717331 | G3: -0.65049148 | H3: -0.69329744 | I3: -0.72842891 | J3: -0.76088522 | K3: -0.79243159 | L3: -0.82367099 | M3: -0.85480715 | N3: -0.85480715 | O3: -0.85480715 | P3: -0.85480715 | Q3: -0.85480715 | R3: -0.85480715 | S3: -0.85480715 | T3: -0.85480715 | U3: -0.85480715 | V3: -0.85480715 | W3: -0.85480715 | X3: -0.85480715 | Y3: -0.85480715 | Z3: -0.85480715 | AA3: -0.85480715 | AB3: -0.85480715 | AC3: -0.85480715 | AD3: -0.85480715 | AE3: -0.85480715
B4: hydrogen | C4: Fuel cost savings (industry, buldings & transport) | D4: 0 | E4: 0 | F4: -0.032489811 | G4: -0.035993369 | H4: -0.038361933 | I4: -0.040305847 | J4: -0.042101739 | K4: -0.04384728 | L4: -0.045575837 | M4: -0.047298681 | N4: -0.047298681 | O4: -0.047298681 | P4: -0.047298681 | Q4: -0.047298681 | R4: -0.047298681 | S4: -0.047298681 | T4: -0.047298681 | U4: -0.047298681 | V4: -0.047298681 | W4: -0.047298681 | X4: -0.047298681 | Y4: -0.047298681 | Z4: -0.047298681 | AA4: -0.047298681 | AB4: -0.047298681 | AC4: -0.047298681 | AD4: -0.047298681 | AE4: -0.047298681
B5: natural_gas | C5: Fuel cost savings (industry, buldings & transport) | D5: 0 | E5: 0 | F5: -0.38041438 | G5: -0.42143658 | H5: -0.44916946 | I5: -0.47193022 | J5: -0.49295783 | K5: -0.5133959 | L5: -0.5336351 | M5: -0.55380741 | N5: -0.55380741 | O5: -0.55380741 | P5: -0.55380741 | Q5: -0.55380741 | R5: -0.55380741 | S5: -0.55380741 | T5: -0.55380741 | U5: -0.55380741 | V5: -0.55380741 | W5: -0.55380741 | X5: -0.55380741 | Y5: -0.55380741 | Z5: -0.55380741 | AA5: -0.55380741 | AB5: -0.55380741 | AC5: -0.55380741 | AD5: -0.55380741 | AE5: -0.55380741
A6: entc | B6: biofuels | C6: Fuel cost savings (industry, buldings & transport) | D6: 0 | E6: 0 | F6: 0 | G6: 0 | H6: 0 | I6: 0 | J6: 0 | K6: 0 | L6: 0 | M6: 0 | N6: 0 | O6: 0 | P6: 0 | Q6: 0 | R6: 0 | S6: 0 | T6: 0 | U6: 0 | V6: 0 | W6: 0 | X6: 0 | Y6: 0 | Z6: 0 | AA6: 0 | AB6: 0 | AC6: 0 | AD6: 0 | AE6: 0
B7: biogas | C7: Fuel cost savings (industry, buldings & transport) | D7: 0 | E7: 0 | F7: -0.00040772474 | G7: -0.003127593 | H7: -0.0062504268 | I7: -0.0097953935 | J7: -0.013791323 | K7: -0.018268898 | L7: -0.023265802 | M7: -0.028822259 | N7: -0.034979403 | O7: -0.041778685 | P7: -0.049261833 | Q7: -0.050541144 | R7: -0.051836891 | S7: -0.053149399 | T7: -0.054478832 | U7: -0.055825243 | V7: -0.057202028 | W7: -0.058610231 | X7: -0.0600278 | Y7: -0.06147927 | Z7: -0.062965776 | AA7: -0.064488504 | AB7: -0.066048557 | AC7: -0.067647151 | AD7: -0.069285243 | AE7: -0.070964385
B8: biomass | C8: Fuel cost savings (industry, buldings & transport) | D8: 0 | E8: 0 | F8: -0.00017209269 | G8: -0.0026482968 | H8: 0.014269957 | I8: 0.019676051 | J8: 0.028167254 | K8: 0.028190007 | L8: 0.027263452 | M8: 0.026131426 | N8: 0.025171038 | O8: 0.02420096 | P8: 0.023221441 | Q8: 0.022264683 | R8: 0.021234891 | S8: 0.020527848 | T8: 0.018774843 | U8: 0.002083857 | V8: 0.0022091988 | W8: 0.0023370687 | X8: 0.0024675344 | Y8: 0.0016693125 | Z8: 0.00077240064 | AA8: 0.00077240064 | AB8: 0.00077240064 | AC8: 0.00077240064 | AD8: 0.00077240064 | AE8: 0.00077240064
B9: coal | C9: Fuel cost savings (industry, buldings & transport) | D9: 0 | E9: 0 | F9: -0.040756494 | G9: -0.0014793345 | H9: 0.070606906 | I9: 0.21406641 | J9: 0.47788891 | K9: 0.73950307 | L9: 0.89118765 | M9: 0.97610767 | N9: 1.0342298 | O9: 1.0883304 | P9: 1.1444741 | Q9: 1.1665635 | R9: 1.1888537 | S9: 1.2113387 | T9: 1.2340127 | U9: 1.2568692 | V9: 1.2801831 | W9: 1.3039671 | X9: 1.328234 | Y9: 1.3529966 | Z9: 1.3782675 | AA9: 1.4040591 | AB9: 1.4303821 | AC9: 1.457247 | AD9: 1.4846637 | AE9: 1.5126402
B10: coke | C10: Fuel cost savings (industry, buldings & transport) | D10: 0 | E10: 0 | F10: 0 | G10: 0 | H10: 0 | I10: 0 | J10: 0 | K10: 0 | L10: 0 | M10: 0 | N10: 0 | O10: 0 | P10: 0 | Q10: 0 | R10: 0 | S10: 0 | T10: 0 | U10: 0 | V10: 0 | W10: 0 | X10: 0 | Y10: 0 | Z10: 0 | AA10: 0 | AB10: 0 | AC10: 0 | AD10: 0 | AE10: 0
B11: diesel | C11: Fuel cost savings (industry, buldings & transport) | D11: 0 | E11: 0 | F11: 0 | G11: 0 | H11: 0 | I11: 0 | J11: 0 | K11: 0 | L11: 0 | M11: 0 | N11: 0 | O11: 0 | P11: 0 | Q11: 0 | R11: 0 | S11: 0 | T11: 0 | U11: 0 | V11: 0 | W11: 0 | X11: 0 | Y11: 0 | Z11: 0 | AA11: 0 | AB11: 0 | AC11: 0 | AD11: 0 | AE11: 0
B12: electricity | C12: Fuel cost savings (industry, buldings & transport) | D12: 0 | E12: 0 | F12: 0 | G12: -0.00067913572 | H12: -0.0014619705 | I12: -0.0064050993 | J12: -0.013887187 | K12: -0.080821811 | L12: -0.31323305 | M12: -0.37347928 | N12: -0.48266475 | O12: -0.58978 | P12: -0.69477865 | Q12: -0.79760723 | R12: -0.89820521 | S12: -0.99650512 | T12: -1.0924326 | U12: -1.1859064 | V12: -1.2771881 | W12: -1.3662781 | X12: -1.453169 | Y12: -1.5378447 | Z12: -1.6202805 | AA12: -1.7004428 | AB12: -1.7782886 | AC12: -1.8537652 | AD12: -1.9268096 | AE12: -1.997348
B13: gasoline | C13: Fuel cost savings (industry, buldings & transport) | D13: 0 | E13: 0 | F13: 0 | G13: 0 | H13: 0 | I13: 0 | J13: 0 | K13: 0 | L13: 0 | M13: 0 | N13: 0 | O13: 0 | P13: 0 | Q13: 0 | R13: 0 | S13: 0 | T13: 0 | U13: 0 | V13: 0 | W13: 0 | X13: 0 | Y13: 0 | Z13: 0 | AA13: 0 | AB13: 0 | AC13: 0 | AD13: 0 | AE13: 0
B14: hydrocarbon_gas_liquids | C14: Fuel cost savings (industry, buldings & transport) | D14: 0 | E14: 0 | F14: 0 | G14: 0 | H14: 0 | I14: 0 | J14: 0 | K14: 0 | L14: 0 | M14: 0 | N14: 0 | O14: 0 | P14: 0 | Q14: 0 | R14: 0 | S14: 0 | T14: 0 | U14: 0 | V14: 0 | W14: 0 | X14: 0 | Y14: 0 | Z14: 0 | AA14: 0 | AB14: 0 | AC14: 0 | AD14: 0 | AE14: 0
B15: hydrogen | C15: Fuel cost savings (industry, buldings & transport) | D15: 0 | E15: 0 | F15: 0 | G15: 0 | H15: 0 | I15: 0 | J15: 0 | K15: 0 | L15: 0 | M15: 0 | N15: 0 | O15: 0 | P15: 0 | Q15: 0 | R15: 0 | S15: 0 | T15: 0 | U15: 0 | V15: 0 | W15: 0 | X15: 0 | Y15: 0 | Z15: 0 | AA15: 0 | AB15: 0 | AC15: 0 | AD15: 0 | AE15: 0
B16: kerosene | C16: Fuel cost savings (industry, buldings & transport) | D16: 0 | E16: 0 | F16: 0 | G16: 0 | H16: 0 | I16: 0 | J16: 0 | K16: 0 | L16: 0 | M16: 0 | N16: 0 | O16: 0 | P16: 0 | Q16: 0 | R16: 0 | S16: 0 | T16: 0 | U16: 0 | V16: 0 | W16: 0 | X16: 0 | Y16: 0 | Z16: 0 | AA16: 0 | AB16: 0 | AC16: 0 | AD16: 0 | AE16: 0
B17: natural_gas | C17: Fuel cost savings (industry, buldings & transport) | D17: 0 | E17: 0 | F17: -0.0075519167 | G17: 0.00031812752 | H17: 0.0092252879 | I17: 0.022729368 | J17: 0.044845911 | K17: 0.076992358 | L17: 0.10973272 | M17: 0.12021007 | N17: 0.12740331 | O17: 0.13410649 | P17: 0.14106365 | Q17: 0.14384675 | R17: 0.14665795 | S17: 0.1494966 | T17: 0.15236201 | U17: 0.15525346 | V17: 0.15820523 | W17: 0.16121906 | X17: 0.16429667 | Y17: 0.16743982 | Z17: 0.17065027 | AA17: 0.17392971 | AB17: 0.17727966 | AC17: 0.18070163 | AD17: 0.18419704 | AE17: 0.18776711
B18: nuclear | C18: Fuel cost savings (industry, buldings & transport) | D18: 0 | E18: 0 | F18: -0.0006922468 | G18: -0.00065210883 | H18: -0.00057761689 | I18: -0.00050993954 | J18: -0.00042526707 | K18: 9.437218e-05 | L18: 0.00027955648 | M18: 0.00062546577 | N18: 0.00065054295 | O18: -0.0003643804 | P18: -0.0069437238 | Q18: -0.007152698 | R18: -0.0076718278 | S18: -0.0081691383 | T18: -0.0086242949 | U18: -0.0049125018 | V18: -0.005435115 | W18: -0.0057503898 | X18: -0.005813865 | Y18: -0.0056565029 | Z18: -0.005017984 | AA18: -0.0052785629 | AB18: -0.0055214443 | AC18: -0.0057513256 | AD18: -0.0059601848 | AE18: -0.006161215
... B21: waste | C21: Fuel cost savings (industry, buldings & transport) | D21: 0 | E21: 0 | F21: 2.4725704e-05 | G21: 3.3909444e-05 | H21: 4.3076461e-05 | I21: 5.1501535e-05 | J21: 5.8759911e-05 | K21: 6.4791476e-05 | L21: 6.9777534e-05 | M21: 7.3978051e-05 | N21: 7.7631789e-05 | O21: 8.0921373e-05 | P21: 8.3974417e-05 | Q21: 8.6815025e-05 | R21: 8.9557801e-05 | S21: 9.2237513e-05 | T21: 9.4874186e-05 | U21: 9.747878e-05 | V21: 0.00010005929 | W21: 0.00010261951 | X21: 0.0001037473 | Y21: 0.0001048775 | Z21: 0.00010601111 | AA21: 0.00010714929 | AB21: 0.00010829275 | AC21: 0.00010944256 | AD21: 0.00011061052 | AE21: 0.00011178717
A22: inen | B22: biomass | C22: Fuel cost savings (industry, buldings & transport) | D22: 0 | E22: 0 | F22: 0.00085625502 | G22: 0.0024202018 | H22: 0.0039780888 | I22: 0.0064049535 | J22: 0.0087910944 | K22: 0.011138466 | L22: 0.013450084 | M22: 0.015728908 | N22: 0.017977766 | O22: 0.020198845 | P22: 0.022392661 | Q22: 0.024557338 | R22: 0.026689681 | S22: 0.028787476 | T22: 0.030850509 | U22: 0.032879842 | V22: 0.034882364 | W22: 0.036860088 | X22: 0.038814613 | Y22: 0.040747142 | Z22: 0.042658563 | AA22: 0.044549494 | AB22: 0.046420322 | AC22: 0.048271228 | AD22: 0.050101406 | AE22: 0.051913018
B23: coal | C23: Fuel cost savings (industry, buldings & transport) | D23: 0 | E23: 0 | F23: 3.9189469e-05 | G23: 0.00011076889 | H23: 0.00018207098 | I23: 0.00029314483 | J23: 0.00040235481 | K23: 0.00050979036 | L23: 0.00061558958 | M23: 0.00071988783 | N23: 0.00082281457 | O23: 0.00092446994 | P23: 0.0010248775 | Q23: 0.0011239514 | R23: 0.0012215455 | S23: 0.0013175583 | T23: 0.0014119801 | U23: 0.0015048596 | V23: 0.0015965119 | W23: 0.0016870293 | X23: 0.0017764849 | Y23: 0.0018649337 | Z23: 0.0019524165 | AA23: 0.0020389615 | AB23: 0.0021245864 | AC23: 0.0022092995 | AD23: 0.0022930639 | AE23: 0.0023759786
B24: coke | C24: Fuel cost savings (industry, buldings & transport) | D24: 0 | E24: 0 | F24: 0.002577606 | G24: 0.0072855943 | H24: 0.011975341 | I24: 0.019280993 | J24: 0.026464053 | K24: 0.033530404 | L24: 0.040489128 | M24: 0.047349129 | N24: 0.054118921 | O24: 0.060805093 | P24: 0.067409192 | Q24: 0.073925573 | R24: 0.08034462 | S24: 0.086659663 | T24: 0.092870065 | U24: 0.098979017 | V24: 0.10500726 | W24: 0.11096085 | X24: 0.11684461 | Y24: 0.12266215 | Z24: 0.12841615 | AA24: 0.13410846 | AB24: 0.13974026 | AC24: 0.14531209 | AD24: 0.15082152 | AE24: 0.15627507
B25: diesel | C25: Fuel cost savings (industry, buldings & transport) | D25: 0 | E25: 0 | F25: 0.0084335545 | G25: 0.022811717 | H25: 0.037211792 | I25: 0.060344203 | J25: 0.083200368 | K25: 0.10578901 | L25: 0.12812994 | M25: 0.15024347 | N25: 0.17214958 | O25: 0.19386263 | P25: 0.21538071 | Q25: 0.23667802 | R25: 0.25771545 | S25: 0.27846401 | T25: 0.29891554 | U25: 0.31907537 | V25: 0.33900619 | W25: 0.35872374 | X25: 0.37824003 | Y25: 0.39756328 | Z25: 0.41669886 | AA25: 0.43564964 | AB25: 0.45441636 | AC25: 0.47299795 | AD25: 0.49138317 | AE25: 0.50959238
B26: electricity | C26: Fuel cost savings (industry, buldings & transport) | D26: 0 | E26: 0 | F26: 0.053355314 | G26: 0.12620809 | H26: 0.20013389 | I26: 0.26637321 | J26: 0.33384979 | K26: 0.40254612 | L26: 0.47254657 | M26: 0.54399193 | N26: 0.6170881 | O26: 0.69206615 | P26: 0.7690481 | Q26: 0.84787437 | R26: 0.92811079 | S26: 1.009303 | T26: 1.0911949 | U26: 1.1737279 | V26: 1.2571644 | W26: 1.3416045 | X26: 1.4271385 | Y26: 1.5138321 | Z26: 1.6017344 | AA26: 1.6908738 | AB26: 1.7812595 | AC26: 1.8728873 | AD26: 1.9635407 | AE26: 2.0549238
B27: gasoline | C27: Fuel cost savings (industry, buldings & transport) | D27: 0 | E27: 0 | F27: 0.0024887067 | G27: 0.0067316423 | H27: 0.010981044 | I27: 0.017807322 | J27: 0.024552081 | K27: 0.031217894 | L27: 0.037810611 | M27: 0.044336221 | N27: 0.050800621 | O27: 0.057208051 | P27: 0.063557948 | Q27: 0.069842694 | R27: 0.076050751 | S27: 0.082173565 | T27: 0.088208726 | U27: 0.09415781 | V27: 0.10003931 | W27: 0.10585788 | X27: 0.11161705 | Y27: 0.11731926 | Z27: 0.12296609 | AA27: 0.12855839 | AB27: 0.13409637 | AC27: 0.13957972 | AD27: 0.14500512 | AE27: 0.15037858
B28: hydrocarbon_gas_liquids | C28: Fuel cost savings (industry, buldings & transport) | D28: 0 | E28: 0 | F28: 0.001745475 | G28: 0.004721293 | H28: 0.0077016463 | I28: 0.012489313 | J28: 0.017219805 | K28: 0.021894928 | L28: 0.026518785 | M28: 0.031095575 | N28: 0.035629435 | O28: 0.040123339 | P28: 0.044576892 | Q28: 0.048984751 | R28: 0.053338823 | S28: 0.05763311 | T28: 0.061865919 | U28: 0.066038358 | V28: 0.070163397 | W28: 0.074244298 | X28: 0.078283541 | Y28: 0.082282834 | Z28: 0.086243285 | AA28: 0.090165487 | AB28: 0.094049597 | AC28: 0.097895389 | AD28: 0.10170054 | AE28: 0.10546926
B29: hydrogen | C29: Fuel cost savings (industry, buldings & transport) | D29: 0 | E29: 0 | F29: 0 | G29: 0 | H29: 0 | I29: -0.075937392 | J29: -0.14824627 | K29: -0.21695891 | L29: -0.28210538 | M29: -0.34371379 | N29: -0.40181053 | O29: -0.45642054 | P29: -0.50756753 | Q29: -0.55527419 | R29: -0.59956243 | S29: -0.64045351 | T29: -0.67796831 | U29: -0.7121274 | V29: -0.74307561 | W29: -0.77084733 | X29: -0.7954739 | Y29: -0.81698375 | Z29: -0.8354026 | AA29: -0.8507536 | AB29: -0.86305758 | AC29: -0.87233303 | AD29: -0.87859629 | AE29: -0.88186171
B30: kerosene | C30: Fuel cost savings (industry, buldings & transport) | D30: 0 | E30: 0 | F30: 1.3545365e-05 | G30: 3.6638529e-05 | H30: 5.9766888e-05 | I30: 9.6920492e-05 | J30: 0.00013363041 | K30: 0.00016991065 | L30: 0.00020579305 | M30: 0.0002413102 | N30: 0.00027649419 | O30: 0.00031136812 | P30: 0.00034592891 | Q30: 0.00038013511 | R30: 0.0004139239 | S30: 0.00044724874 | T30: 0.00048009651 | U30: 0.00051247578 | V30: 0.00054448721 | W30: 0.00057615612 | X30: 0.00060750176 | Y30: 0.00063853737 | Z30: 0.00066927156 | AA30: 0.00069970892 | AB30: 0.00072985068 | AC30: 0.00075969508 | AD30: 0.0007892241 | AE30: 0.00081847041
B31: natural_gas | C31: Fuel cost savings (industry, buldings & transport) | D31: 0 | E31: 0 | F31: 0.00022379392 | G31: 0.00059849674 | H31: 0.00097426253 | I31: 0.0015828608 | J31: 0.0021849281 | K31: 0.0027806371 | L31: 0.0033704575 | M31: 0.0039548773 | N31: 0.0045343809 | O31: 0.0051093077 | P31: 0.0056795652 | Q31: 0.0062444232 | R31: 0.0068027954 | S31: 0.0073538668 | T31: 0.0078973811 | U31: 0.0084334472 | V31: 0.0089636935 | W31: 0.0094885117 | X31: 0.010008194 | Y31: 0.010522936 | Z31: 0.011032855 | AA31: 0.011538006 | AB31: 0.012038387 | AC31: 0.012533949 | AD31: 0.013024371 | AE31: 0.013510185
B32: oil | C32: Fuel cost savings (industry, buldings & transport) | D32: 0 | E32: 0 | F32: 0.0064564666 | G32: 0.01746394 | H32: 0.028488189 | I32: 0.046197642 | J32: 0.06369561 | K32: 0.08098877 | L32: 0.098092294 | M32: 0.11502172 | N32: 0.13179235 | O32: 0.14841519 | P32: 0.16488876 | Q32: 0.18119332 | R32: 0.19729892 | S32: 0.21318337 | T32: 0.22884042 | U32: 0.24427417 | V32: 0.25953258 | W32: 0.27462772 | X32: 0.28956878 | Y32: 0.30436206 | Z32: 0.31901167 | AA32: 0.33351979 | AB32: 0.34788701 | AC32: 0.3621125 | AD32: 0.37618765 | AE32: 0.39012805
A33: scoe | B33: biomass | C33: Fuel cost savings (industry, buldings & transport) | D33: 0 | E33: 0 | F33: 0 | G33: 0.0025657708 | H33: 0.0048815474 | I33: 0.0069662788 | J33: 0.0088413612 | K33: 0.018179653 | L33: 0.029626226 | M33: 0.046067348 | N33: 0.073956655 | O33: 0.12609341 | P33: 0.22099491 | Q33: 0.36653083 | R33: 0.53306278 | S33: 0.67161998 | T33: 0.76423396 | U33: 0.82298149 | V33: 0.86404926 | W33: 0.89743464 | X33: 0.92809576 | Y33: 0.95829131 | Z33: 0.98401172 | AA33: 1.0107365 | AB33: 1.0386088 | AC33: 1.0676792 | AD33: 1.0980007 | AE33: 1.1296279
B34: coal | C34: Fuel cost savings (industry, buldings & transport) | D34: 0 | E34: 0 | F34: 0 | G34: 0 | H34: 0 | I34: 0 | J34: 0 | K34: 0 | L34: 0 | M34: 0 | N34: 0 | O34: 0 | P34: 0 | Q34: 0 | R34: 0 | S34: 0 | T34: 0 | U34: 0 | V34: 0 | W34: 0 | X34: 0 | Y34: 0 | Z34: 0 | AA34: 0 | AB34: 0 | AC34: 0 | AD34: 0 | AE34: 0
B35: diesel | C35: Fuel cost savings (industry, buldings & transport) | D35: 0 | E35: 0 | F35: 0 | G35: 0 | H35: 0 | I35: 0 | J35: 0 | K35: 0 | L35: 0 | M35: 0 | N35: 0 | O35: 0 | P35: 0 | Q35: 0 | R35: 0 | S35: 0 | T35: 0 | U35: 0 | V35: 0 | W35: 0 | X35: 0 | Y35: 0 | Z35: 0 | AA35: 0 | AB35: 0 | AC35: 0 | AD35: 0 | AE35: 0
B36: electricity | C36: Fuel cost savings (industry, buldings & transport) | D36: 0 | E36: 0 | F36: 0 | G36: 0 | H36: 0 | I36: 0 | J36: 0 | K36: -0.005986631 | L36: -0.013497661 | M36: -0.024728405 | N36: -0.044651835 | O36: -0.083663828 | P36: -0.15919886 | Q36: -0.28638135 | R36: -0.450537 | S36: -0.60364624 | T36: -0.71401276 | U36: -0.78650681 | V36: -0.83788915 | W36: -0.88035996 | X36: -0.92032146 | Y36: -0.96073388 | Z36: -0.99546574 | AA36: -1.0447224 | AB36: -1.094767 | AC36: -1.1456122 | AD36: -1.1972709 | AE36: -1.2497563
B37: gasoline | C37: Fuel cost savings (industry, buldings & transport) | D37: 0 | E37: 0 | F37: 0 | G37: 0 | H37: 0 | I37: 0 | J37: 0 | K37: 0 | L37: 0 | M37: 0 | N37: 0 | O37: 0 | P37: 0 | Q37: 0 | R37: 0 | S37: 0 | T37: 0 | U37: 0 | V37: 0 | W37: 0 | X37: 0 | Y37: 0 | Z37: 0 | AA37: 0 | AB37: 0 | AC37: 0 | AD37: 0 | AE37: 0
B38: hydrocarbon_gas_liquids | C38: Fuel cost savings (industry, buldings & transport) | D38: 0 | E38: 0 | F38: 0 | G38: 0.19508424 | H38: 0.37832593 | I38: 0.54964072 | J38: 0.70906246 | K38: 0.97686253 | L38: 1.2625898 | M38: 1.6083931 | N38: 2.1091787 | O38: 2.9586127 | P38: 4.4643284 | Q38: 6.8445858 | R38: 9.7356521 | S38: 12.246921 | T38: 13.888049 | U38: 14.811641 | V38: 15.333491 | W38: 15.666652 | X38: 15.918865 | Y38: 16.138828 | Z38: 16.244652 | AA38: 16.348114 | AB38: 16.454795 | AC38: 16.564802 | AD38: 16.67824 | AE38: 16.795199
B39: hydrogen | C39: Fuel cost savings (industry, buldings & transport) | D39: 0 | E39: 0 | F39: 0 | G39: 0 | H39: 0 | I39: 0 | J39: 0 | K39: 0 | L39: 0 | M39: 0 | N39: 0 | O39: 0 | P39: 0 | Q39: 0 | R39: 0 | S39: 0 | T39: 0 | U39: 0 | V39: 0 | W39: 0 | X39: 0 | Y39: 0 | Z39: 0 | AA39: 0 | AB39: 0 | AC39: 0 | AD39: 0 | AE39: 0
B40: kerosene | C40: Fuel cost savings (industry, buldings & transport) | D40: 0 | E40: 0 | F40: 0 | G40: 0 | H40: 0 | I40: 0 | J40: 0 | K40: 0 | L40: 0 | M40: 0 | N40: 0 | O40: 0 | P40: 0 | Q40: 0 | R40: 0 | S40: 0 | T40: 0 | U40: 0 | V40: 0 | W40: 0 | X40: 0 | Y40: 0 | Z40: 0 | AA40: 0 | AB40: 0 | AC40: 0 | AD40: 0 | AE40: 0
B41: natural_gas | C41: Fuel cost savings (industry, buldings & transport) | D41: 0 | E41: 0 | F41: 0 | G41: 0 | H41: 0 | I41: 0 | J41: 0 | K41: 0 | L41: 0 | M41: 0 | N41: 0 | O41: 0 | P41: 0 | Q41: 0 | R41: 0 | S41: 0 | T41: 0 | U41: 0 | V41: 0 | W41: 0 | X41: 0 | Y41: 0 | Z41: 0 | AA41: 0 | AB41: 0 | AC41: 0 | AD41: 0 | AE41: 0
A42: trns | B42: biofuels | C42: Fuel cost savings (industry, buldings & transport) | D42: 0 | E42: 0 | F42: 0 | G42: 0 | H42: 0 | I42: 0 | J42: 0 | K42: 0 | L42: 0 | M42: 0 | N42: 0 | O42: 0 | P42: 0 | Q42: 0 | R42: 0 | S42: 0 | T42: 0 | U42: 0 | V42: 0 | W42: 0 | X42: 0 | Y42: 0 | Z42: 0 | AA42: 0 | AB42: 0 | AC42: 0 | AD42: 0 | AE42: 0
...
